<robot name = "robot">
    <link name="Link0">
        <inertial>
            <origin xyz="0.0 0.0 2.18660922264225" rpy="0 0 0"/>
            <mass value="1" />
            <inertia ixx="100" ixy="0" ixz="0" iyy="100" iyz="0" izz="100" />
        </inertial>
        <visual>
            <origin xyz="0.0 0.0 2.18660922264225" rpy="0 0 0"/>
            <geometry>
                <box size="0.7874854540661725 0.5618786089603851 0.37321844528450027" />
            </geometry>
            <material name="Green">
                <color rgba="0 1.0 0 1.0"/>
            </material>
        </visual>
        <collision>
            <origin xyz="0.0 0.0 2.18660922264225" rpy="0 0 0"/>
            <geometry>
                <box size="0.7874854540661725 0.5618786089603851 0.37321844528450027" />
            </geometry>
        </collision>
    </link>
    <joint name="Link0_Link1" type="revolute">
       <parent link="Link0"/>
       <child  link="Link1"/>
       <origin rpy="0 0 0" xyz="0.0 0.28093930448019255 2.18660922264225" />
     <axis xyz="1 0 1"/>
       <limit effort="0.0" lower="-3.14159" upper="3.14159" velocity="0.0"/>
    </joint>
    <link name="Link1">
        <inertial>
            <origin xyz="0.0 0.20477686058576428 0.0" rpy="0 0 0"/>
            <mass value="1" />
            <inertia ixx="100" ixy="0" ixz="0" iyy="100" iyz="0" izz="100" />
        </inertial>
        <visual>
            <origin xyz="0.0 0.20477686058576428 0.0" rpy="0 0 0"/>
            <geometry>
                <box size="0.5774555856829007 0.40955372117152855 0.39040758723791325" />
            </geometry>
            <material name="Green">
                <color rgba="0 1.0 0 1.0"/>
            </material>
        </visual>
        <collision>
            <origin xyz="0.0 0.20477686058576428 0.0" rpy="0 0 0"/>
            <geometry>
                <box size="0.5774555856829007 0.40955372117152855 0.39040758723791325" />
            </geometry>
        </collision>
    </link>
    <joint name="Link1_Link2" type="revolute">
       <parent link="Link1"/>
       <child  link="Link2"/>
       <origin rpy="0 0 0" xyz="0.0 0.40955372117152855 0.0" />
     <axis xyz="[1 0 1]"/>
       <limit effort="0.0" lower="-3.14159" upper="3.14159" velocity="0.0"/>
    </joint>
    <link name="Link2">
        <inertial>
            <origin xyz="0.0 0.257504070519103 0.0" rpy="0 0 0"/>
            <mass value="1" />
            <inertia ixx="100" ixy="0" ixz="0" iyy="100" iyz="0" izz="100" />
        </inertial>
        <visual>
            <origin xyz="0.0 0.257504070519103 0.0" rpy="0 0 0"/>
            <geometry>
                <box size="0.5851013725864486 0.515008141038206 0.41901877697736484" />
            </geometry>
            <material name="Blue">
                <color rgba="0 0 1.0 1.0"/>
            </material>
        </visual>
        <collision>
            <origin xyz="0.0 0.257504070519103 0.0" rpy="0 0 0"/>
            <geometry>
                <box size="0.5851013725864486 0.515008141038206 0.41901877697736484" />
            </geometry>
        </collision>
    </link>
    <joint name="Link2_Link2-0" type="revolute">
       <parent link="Link2"/>
       <child  link="Link2-0"/>
       <origin rpy="0 0 0" xyz="0.0 0.257504070519103 0.20950938848868242" />
     <axis xyz="[1 1 0]"/>
       <limit effort="0.0" lower="-3.14159" upper="3.14159" velocity="0.0"/>
    </joint>
    <link name="Link2-0">
        <inertial>
            <origin xyz="0.0 0.0 0.07549133152756887" rpy="0 0 0"/>
            <mass value="1" />
            <inertia ixx="100" ixy="0" ixz="0" iyy="100" iyz="0" izz="100" />
        </inertial>
        <visual>
            <origin xyz="0.0 0.0 0.07549133152756887" rpy="0 0 0"/>
            <geometry>
                <box size="0.5743340921102046 0.9909457898786859 0.15098266305513774" />
            </geometry>
            <material name="Green">
                <color rgba="0 1.0 0 1.0"/>
            </material>
        </visual>
        <collision>
            <origin xyz="0.0 0.0 0.07549133152756887" rpy="0 0 0"/>
            <geometry>
                <box size="0.5743340921102046 0.9909457898786859 0.15098266305513774" />
            </geometry>
        </collision>
    </link>
    <joint name="Link2-0_Link2-0-0" type="revolute">
       <parent link="Link2-0"/>
       <child  link="Link2-0-0"/>
       <origin rpy="0 0 0" xyz="0.0 0.49547289493934293 0.07549133152756887" />
     <axis xyz="[1 0 1]"/>
       <limit effort="0.0" lower="-3.14159" upper="3.14159" velocity="0.0"/>
    </joint>
    <link name="Link2-0-0">
        <inertial>
            <origin xyz="0.0 0.18900434091663865 0.0" rpy="0 0 0"/>
            <mass value="1" />
            <inertia ixx="100" ixy="0" ixz="0" iyy="100" iyz="0" izz="100" />
        </inertial>
        <visual>
            <origin xyz="0.0 0.18900434091663865 0.0" rpy="0 0 0"/>
            <geometry>
                <box size="0.598759340894332 0.3780086818332773 0.2855216253938097" />
            </geometry>
            <material name="Green">
                <color rgba="0 1.0 0 1.0"/>
            </material>
        </visual>
        <collision>
            <origin xyz="0.0 0.18900434091663865 0.0" rpy="0 0 0"/>
            <geometry>
                <box size="0.598759340894332 0.3780086818332773 0.2855216253938097" />
            </geometry>
        </collision>
    </link>
    <joint name="Link2-0-0_Link2-0-0-0" type="revolute">
       <parent link="Link2-0-0"/>
       <child  link="Link2-0-0-0"/>
       <origin rpy="0 0 0" xyz="-0.299379670447166 0.18900434091663865 0.0" />
     <axis xyz="[2 1 1]"/>
       <limit effort="0.0" lower="-3.14159" upper="3.14159" velocity="0.0"/>
    </joint>
    <link name="Link2-0-0-0">
        <inertial>
            <origin xyz="-0.21634932080421834 0.0 0.0" rpy="0 0 0"/>
            <mass value="1" />
            <inertia ixx="100" ixy="0" ixz="0" iyy="100" iyz="0" izz="100" />
        </inertial>
        <visual>
            <origin xyz="-0.21634932080421834 0.0 0.0" rpy="0 0 0"/>
            <geometry>
                <box size="0.4326986416084367 0.5764514445113822 0.26541628388572763" />
            </geometry>
            <material name="Blue">
                <color rgba="0 0 1.0 1.0"/>
            </material>
        </visual>
        <collision>
            <origin xyz="-0.21634932080421834 0.0 0.0" rpy="0 0 0"/>
            <geometry>
                <box size="0.4326986416084367 0.5764514445113822 0.26541628388572763" />
            </geometry>
        </collision>
    </link>
    <joint name="Link2-0-0_Link2-0-1" type="revolute">
       <parent link="Link2-0-0"/>
       <child  link="Link2-0-1"/>
       <origin rpy="0 0 0" xyz="0.0 0.3780086818332773 0.0" />
     <axis xyz="[1 0 1]"/>
       <limit effort="0.0" lower="-3.14159" upper="3.14159" velocity="0.0"/>
    </joint>
    <link name="Link2-0-1">
        <inertial>
            <origin xyz="0.0 0.4902797599205284 0.0" rpy="0 0 0"/>
            <mass value="1" />
            <inertia ixx="100" ixy="0" ixz="0" iyy="100" iyz="0" izz="100" />
        </inertial>
        <visual>
            <origin xyz="0.0 0.4902797599205284 0.0" rpy="0 0 0"/>
            <geometry>
                <box size="0.25813659020226226 0.9805595198410568 0.4717164072973152" />
            </geometry>
            <material name="Blue">
                <color rgba="0 0 1.0 1.0"/>
            </material>
        </visual>
        <collision>
            <origin xyz="0.0 0.4902797599205284 0.0" rpy="0 0 0"/>
            <geometry>
                <box size="0.25813659020226226 0.9805595198410568 0.4717164072973152" />
            </geometry>
        </collision>
    </link>
</robot>