<robot name = "robot">
    <link name="Link0">
        <inertial>
            <origin xyz="0.0 0.0 2.141700858729992" rpy="0 0 0"/>
            <mass value="1" />
            <inertia ixx="100" ixy="0" ixz="0" iyy="100" iyz="0" izz="100" />
        </inertial>
        <visual>
            <origin xyz="0.0 0.0 2.141700858729992" rpy="0 0 0"/>
            <geometry>
                <box size="0.5668530778865909 0.37025879167484854 0.28340171745998477" />
            </geometry>
            <material name="Green">
                <color rgba="0 1.0 0 1.0"/>
            </material>
        </visual>
        <collision>
            <origin xyz="0.0 0.0 2.141700858729992" rpy="0 0 0"/>
            <geometry>
                <box size="0.5668530778865909 0.37025879167484854 0.28340171745998477" />
            </geometry>
        </collision>
    </link>
    <joint name="Link0_Link1" type="revolute">
       <parent link="Link0"/>
       <child  link="Link1"/>
       <origin rpy="0 0 0" xyz="0.0 0.18512939583742427 2.141700858729992" />
     <axis xyz="1 0 1"/>
       <limit effort="0.0" lower="-3.14159" upper="3.14159" velocity="0.0"/>
    </joint>
    <link name="Link1">
        <inertial>
            <origin xyz="0.0 0.41524003314820135 0.0" rpy="0 0 0"/>
            <mass value="1" />
            <inertia ixx="100" ixy="0" ixz="0" iyy="100" iyz="0" izz="100" />
        </inertial>
        <visual>
            <origin xyz="0.0 0.41524003314820135 0.0" rpy="0 0 0"/>
            <geometry>
                <box size="0.4726021807466551 0.8304800662964027 0.19547568565191406" />
            </geometry>
            <material name="Green">
                <color rgba="0 1.0 0 1.0"/>
            </material>
        </visual>
        <collision>
            <origin xyz="0.0 0.41524003314820135 0.0" rpy="0 0 0"/>
            <geometry>
                <box size="0.4726021807466551 0.8304800662964027 0.19547568565191406" />
            </geometry>
        </collision>
    </link>
    <joint name="Link1_Link2" type="revolute">
       <parent link="Link1"/>
       <child  link="Link2"/>
       <origin rpy="0 0 0" xyz="0.0 0.8304800662964027 0.0" />
     <axis xyz="[1 0 1]"/>
       <limit effort="0.0" lower="-3.14159" upper="3.14159" velocity="0.0"/>
    </joint>
    <link name="Link2">
        <inertial>
            <origin xyz="0.0 0.2809313821435361 0.0" rpy="0 0 0"/>
            <mass value="1" />
            <inertia ixx="100" ixy="0" ixz="0" iyy="100" iyz="0" izz="100" />
        </inertial>
        <visual>
            <origin xyz="0.0 0.2809313821435361 0.0" rpy="0 0 0"/>
            <geometry>
                <box size="0.7159084927433261 0.5618627642870722 0.35988084831606326" />
            </geometry>
            <material name="Green">
                <color rgba="0 1.0 0 1.0"/>
            </material>
        </visual>
        <collision>
            <origin xyz="0.0 0.2809313821435361 0.0" rpy="0 0 0"/>
            <geometry>
                <box size="0.7159084927433261 0.5618627642870722 0.35988084831606326" />
            </geometry>
        </collision>
    </link>
    <joint name="Link2_Link2-0" type="revolute">
       <parent link="Link2"/>
       <child  link="Link2-0"/>
       <origin rpy="0 0 0" xyz="0.35795424637166307 0.2809313821435361 0.0" />
     <axis xyz="[0 1 1]"/>
       <limit effort="0.0" lower="-3.14159" upper="3.14159" velocity="0.0"/>
    </joint>
    <link name="Link2-0">
        <inertial>
            <origin xyz="0.11353064087512679 0.0 0.0" rpy="0 0 0"/>
            <mass value="1" />
            <inertia ixx="100" ixy="0" ixz="0" iyy="100" iyz="0" izz="100" />
        </inertial>
        <visual>
            <origin xyz="0.11353064087512679 0.0 0.0" rpy="0 0 0"/>
            <geometry>
                <box size="0.22706128175025359 0.6153758717975667 0.29422551254655765" />
            </geometry>
            <material name="Green">
                <color rgba="0 1.0 0 1.0"/>
            </material>
        </visual>
        <collision>
            <origin xyz="0.11353064087512679 0.0 0.0" rpy="0 0 0"/>
            <geometry>
                <box size="0.22706128175025359 0.6153758717975667 0.29422551254655765" />
            </geometry>
        </collision>
    </link>
    <joint name="Link2-0_Link2-0-0" type="revolute">
       <parent link="Link2-0"/>
       <child  link="Link2-0-0"/>
       <origin rpy="0 0 0" xyz="0.11353064087512679 0.0 0.22814862242848546" />
     <axis xyz="[1 1 0]"/>
       <limit effort="0.0" lower="-3.14159" upper="3.14159" velocity="0.0"/>
    </joint>
    <link name="Link2-0-0">
        <inertial>
            <origin xyz="0.0 0.0 0.16961824844872586" rpy="0 0 0"/>
            <mass value="1" />
            <inertia ixx="100" ixy="0" ixz="0" iyy="100" iyz="0" izz="100" />
        </inertial>
        <visual>
            <origin xyz="0.0 0.0 0.16961824844872586" rpy="0 0 0"/>
            <geometry>
                <box size="0.3937329371932142 0.5914052597880438 0.3392364968974517" />
            </geometry>
            <material name="Blue">
                <color rgba="0 0 1.0 1.0"/>
            </material>
        </visual>
        <collision>
            <origin xyz="0.0 0.0 0.16961824844872586" rpy="0 0 0"/>
            <geometry>
                <box size="0.3937329371932142 0.5914052597880438 0.3392364968974517" />
            </geometry>
        </collision>
    </link>
    <joint name="Link2-0-0_Link2-0-1" type="revolute">
       <parent link="Link2-0-0"/>
       <child  link="Link2-0-1"/>
       <origin rpy="0 0 0" xyz="0.0 0.0 0.3392364968974517" />
     <axis xyz="[1 1 0]"/>
       <limit effort="0.0" lower="-3.14159" upper="3.14159" velocity="0.0"/>
    </joint>
    <link name="Link2-0-1">
        <inertial>
            <origin xyz="0.0 0.0 0.15442164454139218" rpy="0 0 0"/>
            <mass value="1" />
            <inertia ixx="100" ixy="0" ixz="0" iyy="100" iyz="0" izz="100" />
        </inertial>
        <visual>
            <origin xyz="0.0 0.0 0.15442164454139218" rpy="0 0 0"/>
            <geometry>
                <box size="0.7110682704593749 0.736336434629268 0.30884328908278436" />
            </geometry>
            <material name="Green">
                <color rgba="0 1.0 0 1.0"/>
            </material>
        </visual>
        <collision>
            <origin xyz="0.0 0.0 0.15442164454139218" rpy="0 0 0"/>
            <geometry>
                <box size="0.7110682704593749 0.736336434629268 0.30884328908278436" />
            </geometry>
        </collision>
    </link>
    <joint name="Link2-0-1_Link2-0-2" type="revolute">
       <parent link="Link2-0-1"/>
       <child  link="Link2-0-2"/>
       <origin rpy="0 0 0" xyz="0.0 0.0 0.30884328908278436" />
     <axis xyz="[1 1 0]"/>
       <limit effort="0.0" lower="-3.14159" upper="3.14159" velocity="0.0"/>
    </joint>
    <link name="Link2-0-2">
        <inertial>
            <origin xyz="0.0 0.0 0.15447854128884667" rpy="0 0 0"/>
            <mass value="1" />
            <inertia ixx="100" ixy="0" ixz="0" iyy="100" iyz="0" izz="100" />
        </inertial>
        <visual>
            <origin xyz="0.0 0.0 0.15447854128884667" rpy="0 0 0"/>
            <geometry>
                <box size="0.2831277487482631 0.9387487331671694 0.30895708257769333" />
            </geometry>
            <material name="Green">
                <color rgba="0 1.0 0 1.0"/>
            </material>
        </visual>
        <collision>
            <origin xyz="0.0 0.0 0.15447854128884667" rpy="0 0 0"/>
            <geometry>
                <box size="0.2831277487482631 0.9387487331671694 0.30895708257769333" />
            </geometry>
        </collision>
    </link>
    <joint name="Link2-0-2_Link2-0-3" type="revolute">
       <parent link="Link2-0-2"/>
       <child  link="Link2-0-3"/>
       <origin rpy="0 0 0" xyz="0.0 0.0 0.30895708257769333" />
     <axis xyz="[1 1 0]"/>
       <limit effort="0.0" lower="-3.14159" upper="3.14159" velocity="0.0"/>
    </joint>
    <link name="Link2-0-3">
        <inertial>
            <origin xyz="0.0 0.0 0.18927567446491536" rpy="0 0 0"/>
            <mass value="1" />
            <inertia ixx="100" ixy="0" ixz="0" iyy="100" iyz="0" izz="100" />
        </inertial>
        <visual>
            <origin xyz="0.0 0.0 0.18927567446491536" rpy="0 0 0"/>
            <geometry>
                <box size="0.8849632764653378 0.33900682209508604 0.3785513489298307" />
            </geometry>
            <material name="Blue">
                <color rgba="0 0 1.0 1.0"/>
            </material>
        </visual>
        <collision>
            <origin xyz="0.0 0.0 0.18927567446491536" rpy="0 0 0"/>
            <geometry>
                <box size="0.8849632764653378 0.33900682209508604 0.3785513489298307" />
            </geometry>
        </collision>
    </link>
    <joint name="Link2-0-3_Link2-0-4" type="revolute">
       <parent link="Link2-0-3"/>
       <child  link="Link2-0-4"/>
       <origin rpy="0 0 0" xyz="0.0 0.0 0.3785513489298307" />
     <axis xyz="[1 1 0]"/>
       <limit effort="0.0" lower="-3.14159" upper="3.14159" velocity="0.0"/>
    </joint>
    <link name="Link2-0-4">
        <inertial>
            <origin xyz="0.0 0.0 0.1649649325095876" rpy="0 0 0"/>
            <mass value="1" />
            <inertia ixx="100" ixy="0" ixz="0" iyy="100" iyz="0" izz="100" />
        </inertial>
        <visual>
            <origin xyz="0.0 0.0 0.1649649325095876" rpy="0 0 0"/>
            <geometry>
                <box size="0.33964928001282935 0.27473686642541006 0.3299298650191752" />
            </geometry>
            <material name="Green">
                <color rgba="0 1.0 0 1.0"/>
            </material>
        </visual>
        <collision>
            <origin xyz="0.0 0.0 0.1649649325095876" rpy="0 0 0"/>
            <geometry>
                <box size="0.33964928001282935 0.27473686642541006 0.3299298650191752" />
            </geometry>
        </collision>
    </link>
    <joint name="Link1_Link1-0" type="revolute">
       <parent link="Link1"/>
       <child  link="Link1-0"/>
       <origin rpy="0 0 0" xyz="-0.23630109037332755 0.41524003314820135 0.0" />
     <axis xyz="[2 1 1]"/>
       <limit effort="0.0" lower="-3.14159" upper="3.14159" velocity="0.0"/>
    </joint>
    <link name="Link1-0">
        <inertial>
            <origin xyz="-0.29492235766973035 0.0 0.0" rpy="0 0 0"/>
            <mass value="1" />
            <inertia ixx="100" ixy="0" ixz="0" iyy="100" iyz="0" izz="100" />
        </inertial>
        <visual>
            <origin xyz="-0.29492235766973035 0.0 0.0" rpy="0 0 0"/>
            <geometry>
                <box size="0.5898447153394607 0.3810046274211445 0.4754880817791742" />
            </geometry>
            <material name="Blue">
                <color rgba="0 0 1.0 1.0"/>
            </material>
        </visual>
        <collision>
            <origin xyz="-0.29492235766973035 0.0 0.0" rpy="0 0 0"/>
            <geometry>
                <box size="0.5898447153394607 0.3810046274211445 0.4754880817791742" />
            </geometry>
        </collision>
    </link>
</robot>