<robot name = "robot">
    <link name="Link0">
        <inertial>
            <origin xyz="0.0 0.0 2.2112659548937343" rpy="0 0 0"/>
            <mass value="1" />
            <inertia ixx="100" ixy="0" ixz="0" iyy="100" iyz="0" izz="100" />
        </inertial>
        <visual>
            <origin xyz="0.0 0.0 2.2112659548937343" rpy="0 0 0"/>
            <geometry>
                <box size="0.37962886436305887 0.6957273965811951 0.4225319097874685" />
            </geometry>
            <material name="Green">
                <color rgba="0 1.0 0 1.0"/>
            </material>
        </visual>
        <collision>
            <origin xyz="0.0 0.0 2.2112659548937343" rpy="0 0 0"/>
            <geometry>
                <box size="0.37962886436305887 0.6957273965811951 0.4225319097874685" />
            </geometry>
        </collision>
    </link>
    <joint name="Link0_Link1" type="revolute">
       <parent link="Link0"/>
       <child  link="Link1"/>
       <origin rpy="0 0 0" xyz="0.0 0.34786369829059754 2.2112659548937343" />
     <axis xyz="1 0 1"/>
       <limit effort="0.0" lower="-3.14159" upper="3.14159" velocity="0.0"/>
    </joint>
    <link name="Link1">
        <inertial>
            <origin xyz="0.0 0.2331290400266448 0.0" rpy="0 0 0"/>
            <mass value="1" />
            <inertia ixx="100" ixy="0" ixz="0" iyy="100" iyz="0" izz="100" />
        </inertial>
        <visual>
            <origin xyz="0.0 0.2331290400266448 0.0" rpy="0 0 0"/>
            <geometry>
                <box size="0.2262782379723694 0.4662580800532896 0.292694312713638" />
            </geometry>
            <material name="Blue">
                <color rgba="0 0 1.0 1.0"/>
            </material>
        </visual>
        <collision>
            <origin xyz="0.0 0.2331290400266448 0.0" rpy="0 0 0"/>
            <geometry>
                <box size="0.2262782379723694 0.4662580800532896 0.292694312713638" />
            </geometry>
        </collision>
    </link>
    <joint name="Link1_Link2" type="revolute">
       <parent link="Link1"/>
       <child  link="Link2"/>
       <origin rpy="0 0 0" xyz="0.0 0.4662580800532896 0.0" />
     <axis xyz="[1 0 1]"/>
       <limit effort="0.0" lower="-3.14159" upper="3.14159" velocity="0.0"/>
    </joint>
    <link name="Link2">
        <inertial>
            <origin xyz="0.0 0.16576690885120865 0.0" rpy="0 0 0"/>
            <mass value="1" />
            <inertia ixx="100" ixy="0" ixz="0" iyy="100" iyz="0" izz="100" />
        </inertial>
        <visual>
            <origin xyz="0.0 0.16576690885120865 0.0" rpy="0 0 0"/>
            <geometry>
                <box size="0.4008460811534043 0.3315338177024173 0.29319931411333766" />
            </geometry>
            <material name="Blue">
                <color rgba="0 0 1.0 1.0"/>
            </material>
        </visual>
        <collision>
            <origin xyz="0.0 0.16576690885120865 0.0" rpy="0 0 0"/>
            <geometry>
                <box size="0.4008460811534043 0.3315338177024173 0.29319931411333766" />
            </geometry>
        </collision>
    </link>
    <joint name="Link2_Link2-0" type="revolute">
       <parent link="Link2"/>
       <child  link="Link2-0"/>
       <origin rpy="0 0 0" xyz="0.20042304057670216 0.16576690885120865 0.0" />
     <axis xyz="[0 1 1]"/>
       <limit effort="0.0" lower="-3.14159" upper="3.14159" velocity="0.0"/>
    </joint>
    <link name="Link2-0">
        <inertial>
            <origin xyz="0.36863761219067925 0.0 0.0" rpy="0 0 0"/>
            <mass value="1" />
            <inertia ixx="100" ixy="0" ixz="0" iyy="100" iyz="0" izz="100" />
        </inertial>
        <visual>
            <origin xyz="0.36863761219067925 0.0 0.0" rpy="0 0 0"/>
            <geometry>
                <box size="0.7372752243813585 0.8522348520544936 0.48931242332147723" />
            </geometry>
            <material name="Blue">
                <color rgba="0 0 1.0 1.0"/>
            </material>
        </visual>
        <collision>
            <origin xyz="0.36863761219067925 0.0 0.0" rpy="0 0 0"/>
            <geometry>
                <box size="0.7372752243813585 0.8522348520544936 0.48931242332147723" />
            </geometry>
        </collision>
    </link>
    <joint name="Link2_Link3" type="revolute">
       <parent link="Link2"/>
       <child  link="Link3"/>
       <origin rpy="0 0 0" xyz="0.0 0.3315338177024173 0.0" />
     <axis xyz="[1 0 1]"/>
       <limit effort="0.0" lower="-3.14159" upper="3.14159" velocity="0.0"/>
    </joint>
    <link name="Link3">
        <inertial>
            <origin xyz="0.0 0.3079330125931342 0.0" rpy="0 0 0"/>
            <mass value="1" />
            <inertia ixx="100" ixy="0" ixz="0" iyy="100" iyz="0" izz="100" />
        </inertial>
        <visual>
            <origin xyz="0.0 0.3079330125931342 0.0" rpy="0 0 0"/>
            <geometry>
                <box size="0.7951124309558981 0.6158660251862684 0.45753381403895865" />
            </geometry>
            <material name="Blue">
                <color rgba="0 0 1.0 1.0"/>
            </material>
        </visual>
        <collision>
            <origin xyz="0.0 0.3079330125931342 0.0" rpy="0 0 0"/>
            <geometry>
                <box size="0.7951124309558981 0.6158660251862684 0.45753381403895865" />
            </geometry>
        </collision>
    </link>
    <joint name="Link3_Link3-0" type="revolute">
       <parent link="Link3"/>
       <child  link="Link3-0"/>
       <origin rpy="0 0 0" xyz="0.0 0.3079330125931342 -0.22876690701947933" />
     <axis xyz="[1 1 2]"/>
       <limit effort="0.0" lower="-3.14159" upper="3.14159" velocity="0.0"/>
    </joint>
    <link name="Link3-0">
        <inertial>
            <origin xyz="0.0 0.0 -0.1622032176962692" rpy="0 0 0"/>
            <mass value="1" />
            <inertia ixx="100" ixy="0" ixz="0" iyy="100" iyz="0" izz="100" />
        </inertial>
        <visual>
            <origin xyz="0.0 0.0 -0.1622032176962692" rpy="0 0 0"/>
            <geometry>
                <box size="0.35038216047029513 0.9915342198462571 0.3244064353925384" />
            </geometry>
            <material name="Green">
                <color rgba="0 1.0 0 1.0"/>
            </material>
        </visual>
        <collision>
            <origin xyz="0.0 0.0 -0.1622032176962692" rpy="0 0 0"/>
            <geometry>
                <box size="0.35038216047029513 0.9915342198462571 0.3244064353925384" />
            </geometry>
        </collision>
    </link>
    <joint name="Link3-0_Link3-1" type="revolute">
       <parent link="Link3-0"/>
       <child  link="Link3-1"/>
       <origin rpy="0 0 0" xyz="0.0 0.0 -0.3244064353925384" />
     <axis xyz="[1 1 2]"/>
       <limit effort="0.0" lower="-3.14159" upper="3.14159" velocity="0.0"/>
    </joint>
    <link name="Link3-1">
        <inertial>
            <origin xyz="0.0 0.0 -0.19144645096947044" rpy="0 0 0"/>
            <mass value="1" />
            <inertia ixx="100" ixy="0" ixz="0" iyy="100" iyz="0" izz="100" />
        </inertial>
        <visual>
            <origin xyz="0.0 0.0 -0.19144645096947044" rpy="0 0 0"/>
            <geometry>
                <box size="0.26736426343399455 0.32527063855624627 0.3828929019389409" />
            </geometry>
            <material name="Blue">
                <color rgba="0 0 1.0 1.0"/>
            </material>
        </visual>
        <collision>
            <origin xyz="0.0 0.0 -0.19144645096947044" rpy="0 0 0"/>
            <geometry>
                <box size="0.26736426343399455 0.32527063855624627 0.3828929019389409" />
            </geometry>
        </collision>
    </link>
    <joint name="Link3-1_Link3-1-0" type="revolute">
       <parent link="Link3-1"/>
       <child  link="Link3-1-0"/>
       <origin rpy="0 0 0" xyz="0.0 0.16263531927812314 -0.19144645096947044" />
     <axis xyz="[1 0 1]"/>
       <limit effort="0.0" lower="-3.14159" upper="3.14159" velocity="0.0"/>
    </joint>
    <link name="Link3-1-0">
        <inertial>
            <origin xyz="0.0 0.46993950270538615 0.0" rpy="0 0 0"/>
            <mass value="1" />
            <inertia ixx="100" ixy="0" ixz="0" iyy="100" iyz="0" izz="100" />
        </inertial>
        <visual>
            <origin xyz="0.0 0.46993950270538615 0.0" rpy="0 0 0"/>
            <geometry>
                <box size="0.5477884702650476 0.9398790054107723 0.3013360357699652" />
            </geometry>
            <material name="Green">
                <color rgba="0 1.0 0 1.0"/>
            </material>
        </visual>
        <collision>
            <origin xyz="0.0 0.46993950270538615 0.0" rpy="0 0 0"/>
            <geometry>
                <box size="0.5477884702650476 0.9398790054107723 0.3013360357699652" />
            </geometry>
        </collision>
    </link>
    <joint name="Link3-1-0_Link3-1-1" type="revolute">
       <parent link="Link3-1-0"/>
       <child  link="Link3-1-1"/>
       <origin rpy="0 0 0" xyz="0.0 0.9398790054107723 0.0" />
     <axis xyz="[1 0 1]"/>
       <limit effort="0.0" lower="-3.14159" upper="3.14159" velocity="0.0"/>
    </joint>
    <link name="Link3-1-1">
        <inertial>
            <origin xyz="0.0 0.2552868733716533 0.0" rpy="0 0 0"/>
            <mass value="1" />
            <inertia ixx="100" ixy="0" ixz="0" iyy="100" iyz="0" izz="100" />
        </inertial>
        <visual>
            <origin xyz="0.0 0.2552868733716533 0.0" rpy="0 0 0"/>
            <geometry>
                <box size="0.5194195704715018 0.5105737467433066 0.24073999208557084" />
            </geometry>
            <material name="Green">
                <color rgba="0 1.0 0 1.0"/>
            </material>
        </visual>
        <collision>
            <origin xyz="0.0 0.2552868733716533 0.0" rpy="0 0 0"/>
            <geometry>
                <box size="0.5194195704715018 0.5105737467433066 0.24073999208557084" />
            </geometry>
        </collision>
    </link>
    <joint name="Link3-1-1_Link3-1-2" type="revolute">
       <parent link="Link3-1-1"/>
       <child  link="Link3-1-2"/>
       <origin rpy="0 0 0" xyz="0.0 0.5105737467433066 0.0" />
     <axis xyz="[1 0 1]"/>
       <limit effort="0.0" lower="-3.14159" upper="3.14159" velocity="0.0"/>
    </joint>
    <link name="Link3-1-2">
        <inertial>
            <origin xyz="0.0 0.38824030435718426 0.0" rpy="0 0 0"/>
            <mass value="1" />
            <inertia ixx="100" ixy="0" ixz="0" iyy="100" iyz="0" izz="100" />
        </inertial>
        <visual>
            <origin xyz="0.0 0.38824030435718426 0.0" rpy="0 0 0"/>
            <geometry>
                <box size="0.2775781723375666 0.7764806087143685 0.15939902269820283" />
            </geometry>
            <material name="Green">
                <color rgba="0 1.0 0 1.0"/>
            </material>
        </visual>
        <collision>
            <origin xyz="0.0 0.38824030435718426 0.0" rpy="0 0 0"/>
            <geometry>
                <box size="0.2775781723375666 0.7764806087143685 0.15939902269820283" />
            </geometry>
        </collision>
    </link>
    <joint name="Link3-1-2_Link3-1-3" type="revolute">
       <parent link="Link3-1-2"/>
       <child  link="Link3-1-3"/>
       <origin rpy="0 0 0" xyz="0.0 0.7764806087143685 0.0" />
     <axis xyz="[1 0 1]"/>
       <limit effort="0.0" lower="-3.14159" upper="3.14159" velocity="0.0"/>
    </joint>
    <link name="Link3-1-3">
        <inertial>
            <origin xyz="0.0 0.4437787808967553 0.0" rpy="0 0 0"/>
            <mass value="1" />
            <inertia ixx="100" ixy="0" ixz="0" iyy="100" iyz="0" izz="100" />
        </inertial>
        <visual>
            <origin xyz="0.0 0.4437787808967553 0.0" rpy="0 0 0"/>
            <geometry>
                <box size="0.45264503488767344 0.8875575617935106 0.42275783256622723" />
            </geometry>
            <material name="Green">
                <color rgba="0 1.0 0 1.0"/>
            </material>
        </visual>
        <collision>
            <origin xyz="0.0 0.4437787808967553 0.0" rpy="0 0 0"/>
            <geometry>
                <box size="0.45264503488767344 0.8875575617935106 0.42275783256622723" />
            </geometry>
        </collision>
    </link>
    <joint name="Link3-1_Link3-2" type="revolute">
       <parent link="Link3-1"/>
       <child  link="Link3-2"/>
       <origin rpy="0 0 0" xyz="0.0 0.0 -0.3828929019389409" />
     <axis xyz="[1 1 2]"/>
       <limit effort="0.0" lower="-3.14159" upper="3.14159" velocity="0.0"/>
    </joint>
    <link name="Link3-2">
        <inertial>
            <origin xyz="0.0 0.0 -0.19196171759949437" rpy="0 0 0"/>
            <mass value="1" />
            <inertia ixx="100" ixy="0" ixz="0" iyy="100" iyz="0" izz="100" />
        </inertial>
        <visual>
            <origin xyz="0.0 0.0 -0.19196171759949437" rpy="0 0 0"/>
            <geometry>
                <box size="0.5957704214215603 0.804416212649975 0.38392343519898875" />
            </geometry>
            <material name="Blue">
                <color rgba="0 0 1.0 1.0"/>
            </material>
        </visual>
        <collision>
            <origin xyz="0.0 0.0 -0.19196171759949437" rpy="0 0 0"/>
            <geometry>
                <box size="0.5957704214215603 0.804416212649975 0.38392343519898875" />
            </geometry>
        </collision>
    </link>
    <joint name="Link3-2_Link3-2-0" type="revolute">
       <parent link="Link3-2"/>
       <child  link="Link3-2-0"/>
       <origin rpy="0 0 0" xyz="-0.29788521071078017 0.0 -0.19196171759949437" />
     <axis xyz="[2 1 1]"/>
       <limit effort="0.0" lower="-3.14159" upper="3.14159" velocity="0.0"/>
    </joint>
    <link name="Link3-2-0">
        <inertial>
            <origin xyz="-0.3438804843169832 0.0 0.0" rpy="0 0 0"/>
            <mass value="1" />
            <inertia ixx="100" ixy="0" ixz="0" iyy="100" iyz="0" izz="100" />
        </inertial>
        <visual>
            <origin xyz="-0.3438804843169832 0.0 0.0" rpy="0 0 0"/>
            <geometry>
                <box size="0.6877609686339664 0.29997380080871083 0.49258038228672696" />
            </geometry>
            <material name="Blue">
                <color rgba="0 0 1.0 1.0"/>
            </material>
        </visual>
        <collision>
            <origin xyz="-0.3438804843169832 0.0 0.0" rpy="0 0 0"/>
            <geometry>
                <box size="0.6877609686339664 0.29997380080871083 0.49258038228672696" />
            </geometry>
        </collision>
    </link>
</robot>