<robot name = "robot">
    <link name="Link0">
        <inertial>
            <origin xyz="0.0 0.0 2.0940712037426783" rpy="0 0 0"/>
            <mass value="1" />
            <inertia ixx="100" ixy="0" ixz="0" iyy="100" iyz="0" izz="100" />
        </inertial>
        <visual>
            <origin xyz="0.0 0.0 2.0940712037426783" rpy="0 0 0"/>
            <geometry>
                <box size="0.29516694426156187 0.3830916274510865 0.18814240748535682" />
            </geometry>
            <material name="Green">
                <color rgba="0 1.0 0 1.0"/>
            </material>
        </visual>
        <collision>
            <origin xyz="0.0 0.0 2.0940712037426783" rpy="0 0 0"/>
            <geometry>
                <box size="0.29516694426156187 0.3830916274510865 0.18814240748535682" />
            </geometry>
        </collision>
    </link>
    <joint name="Link0_Link1" type="revolute">
       <parent link="Link0"/>
       <child  link="Link1"/>
       <origin rpy="0 0 0" xyz="0.0 0.19154581372554325 2.0940712037426783" />
     <axis xyz="1 0 1"/>
       <limit effort="0.0" lower="-3.14159" upper="3.14159" velocity="0.0"/>
    </joint>
    <link name="Link1">
        <inertial>
            <origin xyz="0.0 0.420539551377605 0.0" rpy="0 0 0"/>
            <mass value="1" />
            <inertia ixx="100" ixy="0" ixz="0" iyy="100" iyz="0" izz="100" />
        </inertial>
        <visual>
            <origin xyz="0.0 0.420539551377605 0.0" rpy="0 0 0"/>
            <geometry>
                <box size="0.6555045353518991 0.84107910275521 0.355613648909883" />
            </geometry>
            <material name="Green">
                <color rgba="0 1.0 0 1.0"/>
            </material>
        </visual>
        <collision>
            <origin xyz="0.0 0.420539551377605 0.0" rpy="0 0 0"/>
            <geometry>
                <box size="0.6555045353518991 0.84107910275521 0.355613648909883" />
            </geometry>
        </collision>
    </link>
    <joint name="Link1_Link2" type="revolute">
       <parent link="Link1"/>
       <child  link="Link2"/>
       <origin rpy="0 0 0" xyz="0.0 0.84107910275521 0.0" />
     <axis xyz="[1 0 1]"/>
       <limit effort="0.0" lower="-3.14159" upper="3.14159" velocity="0.0"/>
    </joint>
    <link name="Link2">
        <inertial>
            <origin xyz="0.0 0.15478763963472408 0.0" rpy="0 0 0"/>
            <mass value="1" />
            <inertia ixx="100" ixy="0" ixz="0" iyy="100" iyz="0" izz="100" />
        </inertial>
        <visual>
            <origin xyz="0.0 0.15478763963472408 0.0" rpy="0 0 0"/>
            <geometry>
                <box size="0.735611527919191 0.30957527926944817 0.3466893811994842" />
            </geometry>
            <material name="Blue">
                <color rgba="0 0 1.0 1.0"/>
            </material>
        </visual>
        <collision>
            <origin xyz="0.0 0.15478763963472408 0.0" rpy="0 0 0"/>
            <geometry>
                <box size="0.735611527919191 0.30957527926944817 0.3466893811994842" />
            </geometry>
        </collision>
    </link>
    <joint name="Link2_Link2-0" type="revolute">
       <parent link="Link2"/>
       <child  link="Link2-0"/>
       <origin rpy="0 0 0" xyz="0.0 0.15478763963472408 -0.1733446905997421" />
     <axis xyz="[1 1 2]"/>
       <limit effort="0.0" lower="-3.14159" upper="3.14159" velocity="0.0"/>
    </joint>
    <link name="Link2-0">
        <inertial>
            <origin xyz="0.0 0.0 -0.14712059734301608" rpy="0 0 0"/>
            <mass value="1" />
            <inertia ixx="100" ixy="0" ixz="0" iyy="100" iyz="0" izz="100" />
        </inertial>
        <visual>
            <origin xyz="0.0 0.0 -0.14712059734301608" rpy="0 0 0"/>
            <geometry>
                <box size="0.7009275960675176 0.5980815629958147 0.29424119468603216" />
            </geometry>
            <material name="Blue">
                <color rgba="0 0 1.0 1.0"/>
            </material>
        </visual>
        <collision>
            <origin xyz="0.0 0.0 -0.14712059734301608" rpy="0 0 0"/>
            <geometry>
                <box size="0.7009275960675176 0.5980815629958147 0.29424119468603216" />
            </geometry>
        </collision>
    </link>
    <joint name="Link2-0_Link2-0-0" type="revolute">
       <parent link="Link2-0"/>
       <child  link="Link2-0-0"/>
       <origin rpy="0 0 0" xyz="0.0 -0.29904078149790736 -0.14712059734301608" />
     <axis xyz="[1 2 1]"/>
       <limit effort="0.0" lower="-3.14159" upper="3.14159" velocity="0.0"/>
    </joint>
    <link name="Link2-0-0">
        <inertial>
            <origin xyz="0.0 -0.4134564241843081 0.0" rpy="0 0 0"/>
            <mass value="1" />
            <inertia ixx="100" ixy="0" ixz="0" iyy="100" iyz="0" izz="100" />
        </inertial>
        <visual>
            <origin xyz="0.0 -0.4134564241843081 0.0" rpy="0 0 0"/>
            <geometry>
                <box size="0.6206036311815448 0.8269128483686162 0.41127766848266956" />
            </geometry>
            <material name="Green">
                <color rgba="0 1.0 0 1.0"/>
            </material>
        </visual>
        <collision>
            <origin xyz="0.0 -0.4134564241843081 0.0" rpy="0 0 0"/>
            <geometry>
                <box size="0.6206036311815448 0.8269128483686162 0.41127766848266956" />
            </geometry>
        </collision>
    </link>
    <joint name="Link2-0_Link2-1" type="revolute">
       <parent link="Link2-0"/>
       <child  link="Link2-1"/>
       <origin rpy="0 0 0" xyz="0.0 0.0 -0.29424119468603216" />
     <axis xyz="[1 1 2]"/>
       <limit effort="0.0" lower="-3.14159" upper="3.14159" velocity="0.0"/>
    </joint>
    <link name="Link2-1">
        <inertial>
            <origin xyz="0.0 0.0 -0.07196505265248979" rpy="0 0 0"/>
            <mass value="1" />
            <inertia ixx="100" ixy="0" ixz="0" iyy="100" iyz="0" izz="100" />
        </inertial>
        <visual>
            <origin xyz="0.0 0.0 -0.07196505265248979" rpy="0 0 0"/>
            <geometry>
                <box size="0.27397585143053643 0.9797639571748944 0.14393010530497957" />
            </geometry>
            <material name="Blue">
                <color rgba="0 0 1.0 1.0"/>
            </material>
        </visual>
        <collision>
            <origin xyz="0.0 0.0 -0.07196505265248979" rpy="0 0 0"/>
            <geometry>
                <box size="0.27397585143053643 0.9797639571748944 0.14393010530497957" />
            </geometry>
        </collision>
    </link>
    <joint name="Link2-1_Link2-2" type="revolute">
       <parent link="Link2-1"/>
       <child  link="Link2-2"/>
       <origin rpy="0 0 0" xyz="0.0 0.0 -0.14393010530497957" />
     <axis xyz="[1 1 2]"/>
       <limit effort="0.0" lower="-3.14159" upper="3.14159" velocity="0.0"/>
    </joint>
    <link name="Link2-2">
        <inertial>
            <origin xyz="0.0 0.0 -0.10261295735909967" rpy="0 0 0"/>
            <mass value="1" />
            <inertia ixx="100" ixy="0" ixz="0" iyy="100" iyz="0" izz="100" />
        </inertial>
        <visual>
            <origin xyz="0.0 0.0 -0.10261295735909967" rpy="0 0 0"/>
            <geometry>
                <box size="0.6691296482976306 0.5273449735080739 0.20522591471819934" />
            </geometry>
            <material name="Blue">
                <color rgba="0 0 1.0 1.0"/>
            </material>
        </visual>
        <collision>
            <origin xyz="0.0 0.0 -0.10261295735909967" rpy="0 0 0"/>
            <geometry>
                <box size="0.6691296482976306 0.5273449735080739 0.20522591471819934" />
            </geometry>
        </collision>
    </link>
    <joint name="Link2-2_Link2-3" type="revolute">
       <parent link="Link2-2"/>
       <child  link="Link2-3"/>
       <origin rpy="0 0 0" xyz="0.0 0.0 -0.20522591471819934" />
     <axis xyz="[1 1 2]"/>
       <limit effort="0.0" lower="-3.14159" upper="3.14159" velocity="0.0"/>
    </joint>
    <link name="Link2-3">
        <inertial>
            <origin xyz="0.0 0.0 -0.07923966878424514" rpy="0 0 0"/>
            <mass value="1" />
            <inertia ixx="100" ixy="0" ixz="0" iyy="100" iyz="0" izz="100" />
        </inertial>
        <visual>
            <origin xyz="0.0 0.0 -0.07923966878424514" rpy="0 0 0"/>
            <geometry>
                <box size="0.4742818058872249 0.7420872607228294 0.15847933756849028" />
            </geometry>
            <material name="Green">
                <color rgba="0 1.0 0 1.0"/>
            </material>
        </visual>
        <collision>
            <origin xyz="0.0 0.0 -0.07923966878424514" rpy="0 0 0"/>
            <geometry>
                <box size="0.4742818058872249 0.7420872607228294 0.15847933756849028" />
            </geometry>
        </collision>
    </link>
    <joint name="Link2-0-0_Link2-0-0-0" type="revolute">
       <parent link="Link2-0-0"/>
       <child  link="Link2-0-0-0"/>
       <origin rpy="0 0 0" xyz="-0.3103018155907724 -0.4134564241843081 0.0" />
     <axis xyz="[2 1 1]"/>
       <limit effort="0.0" lower="-3.14159" upper="3.14159" velocity="0.0"/>
    </joint>
    <link name="Link2-0-0-0">
        <inertial>
            <origin xyz="-0.23641926402221444 0.0 0.0" rpy="0 0 0"/>
            <mass value="1" />
            <inertia ixx="100" ixy="0" ixz="0" iyy="100" iyz="0" izz="100" />
        </inertial>
        <visual>
            <origin xyz="-0.23641926402221444 0.0 0.0" rpy="0 0 0"/>
            <geometry>
                <box size="0.4728385280444289 0.9712774719748705 0.3227811519481223" />
            </geometry>
            <material name="Green">
                <color rgba="0 1.0 0 1.0"/>
            </material>
        </visual>
        <collision>
            <origin xyz="-0.23641926402221444 0.0 0.0" rpy="0 0 0"/>
            <geometry>
                <box size="0.4728385280444289 0.9712774719748705 0.3227811519481223" />
            </geometry>
        </collision>
    </link>
    <joint name="Link2-3_Link2-3-0" type="revolute">
       <parent link="Link2-3"/>
       <child  link="Link2-3-0"/>
       <origin rpy="0 0 0" xyz="-0.23714090294361245 0.0 -0.07923966878424514" />
     <axis xyz="[2 1 1]"/>
       <limit effort="0.0" lower="-3.14159" upper="3.14159" velocity="0.0"/>
    </joint>
    <link name="Link2-3-0">
        <inertial>
            <origin xyz="-0.26984644366165667 0.0 0.0" rpy="0 0 0"/>
            <mass value="1" />
            <inertia ixx="100" ixy="0" ixz="0" iyy="100" iyz="0" izz="100" />
        </inertial>
        <visual>
            <origin xyz="-0.26984644366165667 0.0 0.0" rpy="0 0 0"/>
            <geometry>
                <box size="0.5396928873233133 0.899532334045017 0.25005590120419635" />
            </geometry>
            <material name="Green">
                <color rgba="0 1.0 0 1.0"/>
            </material>
        </visual>
        <collision>
            <origin xyz="-0.26984644366165667 0.0 0.0" rpy="0 0 0"/>
            <geometry>
                <box size="0.5396928873233133 0.899532334045017 0.25005590120419635" />
            </geometry>
        </collision>
    </link>
</robot>