<robot name = "robot">
    <link name="Link0">
        <inertial>
            <origin xyz="0.0 0.0 2.086354409039861" rpy="0 0 0"/>
            <mass value="1" />
            <inertia ixx="100" ixy="0" ixz="0" iyy="100" iyz="0" izz="100" />
        </inertial>
        <visual>
            <origin xyz="0.0 0.0 2.086354409039861" rpy="0 0 0"/>
            <geometry>
                <box size="0.252595359854632 0.4345757863042197 0.1727088180797224" />
            </geometry>
            <material name="Green">
                <color rgba="0 1.0 0 1.0"/>
            </material>
        </visual>
        <collision>
            <origin xyz="0.0 0.0 2.086354409039861" rpy="0 0 0"/>
            <geometry>
                <box size="0.252595359854632 0.4345757863042197 0.1727088180797224" />
            </geometry>
        </collision>
    </link>
    <joint name="Link0_Link1" type="revolute">
       <parent link="Link0"/>
       <child  link="Link1"/>
       <origin rpy="0 0 0" xyz="0.0 0.21728789315210986 2.086354409039861" />
     <axis xyz="1 0 1"/>
       <limit effort="0.0" lower="-3.14159" upper="3.14159" velocity="0.0"/>
    </joint>
    <link name="Link1">
        <inertial>
            <origin xyz="0.0 0.3489881250829441 0.0" rpy="0 0 0"/>
            <mass value="1" />
            <inertia ixx="100" ixy="0" ixz="0" iyy="100" iyz="0" izz="100" />
        </inertial>
        <visual>
            <origin xyz="0.0 0.3489881250829441 0.0" rpy="0 0 0"/>
            <geometry>
                <box size="0.3326015211127602 0.6979762501658882 0.409680281872761" />
            </geometry>
            <material name="Green">
                <color rgba="0 1.0 0 1.0"/>
            </material>
        </visual>
        <collision>
            <origin xyz="0.0 0.3489881250829441 0.0" rpy="0 0 0"/>
            <geometry>
                <box size="0.3326015211127602 0.6979762501658882 0.409680281872761" />
            </geometry>
        </collision>
    </link>
    <joint name="Link1_Link2" type="revolute">
       <parent link="Link1"/>
       <child  link="Link2"/>
       <origin rpy="0 0 0" xyz="0.0 0.6979762501658882 0.0" />
     <axis xyz="[1 0 1]"/>
       <limit effort="0.0" lower="-3.14159" upper="3.14159" velocity="0.0"/>
    </joint>
    <link name="Link2">
        <inertial>
            <origin xyz="0.0 0.3720405987426413 0.0" rpy="0 0 0"/>
            <mass value="1" />
            <inertia ixx="100" ixy="0" ixz="0" iyy="100" iyz="0" izz="100" />
        </inertial>
        <visual>
            <origin xyz="0.0 0.3720405987426413 0.0" rpy="0 0 0"/>
            <geometry>
                <box size="0.5557754076893383 0.7440811974852826 0.28119758584569987" />
            </geometry>
            <material name="Blue">
                <color rgba="0 0 1.0 1.0"/>
            </material>
        </visual>
        <collision>
            <origin xyz="0.0 0.3720405987426413 0.0" rpy="0 0 0"/>
            <geometry>
                <box size="0.5557754076893383 0.7440811974852826 0.28119758584569987" />
            </geometry>
        </collision>
    </link>
    <joint name="Link2_Link2-0" type="revolute">
       <parent link="Link2"/>
       <child  link="Link2-0"/>
       <origin rpy="0 0 0" xyz="0.0 0.3720405987426413 0.14059879292284994" />
     <axis xyz="[1 1 0]"/>
       <limit effort="0.0" lower="-3.14159" upper="3.14159" velocity="0.0"/>
    </joint>
    <link name="Link2-0">
        <inertial>
            <origin xyz="0.0 0.0 0.1707421539991932" rpy="0 0 0"/>
            <mass value="1" />
            <inertia ixx="100" ixy="0" ixz="0" iyy="100" iyz="0" izz="100" />
        </inertial>
        <visual>
            <origin xyz="0.0 0.0 0.1707421539991932" rpy="0 0 0"/>
            <geometry>
                <box size="0.37219559897976345 0.8489277121618263 0.3414843079983864" />
            </geometry>
            <material name="Green">
                <color rgba="0 1.0 0 1.0"/>
            </material>
        </visual>
        <collision>
            <origin xyz="0.0 0.0 0.1707421539991932" rpy="0 0 0"/>
            <geometry>
                <box size="0.37219559897976345 0.8489277121618263 0.3414843079983864" />
            </geometry>
        </collision>
    </link>
    <joint name="Link2-0_Link2-0-0" type="revolute">
       <parent link="Link2-0"/>
       <child  link="Link2-0-0"/>
       <origin rpy="0 0 0" xyz="0.18609779948988173 0.0 0.1707421539991932" />
     <axis xyz="[0 1 1]"/>
       <limit effort="0.0" lower="-3.14159" upper="3.14159" velocity="0.0"/>
    </joint>
    <link name="Link2-0-0">
        <inertial>
            <origin xyz="0.3237755861755335 0.0 0.0" rpy="0 0 0"/>
            <mass value="1" />
            <inertia ixx="100" ixy="0" ixz="0" iyy="100" iyz="0" izz="100" />
        </inertial>
        <visual>
            <origin xyz="0.3237755861755335 0.0 0.0" rpy="0 0 0"/>
            <geometry>
                <box size="0.647551172351067 0.8708148570749077 0.14769300791256323" />
            </geometry>
            <material name="Blue">
                <color rgba="0 0 1.0 1.0"/>
            </material>
        </visual>
        <collision>
            <origin xyz="0.3237755861755335 0.0 0.0" rpy="0 0 0"/>
            <geometry>
                <box size="0.647551172351067 0.8708148570749077 0.14769300791256323" />
            </geometry>
        </collision>
    </link>
    <joint name="Link2-0-0_Link2-0-0-0" type="revolute">
       <parent link="Link2-0-0"/>
       <child  link="Link2-0-0-0"/>
       <origin rpy="0 0 0" xyz="0.3237755861755335 -0.43540742853745384 0.0" />
     <axis xyz="[1 2 1]"/>
       <limit effort="0.0" lower="-3.14159" upper="3.14159" velocity="0.0"/>
    </joint>
    <link name="Link2-0-0-0">
        <inertial>
            <origin xyz="0.0 -0.2386764338078649 0.0" rpy="0 0 0"/>
            <mass value="1" />
            <inertia ixx="100" ixy="0" ixz="0" iyy="100" iyz="0" izz="100" />
        </inertial>
        <visual>
            <origin xyz="0.0 -0.2386764338078649 0.0" rpy="0 0 0"/>
            <geometry>
                <box size="0.7179925643171485 0.4773528676157298 0.28758220284114155" />
            </geometry>
            <material name="Blue">
                <color rgba="0 0 1.0 1.0"/>
            </material>
        </visual>
        <collision>
            <origin xyz="0.0 -0.2386764338078649 0.0" rpy="0 0 0"/>
            <geometry>
                <box size="0.7179925643171485 0.4773528676157298 0.28758220284114155" />
            </geometry>
        </collision>
    </link>
    <joint name="Link2-0-0-0_Link2-0-0-1" type="revolute">
       <parent link="Link2-0-0-0"/>
       <child  link="Link2-0-0-1"/>
       <origin rpy="0 0 0" xyz="0.0 -0.4773528676157298 0.0" />
     <axis xyz="[1 2 1]"/>
       <limit effort="0.0" lower="-3.14159" upper="3.14159" velocity="0.0"/>
    </joint>
    <link name="Link2-0-0-1">
        <inertial>
            <origin xyz="0.0 -0.47769150854023257 0.0" rpy="0 0 0"/>
            <mass value="1" />
            <inertia ixx="100" ixy="0" ixz="0" iyy="100" iyz="0" izz="100" />
        </inertial>
        <visual>
            <origin xyz="0.0 -0.47769150854023257 0.0" rpy="0 0 0"/>
            <geometry>
                <box size="0.4381450460808289 0.9553830170804651 0.4581466233028012" />
            </geometry>
            <material name="Green">
                <color rgba="0 1.0 0 1.0"/>
            </material>
        </visual>
        <collision>
            <origin xyz="0.0 -0.47769150854023257 0.0" rpy="0 0 0"/>
            <geometry>
                <box size="0.4381450460808289 0.9553830170804651 0.4581466233028012" />
            </geometry>
        </collision>
    </link>
    <joint name="Link2-0-0-1_Link2-0-0-2" type="revolute">
       <parent link="Link2-0-0-1"/>
       <child  link="Link2-0-0-2"/>
       <origin rpy="0 0 0" xyz="0.0 -0.9553830170804651 0.0" />
     <axis xyz="[1 2 1]"/>
       <limit effort="0.0" lower="-3.14159" upper="3.14159" velocity="0.0"/>
    </joint>
    <link name="Link2-0-0-2">
        <inertial>
            <origin xyz="0.0 -0.4864519573825127 0.0" rpy="0 0 0"/>
            <mass value="1" />
            <inertia ixx="100" ixy="0" ixz="0" iyy="100" iyz="0" izz="100" />
        </inertial>
        <visual>
            <origin xyz="0.0 -0.4864519573825127 0.0" rpy="0 0 0"/>
            <geometry>
                <box size="0.5445886857298637 0.9729039147650254 0.2833977773542974" />
            </geometry>
            <material name="Green">
                <color rgba="0 1.0 0 1.0"/>
            </material>
        </visual>
        <collision>
            <origin xyz="0.0 -0.4864519573825127 0.0" rpy="0 0 0"/>
            <geometry>
                <box size="0.5445886857298637 0.9729039147650254 0.2833977773542974" />
            </geometry>
        </collision>
    </link>
    <joint name="Link2-0-0-2_Link2-0-0-3" type="revolute">
       <parent link="Link2-0-0-2"/>
       <child  link="Link2-0-0-3"/>
       <origin rpy="0 0 0" xyz="0.0 -0.9729039147650254 0.0" />
     <axis xyz="[1 2 1]"/>
       <limit effort="0.0" lower="-3.14159" upper="3.14159" velocity="0.0"/>
    </joint>
    <link name="Link2-0-0-3">
        <inertial>
            <origin xyz="0.0 -0.4106846289967974 0.0" rpy="0 0 0"/>
            <mass value="1" />
            <inertia ixx="100" ixy="0" ixz="0" iyy="100" iyz="0" izz="100" />
        </inertial>
        <visual>
            <origin xyz="0.0 -0.4106846289967974 0.0" rpy="0 0 0"/>
            <geometry>
                <box size="0.6913563423457021 0.8213692579935948 0.1599083574938705" />
            </geometry>
            <material name="Blue">
                <color rgba="0 0 1.0 1.0"/>
            </material>
        </visual>
        <collision>
            <origin xyz="0.0 -0.4106846289967974 0.0" rpy="0 0 0"/>
            <geometry>
                <box size="0.6913563423457021 0.8213692579935948 0.1599083574938705" />
            </geometry>
        </collision>
    </link>
    <joint name="Link2-0-0_Link2-0-1" type="revolute">
       <parent link="Link2-0-0"/>
       <child  link="Link2-0-1"/>
       <origin rpy="0 0 0" xyz="0.647551172351067 0.0 0.0" />
     <axis xyz="[0 1 1]"/>
       <limit effort="0.0" lower="-3.14159" upper="3.14159" velocity="0.0"/>
    </joint>
    <link name="Link2-0-1">
        <inertial>
            <origin xyz="0.3139099038277684 0.0 0.0" rpy="0 0 0"/>
            <mass value="1" />
            <inertia ixx="100" ixy="0" ixz="0" iyy="100" iyz="0" izz="100" />
        </inertial>
        <visual>
            <origin xyz="0.3139099038277684 0.0 0.0" rpy="0 0 0"/>
            <geometry>
                <box size="0.6278198076555368 0.8569285792670308 0.18811110526857902" />
            </geometry>
            <material name="Green">
                <color rgba="0 1.0 0 1.0"/>
            </material>
        </visual>
        <collision>
            <origin xyz="0.3139099038277684 0.0 0.0" rpy="0 0 0"/>
            <geometry>
                <box size="0.6278198076555368 0.8569285792670308 0.18811110526857902" />
            </geometry>
        </collision>
    </link>
    <joint name="Link2-0-1_Link2-0-2" type="revolute">
       <parent link="Link2-0-1"/>
       <child  link="Link2-0-2"/>
       <origin rpy="0 0 0" xyz="0.6278198076555368 0.0 0.0" />
     <axis xyz="[0 1 1]"/>
       <limit effort="0.0" lower="-3.14159" upper="3.14159" velocity="0.0"/>
    </joint>
    <link name="Link2-0-2">
        <inertial>
            <origin xyz="0.20803127282217854 0.0 0.0" rpy="0 0 0"/>
            <mass value="1" />
            <inertia ixx="100" ixy="0" ixz="0" iyy="100" iyz="0" izz="100" />
        </inertial>
        <visual>
            <origin xyz="0.20803127282217854 0.0 0.0" rpy="0 0 0"/>
            <geometry>
                <box size="0.4160625456443571 0.3418673630270548 0.2387680880623303" />
            </geometry>
            <material name="Blue">
                <color rgba="0 0 1.0 1.0"/>
            </material>
        </visual>
        <collision>
            <origin xyz="0.20803127282217854 0.0 0.0" rpy="0 0 0"/>
            <geometry>
                <box size="0.4160625456443571 0.3418673630270548 0.2387680880623303" />
            </geometry>
        </collision>
    </link>
    <joint name="Link2-0-2_Link2-0-3" type="revolute">
       <parent link="Link2-0-2"/>
       <child  link="Link2-0-3"/>
       <origin rpy="0 0 0" xyz="0.4160625456443571 0.0 0.0" />
     <axis xyz="[0 1 1]"/>
       <limit effort="0.0" lower="-3.14159" upper="3.14159" velocity="0.0"/>
    </joint>
    <link name="Link2-0-3">
        <inertial>
            <origin xyz="0.26255246686152794 0.0 0.0" rpy="0 0 0"/>
            <mass value="1" />
            <inertia ixx="100" ixy="0" ixz="0" iyy="100" iyz="0" izz="100" />
        </inertial>
        <visual>
            <origin xyz="0.26255246686152794 0.0 0.0" rpy="0 0 0"/>
            <geometry>
                <box size="0.5251049337230559 0.35834155938477696 0.47222479108870596" />
            </geometry>
            <material name="Blue">
                <color rgba="0 0 1.0 1.0"/>
            </material>
        </visual>
        <collision>
            <origin xyz="0.26255246686152794 0.0 0.0" rpy="0 0 0"/>
            <geometry>
                <box size="0.5251049337230559 0.35834155938477696 0.47222479108870596" />
            </geometry>
        </collision>
    </link>
    <joint name="Link2-0-3_Link2-0-3-0" type="revolute">
       <parent link="Link2-0-3"/>
       <child  link="Link2-0-3-0"/>
       <origin rpy="0 0 0" xyz="0.26255246686152794 0.0 0.23611239554435298" />
     <axis xyz="[1 1 0]"/>
       <limit effort="0.0" lower="-3.14159" upper="3.14159" velocity="0.0"/>
    </joint>
    <link name="Link2-0-3-0">
        <inertial>
            <origin xyz="0.0 0.0 0.2113670911579232" rpy="0 0 0"/>
            <mass value="1" />
            <inertia ixx="100" ixy="0" ixz="0" iyy="100" iyz="0" izz="100" />
        </inertial>
        <visual>
            <origin xyz="0.0 0.0 0.2113670911579232" rpy="0 0 0"/>
            <geometry>
                <box size="0.23935881080206928 0.7790970044473902 0.4227341823158464" />
            </geometry>
            <material name="Green">
                <color rgba="0 1.0 0 1.0"/>
            </material>
        </visual>
        <collision>
            <origin xyz="0.0 0.0 0.2113670911579232" rpy="0 0 0"/>
            <geometry>
                <box size="0.23935881080206928 0.7790970044473902 0.4227341823158464" />
            </geometry>
        </collision>
    </link>
    <joint name="Link2-0-3-0_Link2-0-3-1" type="revolute">
       <parent link="Link2-0-3-0"/>
       <child  link="Link2-0-3-1"/>
       <origin rpy="0 0 0" xyz="0.0 0.0 0.4227341823158464" />
     <axis xyz="[1 1 0]"/>
       <limit effort="0.0" lower="-3.14159" upper="3.14159" velocity="0.0"/>
    </joint>
    <link name="Link2-0-3-1">
        <inertial>
            <origin xyz="0.0 0.0 0.1017310694163623" rpy="0 0 0"/>
            <mass value="1" />
            <inertia ixx="100" ixy="0" ixz="0" iyy="100" iyz="0" izz="100" />
        </inertial>
        <visual>
            <origin xyz="0.0 0.0 0.1017310694163623" rpy="0 0 0"/>
            <geometry>
                <box size="0.24265261572804928 0.964754326333243 0.2034621388327246" />
            </geometry>
            <material name="Green">
                <color rgba="0 1.0 0 1.0"/>
            </material>
        </visual>
        <collision>
            <origin xyz="0.0 0.0 0.1017310694163623" rpy="0 0 0"/>
            <geometry>
                <box size="0.24265261572804928 0.964754326333243 0.2034621388327246" />
            </geometry>
        </collision>
    </link>
    <joint name="Link2-0-3-1_Link2-0-3-2" type="revolute">
       <parent link="Link2-0-3-1"/>
       <child  link="Link2-0-3-2"/>
       <origin rpy="0 0 0" xyz="0.0 0.0 0.2034621388327246" />
     <axis xyz="[1 1 0]"/>
       <limit effort="0.0" lower="-3.14159" upper="3.14159" velocity="0.0"/>
    </joint>
    <link name="Link2-0-3-2">
        <inertial>
            <origin xyz="0.0 0.0 0.20911110624137869" rpy="0 0 0"/>
            <mass value="1" />
            <inertia ixx="100" ixy="0" ixz="0" iyy="100" iyz="0" izz="100" />
        </inertial>
        <visual>
            <origin xyz="0.0 0.0 0.20911110624137869" rpy="0 0 0"/>
            <geometry>
                <box size="0.5057535964351886 0.7638378117367388 0.41822221248275737" />
            </geometry>
            <material name="Blue">
                <color rgba="0 0 1.0 1.0"/>
            </material>
        </visual>
        <collision>
            <origin xyz="0.0 0.0 0.20911110624137869" rpy="0 0 0"/>
            <geometry>
                <box size="0.5057535964351886 0.7638378117367388 0.41822221248275737" />
            </geometry>
        </collision>
    </link>
    <joint name="Link2-0-3-2_Link2-0-3-3" type="revolute">
       <parent link="Link2-0-3-2"/>
       <child  link="Link2-0-3-3"/>
       <origin rpy="0 0 0" xyz="0.0 0.0 0.41822221248275737" />
     <axis xyz="[1 1 0]"/>
       <limit effort="0.0" lower="-3.14159" upper="3.14159" velocity="0.0"/>
    </joint>
    <link name="Link2-0-3-3">
        <inertial>
            <origin xyz="0.0 0.0 0.10615330166673964" rpy="0 0 0"/>
            <mass value="1" />
            <inertia ixx="100" ixy="0" ixz="0" iyy="100" iyz="0" izz="100" />
        </inertial>
        <visual>
            <origin xyz="0.0 0.0 0.10615330166673964" rpy="0 0 0"/>
            <geometry>
                <box size="0.33558087643615353 0.9221759530504499 0.21230660333347928" />
            </geometry>
            <material name="Green">
                <color rgba="0 1.0 0 1.0"/>
            </material>
        </visual>
        <collision>
            <origin xyz="0.0 0.0 0.10615330166673964" rpy="0 0 0"/>
            <geometry>
                <box size="0.33558087643615353 0.9221759530504499 0.21230660333347928" />
            </geometry>
        </collision>
    </link>
    <joint name="Link2-0-3-3_Link2-0-3-4" type="revolute">
       <parent link="Link2-0-3-3"/>
       <child  link="Link2-0-3-4"/>
       <origin rpy="0 0 0" xyz="0.0 0.0 0.21230660333347928" />
     <axis xyz="[1 1 0]"/>
       <limit effort="0.0" lower="-3.14159" upper="3.14159" velocity="0.0"/>
    </joint>
    <link name="Link2-0-3-4">
        <inertial>
            <origin xyz="0.0 0.0 0.2413570963809552" rpy="0 0 0"/>
            <mass value="1" />
            <inertia ixx="100" ixy="0" ixz="0" iyy="100" iyz="0" izz="100" />
        </inertial>
        <visual>
            <origin xyz="0.0 0.0 0.2413570963809552" rpy="0 0 0"/>
            <geometry>
                <box size="0.5932254440292023 0.45817037438113645 0.4827141927619104" />
            </geometry>
            <material name="Blue">
                <color rgba="0 0 1.0 1.0"/>
            </material>
        </visual>
        <collision>
            <origin xyz="0.0 0.0 0.2413570963809552" rpy="0 0 0"/>
            <geometry>
                <box size="0.5932254440292023 0.45817037438113645 0.4827141927619104" />
            </geometry>
        </collision>
    </link>
    <joint name="Link2-0_Link2-1" type="revolute">
       <parent link="Link2-0"/>
       <child  link="Link2-1"/>
       <origin rpy="0 0 0" xyz="0.0 0.0 0.3414843079983864" />
     <axis xyz="[1 1 0]"/>
       <limit effort="0.0" lower="-3.14159" upper="3.14159" velocity="0.0"/>
    </joint>
    <link name="Link2-1">
        <inertial>
            <origin xyz="0.0 0.0 0.11759830564692979" rpy="0 0 0"/>
            <mass value="1" />
            <inertia ixx="100" ixy="0" ixz="0" iyy="100" iyz="0" izz="100" />
        </inertial>
        <visual>
            <origin xyz="0.0 0.0 0.11759830564692979" rpy="0 0 0"/>
            <geometry>
                <box size="0.5905928434143074 0.8913933839701329 0.23519661129385958" />
            </geometry>
            <material name="Blue">
                <color rgba="0 0 1.0 1.0"/>
            </material>
        </visual>
        <collision>
            <origin xyz="0.0 0.0 0.11759830564692979" rpy="0 0 0"/>
            <geometry>
                <box size="0.5905928434143074 0.8913933839701329 0.23519661129385958" />
            </geometry>
        </collision>
    </link>
    <joint name="Link2-1_Link2-1-0" type="revolute">
       <parent link="Link2-1"/>
       <child  link="Link2-1-0"/>
       <origin rpy="0 0 0" xyz="0.0 0.44569669198506645 0.11759830564692979" />
     <axis xyz="[1 0 1]"/>
       <limit effort="0.0" lower="-3.14159" upper="3.14159" velocity="0.0"/>
    </joint>
    <link name="Link2-1-0">
        <inertial>
            <origin xyz="0.0 0.3043687888799556 0.0" rpy="0 0 0"/>
            <mass value="1" />
            <inertia ixx="100" ixy="0" ixz="0" iyy="100" iyz="0" izz="100" />
        </inertial>
        <visual>
            <origin xyz="0.0 0.3043687888799556 0.0" rpy="0 0 0"/>
            <geometry>
                <box size="0.7911733624817098 0.6087375777599112 0.31082209148068296" />
            </geometry>
            <material name="Green">
                <color rgba="0 1.0 0 1.0"/>
            </material>
        </visual>
        <collision>
            <origin xyz="0.0 0.3043687888799556 0.0" rpy="0 0 0"/>
            <geometry>
                <box size="0.7911733624817098 0.6087375777599112 0.31082209148068296" />
            </geometry>
        </collision>
    </link>
    <joint name="Link2-1-0_Link2-1-1" type="revolute">
       <parent link="Link2-1-0"/>
       <child  link="Link2-1-1"/>
       <origin rpy="0 0 0" xyz="0.0 0.6087375777599112 0.0" />
     <axis xyz="[1 0 1]"/>
       <limit effort="0.0" lower="-3.14159" upper="3.14159" velocity="0.0"/>
    </joint>
    <link name="Link2-1-1">
        <inertial>
            <origin xyz="0.0 0.2037766944738473 0.0" rpy="0 0 0"/>
            <mass value="1" />
            <inertia ixx="100" ixy="0" ixz="0" iyy="100" iyz="0" izz="100" />
        </inertial>
        <visual>
            <origin xyz="0.0 0.2037766944738473 0.0" rpy="0 0 0"/>
            <geometry>
                <box size="0.5551362449505204 0.4075533889476946 0.42117327835444496" />
            </geometry>
            <material name="Green">
                <color rgba="0 1.0 0 1.0"/>
            </material>
        </visual>
        <collision>
            <origin xyz="0.0 0.2037766944738473 0.0" rpy="0 0 0"/>
            <geometry>
                <box size="0.5551362449505204 0.4075533889476946 0.42117327835444496" />
            </geometry>
        </collision>
    </link>
    <joint name="Link2-1-1_Link2-1-1-0" type="revolute">
       <parent link="Link2-1-1"/>
       <child  link="Link2-1-1-0"/>
       <origin rpy="0 0 0" xyz="0.0 0.2037766944738473 -0.21058663917722248" />
     <axis xyz="[1 1 2]"/>
       <limit effort="0.0" lower="-3.14159" upper="3.14159" velocity="0.0"/>
    </joint>
    <link name="Link2-1-1-0">
        <inertial>
            <origin xyz="0.0 0.0 -0.18032656454642426" rpy="0 0 0"/>
            <mass value="1" />
            <inertia ixx="100" ixy="0" ixz="0" iyy="100" iyz="0" izz="100" />
        </inertial>
        <visual>
            <origin xyz="0.0 0.0 -0.18032656454642426" rpy="0 0 0"/>
            <geometry>
                <box size="0.7784038481519695 0.42063113637409055 0.3606531290928485" />
            </geometry>
            <material name="Blue">
                <color rgba="0 0 1.0 1.0"/>
            </material>
        </visual>
        <collision>
            <origin xyz="0.0 0.0 -0.18032656454642426" rpy="0 0 0"/>
            <geometry>
                <box size="0.7784038481519695 0.42063113637409055 0.3606531290928485" />
            </geometry>
        </collision>
    </link>
    <joint name="Link2-1-1-0_Link2-1-1-1" type="revolute">
       <parent link="Link2-1-1-0"/>
       <child  link="Link2-1-1-1"/>
       <origin rpy="0 0 0" xyz="0.0 0.0 -0.3606531290928485" />
     <axis xyz="[1 1 2]"/>
       <limit effort="0.0" lower="-3.14159" upper="3.14159" velocity="0.0"/>
    </joint>
    <link name="Link2-1-1-1">
        <inertial>
            <origin xyz="0.0 0.0 -0.10493696556287913" rpy="0 0 0"/>
            <mass value="1" />
            <inertia ixx="100" ixy="0" ixz="0" iyy="100" iyz="0" izz="100" />
        </inertial>
        <visual>
            <origin xyz="0.0 0.0 -0.10493696556287913" rpy="0 0 0"/>
            <geometry>
                <box size="0.23050790920044642 0.39492742439250894 0.20987393112575825" />
            </geometry>
            <material name="Blue">
                <color rgba="0 0 1.0 1.0"/>
            </material>
        </visual>
        <collision>
            <origin xyz="0.0 0.0 -0.10493696556287913" rpy="0 0 0"/>
            <geometry>
                <box size="0.23050790920044642 0.39492742439250894 0.20987393112575825" />
            </geometry>
        </collision>
    </link>
    <joint name="Link2-1-1-1_Link2-1-1-2" type="revolute">
       <parent link="Link2-1-1-1"/>
       <child  link="Link2-1-1-2"/>
       <origin rpy="0 0 0" xyz="0.0 0.0 -0.20987393112575825" />
     <axis xyz="[1 1 2]"/>
       <limit effort="0.0" lower="-3.14159" upper="3.14159" velocity="0.0"/>
    </joint>
    <link name="Link2-1-1-2">
        <inertial>
            <origin xyz="0.0 0.0 -0.21035391662679115" rpy="0 0 0"/>
            <mass value="1" />
            <inertia ixx="100" ixy="0" ixz="0" iyy="100" iyz="0" izz="100" />
        </inertial>
        <visual>
            <origin xyz="0.0 0.0 -0.21035391662679115" rpy="0 0 0"/>
            <geometry>
                <box size="0.6158534568329426 0.6275064088804545 0.4207078332535823" />
            </geometry>
            <material name="Green">
                <color rgba="0 1.0 0 1.0"/>
            </material>
        </visual>
        <collision>
            <origin xyz="0.0 0.0 -0.21035391662679115" rpy="0 0 0"/>
            <geometry>
                <box size="0.6158534568329426 0.6275064088804545 0.4207078332535823" />
            </geometry>
        </collision>
    </link>
    <joint name="Link2-1-1_Link2-1-2" type="revolute">
       <parent link="Link2-1-1"/>
       <child  link="Link2-1-2"/>
       <origin rpy="0 0 0" xyz="0.0 0.4075533889476946 0.0" />
     <axis xyz="[1 0 1]"/>
       <limit effort="0.0" lower="-3.14159" upper="3.14159" velocity="0.0"/>
    </joint>
    <link name="Link2-1-2">
        <inertial>
            <origin xyz="0.0 0.3084705988426921 0.0" rpy="0 0 0"/>
            <mass value="1" />
            <inertia ixx="100" ixy="0" ixz="0" iyy="100" iyz="0" izz="100" />
        </inertial>
        <visual>
            <origin xyz="0.0 0.3084705988426921 0.0" rpy="0 0 0"/>
            <geometry>
                <box size="0.2632060069738637 0.6169411976853842 0.35440164874925667" />
            </geometry>
            <material name="Blue">
                <color rgba="0 0 1.0 1.0"/>
            </material>
        </visual>
        <collision>
            <origin xyz="0.0 0.3084705988426921 0.0" rpy="0 0 0"/>
            <geometry>
                <box size="0.2632060069738637 0.6169411976853842 0.35440164874925667" />
            </geometry>
        </collision>
    </link>
    <joint name="Link2-1-2_Link2-1-3" type="revolute">
       <parent link="Link2-1-2"/>
       <child  link="Link2-1-3"/>
       <origin rpy="0 0 0" xyz="0.0 0.6169411976853842 0.0" />
     <axis xyz="[1 0 1]"/>
       <limit effort="0.0" lower="-3.14159" upper="3.14159" velocity="0.0"/>
    </joint>
    <link name="Link2-1-3">
        <inertial>
            <origin xyz="0.0 0.2012925091576243 0.0" rpy="0 0 0"/>
            <mass value="1" />
            <inertia ixx="100" ixy="0" ixz="0" iyy="100" iyz="0" izz="100" />
        </inertial>
        <visual>
            <origin xyz="0.0 0.2012925091576243 0.0" rpy="0 0 0"/>
            <geometry>
                <box size="0.5945972530336312 0.4025850183152486 0.3493580179267777" />
            </geometry>
            <material name="Blue">
                <color rgba="0 0 1.0 1.0"/>
            </material>
        </visual>
        <collision>
            <origin xyz="0.0 0.2012925091576243 0.0" rpy="0 0 0"/>
            <geometry>
                <box size="0.5945972530336312 0.4025850183152486 0.3493580179267777" />
            </geometry>
        </collision>
    </link>
    <joint name="Link2-1-3_Link2-1-4" type="revolute">
       <parent link="Link2-1-3"/>
       <child  link="Link2-1-4"/>
       <origin rpy="0 0 0" xyz="0.0 0.4025850183152486 0.0" />
     <axis xyz="[1 0 1]"/>
       <limit effort="0.0" lower="-3.14159" upper="3.14159" velocity="0.0"/>
    </joint>
    <link name="Link2-1-4">
        <inertial>
            <origin xyz="0.0 0.38074179548409504 0.0" rpy="0 0 0"/>
            <mass value="1" />
            <inertia ixx="100" ixy="0" ixz="0" iyy="100" iyz="0" izz="100" />
        </inertial>
        <visual>
            <origin xyz="0.0 0.38074179548409504 0.0" rpy="0 0 0"/>
            <geometry>
                <box size="0.5575311252858376 0.7614835909681901 0.18044878330745073" />
            </geometry>
            <material name="Green">
                <color rgba="0 1.0 0 1.0"/>
            </material>
        </visual>
        <collision>
            <origin xyz="0.0 0.38074179548409504 0.0" rpy="0 0 0"/>
            <geometry>
                <box size="0.5575311252858376 0.7614835909681901 0.18044878330745073" />
            </geometry>
        </collision>
    </link>
    <joint name="Link2-1_Link2-2" type="revolute">
       <parent link="Link2-1"/>
       <child  link="Link2-2"/>
       <origin rpy="0 0 0" xyz="0.0 0.0 0.23519661129385958" />
     <axis xyz="[1 1 0]"/>
       <limit effort="0.0" lower="-3.14159" upper="3.14159" velocity="0.0"/>
    </joint>
    <link name="Link2-2">
        <inertial>
            <origin xyz="0.0 0.0 0.22905818015207827" rpy="0 0 0"/>
            <mass value="1" />
            <inertia ixx="100" ixy="0" ixz="0" iyy="100" iyz="0" izz="100" />
        </inertial>
        <visual>
            <origin xyz="0.0 0.0 0.22905818015207827" rpy="0 0 0"/>
            <geometry>
                <box size="0.6856929485522554 0.7491818715476767 0.45811636030415653" />
            </geometry>
            <material name="Green">
                <color rgba="0 1.0 0 1.0"/>
            </material>
        </visual>
        <collision>
            <origin xyz="0.0 0.0 0.22905818015207827" rpy="0 0 0"/>
            <geometry>
                <box size="0.6856929485522554 0.7491818715476767 0.45811636030415653" />
            </geometry>
        </collision>
    </link>
    <joint name="Link2-2_Link2-2-0" type="revolute">
       <parent link="Link2-2"/>
       <child  link="Link2-2-0"/>
       <origin rpy="0 0 0" xyz="0.0 -0.37459093577383834 0.22905818015207827" />
     <axis xyz="[1 2 1]"/>
       <limit effort="0.0" lower="-3.14159" upper="3.14159" velocity="0.0"/>
    </joint>
    <link name="Link2-2-0">
        <inertial>
            <origin xyz="0.0 -0.4511767510512399 0.0" rpy="0 0 0"/>
            <mass value="1" />
            <inertia ixx="100" ixy="0" ixz="0" iyy="100" iyz="0" izz="100" />
        </inertial>
        <visual>
            <origin xyz="0.0 -0.4511767510512399 0.0" rpy="0 0 0"/>
            <geometry>
                <box size="0.3514791870019545 0.9023535021024798 0.4423177405415979" />
            </geometry>
            <material name="Blue">
                <color rgba="0 0 1.0 1.0"/>
            </material>
        </visual>
        <collision>
            <origin xyz="0.0 -0.4511767510512399 0.0" rpy="0 0 0"/>
            <geometry>
                <box size="0.3514791870019545 0.9023535021024798 0.4423177405415979" />
            </geometry>
        </collision>
    </link>
    <joint name="Link2-2-0_Link2-2-1" type="revolute">
       <parent link="Link2-2-0"/>
       <child  link="Link2-2-1"/>
       <origin rpy="0 0 0" xyz="0.0 -0.9023535021024798 0.0" />
     <axis xyz="[1 2 1]"/>
       <limit effort="0.0" lower="-3.14159" upper="3.14159" velocity="0.0"/>
    </joint>
    <link name="Link2-2-1">
        <inertial>
            <origin xyz="0.0 -0.4810796431352486 0.0" rpy="0 0 0"/>
            <mass value="1" />
            <inertia ixx="100" ixy="0" ixz="0" iyy="100" iyz="0" izz="100" />
        </inertial>
        <visual>
            <origin xyz="0.0 -0.4810796431352486 0.0" rpy="0 0 0"/>
            <geometry>
                <box size="0.5294449352900558 0.9621592862704972 0.30084982431964247" />
            </geometry>
            <material name="Green">
                <color rgba="0 1.0 0 1.0"/>
            </material>
        </visual>
        <collision>
            <origin xyz="0.0 -0.4810796431352486 0.0" rpy="0 0 0"/>
            <geometry>
                <box size="0.5294449352900558 0.9621592862704972 0.30084982431964247" />
            </geometry>
        </collision>
    </link>
    <joint name="Link2-2-1_Link2-2-2" type="revolute">
       <parent link="Link2-2-1"/>
       <child  link="Link2-2-2"/>
       <origin rpy="0 0 0" xyz="0.0 -0.9621592862704972 0.0" />
     <axis xyz="[1 2 1]"/>
       <limit effort="0.0" lower="-3.14159" upper="3.14159" velocity="0.0"/>
    </joint>
    <link name="Link2-2-2">
        <inertial>
            <origin xyz="0.0 -0.30517400866047534 0.0" rpy="0 0 0"/>
            <mass value="1" />
            <inertia ixx="100" ixy="0" ixz="0" iyy="100" iyz="0" izz="100" />
        </inertial>
        <visual>
            <origin xyz="0.0 -0.30517400866047534 0.0" rpy="0 0 0"/>
            <geometry>
                <box size="0.531315356555476 0.6103480173209507 0.27950959808342174" />
            </geometry>
            <material name="Blue">
                <color rgba="0 0 1.0 1.0"/>
            </material>
        </visual>
        <collision>
            <origin xyz="0.0 -0.30517400866047534 0.0" rpy="0 0 0"/>
            <geometry>
                <box size="0.531315356555476 0.6103480173209507 0.27950959808342174" />
            </geometry>
        </collision>
    </link>
    <joint name="Link2-2-2_Link2-2-3" type="revolute">
       <parent link="Link2-2-2"/>
       <child  link="Link2-2-3"/>
       <origin rpy="0 0 0" xyz="0.0 -0.6103480173209507 0.0" />
     <axis xyz="[1 2 1]"/>
       <limit effort="0.0" lower="-3.14159" upper="3.14159" velocity="0.0"/>
    </joint>
    <link name="Link2-2-3">
        <inertial>
            <origin xyz="0.0 -0.15115629919220003 0.0" rpy="0 0 0"/>
            <mass value="1" />
            <inertia ixx="100" ixy="0" ixz="0" iyy="100" iyz="0" izz="100" />
        </inertial>
        <visual>
            <origin xyz="0.0 -0.15115629919220003 0.0" rpy="0 0 0"/>
            <geometry>
                <box size="0.520250960013193 0.30231259838440006 0.3554128045724819" />
            </geometry>
            <material name="Green">
                <color rgba="0 1.0 0 1.0"/>
            </material>
        </visual>
        <collision>
            <origin xyz="0.0 -0.15115629919220003 0.0" rpy="0 0 0"/>
            <geometry>
                <box size="0.520250960013193 0.30231259838440006 0.3554128045724819" />
            </geometry>
        </collision>
    </link>
    <joint name="Link2-2_Link2-3" type="revolute">
       <parent link="Link2-2"/>
       <child  link="Link2-3"/>
       <origin rpy="0 0 0" xyz="0.0 0.0 0.45811636030415653" />
     <axis xyz="[1 1 0]"/>
       <limit effort="0.0" lower="-3.14159" upper="3.14159" velocity="0.0"/>
    </joint>
    <link name="Link2-3">
        <inertial>
            <origin xyz="0.0 0.0 0.18039388237259996" rpy="0 0 0"/>
            <mass value="1" />
            <inertia ixx="100" ixy="0" ixz="0" iyy="100" iyz="0" izz="100" />
        </inertial>
        <visual>
            <origin xyz="0.0 0.0 0.18039388237259996" rpy="0 0 0"/>
            <geometry>
                <box size="0.5616488998547162 0.3476349258826001 0.3607877647451999" />
            </geometry>
            <material name="Green">
                <color rgba="0 1.0 0 1.0"/>
            </material>
        </visual>
        <collision>
            <origin xyz="0.0 0.0 0.18039388237259996" rpy="0 0 0"/>
            <geometry>
                <box size="0.5616488998547162 0.3476349258826001 0.3607877647451999" />
            </geometry>
        </collision>
    </link>
    <joint name="Link2-3_Link2-3-0" type="revolute">
       <parent link="Link2-3"/>
       <child  link="Link2-3-0"/>
       <origin rpy="0 0 0" xyz="-0.2808244499273581 0.0 0.18039388237259996" />
     <axis xyz="[2 1 1]"/>
       <limit effort="0.0" lower="-3.14159" upper="3.14159" velocity="0.0"/>
    </joint>
    <link name="Link2-3-0">
        <inertial>
            <origin xyz="-0.28926095424191584 0.0 0.0" rpy="0 0 0"/>
            <mass value="1" />
            <inertia ixx="100" ixy="0" ixz="0" iyy="100" iyz="0" izz="100" />
        </inertial>
        <visual>
            <origin xyz="-0.28926095424191584 0.0 0.0" rpy="0 0 0"/>
            <geometry>
                <box size="0.5785219084838317 0.9979373151092509 0.12626538997757475" />
            </geometry>
            <material name="Green">
                <color rgba="0 1.0 0 1.0"/>
            </material>
        </visual>
        <collision>
            <origin xyz="-0.28926095424191584 0.0 0.0" rpy="0 0 0"/>
            <geometry>
                <box size="0.5785219084838317 0.9979373151092509 0.12626538997757475" />
            </geometry>
        </collision>
    </link>
    <joint name="Link2-0-0-2_Link2-0-0-2-0" type="revolute">
       <parent link="Link2-0-0-2"/>
       <child  link="Link2-0-0-2-0"/>
       <origin rpy="0 0 0" xyz="0.27229434286493187 -0.4864519573825127 0.0" />
     <axis xyz="[0 1 1]"/>
       <limit effort="0.0" lower="-3.14159" upper="3.14159" velocity="0.0"/>
    </joint>
    <link name="Link2-0-0-2-0">
        <inertial>
            <origin xyz="0.2603502950691578 0.0 0.0" rpy="0 0 0"/>
            <mass value="1" />
            <inertia ixx="100" ixy="0" ixz="0" iyy="100" iyz="0" izz="100" />
        </inertial>
        <visual>
            <origin xyz="0.2603502950691578 0.0 0.0" rpy="0 0 0"/>
            <geometry>
                <box size="0.5207005901383156 0.645635231393017 0.44345161302330643" />
            </geometry>
            <material name="Green">
                <color rgba="0 1.0 0 1.0"/>
            </material>
        </visual>
        <collision>
            <origin xyz="0.2603502950691578 0.0 0.0" rpy="0 0 0"/>
            <geometry>
                <box size="0.5207005901383156 0.645635231393017 0.44345161302330643" />
            </geometry>
        </collision>
    </link>
    <joint name="Link2-0-3-3_Link2-0-3-3-0" type="revolute">
       <parent link="Link2-0-3-3"/>
       <child  link="Link2-0-3-3-0"/>
       <origin rpy="0 0 0" xyz="-0.16779043821807677 0.0 0.10615330166673964" />
     <axis xyz="[2 1 1]"/>
       <limit effort="0.0" lower="-3.14159" upper="3.14159" velocity="0.0"/>
    </joint>
    <link name="Link2-0-3-3-0">
        <inertial>
            <origin xyz="-0.25069918160216587 0.0 0.0" rpy="0 0 0"/>
            <mass value="1" />
            <inertia ixx="100" ixy="0" ixz="0" iyy="100" iyz="0" izz="100" />
        </inertial>
        <visual>
            <origin xyz="-0.25069918160216587 0.0 0.0" rpy="0 0 0"/>
            <geometry>
                <box size="0.5013983632043317 0.4862511081230656 0.4221121950960818" />
            </geometry>
            <material name="Blue">
                <color rgba="0 0 1.0 1.0"/>
            </material>
        </visual>
        <collision>
            <origin xyz="-0.25069918160216587 0.0 0.0" rpy="0 0 0"/>
            <geometry>
                <box size="0.5013983632043317 0.4862511081230656 0.4221121950960818" />
            </geometry>
        </collision>
    </link>
    <joint name="Link2-0-3-3-0_Link2-0-3-3-0-0" type="revolute">
       <parent link="Link2-0-3-3-0"/>
       <child  link="Link2-0-3-3-0-0"/>
       <origin rpy="0 0 0" xyz="-0.25069918160216587 0.2431255540615328 0.0" />
     <axis xyz="[1 0 1]"/>
       <limit effort="0.0" lower="-3.14159" upper="3.14159" velocity="0.0"/>
    </joint>
    <link name="Link2-0-3-3-0-0">
        <inertial>
            <origin xyz="0.0 0.37952155467243176 0.0" rpy="0 0 0"/>
            <mass value="1" />
            <inertia ixx="100" ixy="0" ixz="0" iyy="100" iyz="0" izz="100" />
        </inertial>
        <visual>
            <origin xyz="0.0 0.37952155467243176 0.0" rpy="0 0 0"/>
            <geometry>
                <box size="0.26261194051913 0.7590431093448635 0.3920004127507759" />
            </geometry>
            <material name="Green">
                <color rgba="0 1.0 0 1.0"/>
            </material>
        </visual>
        <collision>
            <origin xyz="0.0 0.37952155467243176 0.0" rpy="0 0 0"/>
            <geometry>
                <box size="0.26261194051913 0.7590431093448635 0.3920004127507759" />
            </geometry>
        </collision>
    </link>
</robot>