<robot name = "robot">
    <link name="Link0">
        <inertial>
            <origin xyz="0.0 0.0 2.1380445238662658" rpy="0 0 0"/>
            <mass value="1" />
            <inertia ixx="100" ixy="0" ixz="0" iyy="100" iyz="0" izz="100" />
        </inertial>
        <visual>
            <origin xyz="0.0 0.0 2.1380445238662658" rpy="0 0 0"/>
            <geometry>
                <box size="0.5281145080860867 0.8510052521912779 0.2760890477325319" />
            </geometry>
            <material name="Green">
                <color rgba="0 1.0 0 1.0"/>
            </material>
        </visual>
        <collision>
            <origin xyz="0.0 0.0 2.1380445238662658" rpy="0 0 0"/>
            <geometry>
                <box size="0.5281145080860867 0.8510052521912779 0.2760890477325319" />
            </geometry>
        </collision>
    </link>
    <joint name="Link0_Link1" type="revolute">
       <parent link="Link0"/>
       <child  link="Link1"/>
       <origin rpy="0 0 0" xyz="0.0 0.42550262609563894 2.1380445238662658" />
     <axis xyz="1 0 1"/>
       <limit effort="0.0" lower="-3.14159" upper="3.14159" velocity="0.0"/>
    </joint>
    <link name="Link1">
        <inertial>
            <origin xyz="0.0 0.22573369251833536 0.0" rpy="0 0 0"/>
            <mass value="1" />
            <inertia ixx="100" ixy="0" ixz="0" iyy="100" iyz="0" izz="100" />
        </inertial>
        <visual>
            <origin xyz="0.0 0.22573369251833536 0.0" rpy="0 0 0"/>
            <geometry>
                <box size="0.5631752155690227 0.4514673850366707 0.2021798401064075" />
            </geometry>
            <material name="Blue">
                <color rgba="0 0 1.0 1.0"/>
            </material>
        </visual>
        <collision>
            <origin xyz="0.0 0.22573369251833536 0.0" rpy="0 0 0"/>
            <geometry>
                <box size="0.5631752155690227 0.4514673850366707 0.2021798401064075" />
            </geometry>
        </collision>
    </link>
    <joint name="Link1_Link2" type="revolute">
       <parent link="Link1"/>
       <child  link="Link2"/>
       <origin rpy="0 0 0" xyz="0.0 0.4514673850366707 0.0" />
     <axis xyz="[1 0 1]"/>
       <limit effort="0.0" lower="-3.14159" upper="3.14159" velocity="0.0"/>
    </joint>
    <link name="Link2">
        <inertial>
            <origin xyz="0.0 0.3122324751749506 0.0" rpy="0 0 0"/>
            <mass value="1" />
            <inertia ixx="100" ixy="0" ixz="0" iyy="100" iyz="0" izz="100" />
        </inertial>
        <visual>
            <origin xyz="0.0 0.3122324751749506 0.0" rpy="0 0 0"/>
            <geometry>
                <box size="0.6763871961905039 0.6244649503499012 0.36852868741175754" />
            </geometry>
            <material name="Blue">
                <color rgba="0 0 1.0 1.0"/>
            </material>
        </visual>
        <collision>
            <origin xyz="0.0 0.3122324751749506 0.0" rpy="0 0 0"/>
            <geometry>
                <box size="0.6763871961905039 0.6244649503499012 0.36852868741175754" />
            </geometry>
        </collision>
    </link>
    <joint name="Link2_Link2-0" type="revolute">
       <parent link="Link2"/>
       <child  link="Link2-0"/>
       <origin rpy="0 0 0" xyz="-0.34356356118830284 0.3122324751749506 0.0" />
     <axis xyz="[2 1 1]"/>
       <limit effort="0.0" lower="-3.14159" upper="3.14159" velocity="0.0"/>
    </joint>
    <link name="Link2-0">
        <inertial>
            <origin xyz="-0.2027518694164237 0.0 0.0" rpy="0 0 0"/>
            <mass value="1" />
            <inertia ixx="100" ixy="0" ixz="0" iyy="100" iyz="0" izz="100" />
        </inertial>
        <visual>
            <origin xyz="-0.2027518694164237 0.0 0.0" rpy="0 0 0"/>
            <geometry>
                <box size="0.4055037388328474 0.9056864196277082 0.9754405345459376" />
            </geometry>
            <material name="Blue">
                <color rgba="0 0 1.0 1.0"/>
            </material>
        </visual>
        <collision>
            <origin xyz="-0.2027518694164237 0.0 0.0" rpy="0 0 0"/>
            <geometry>
                <box size="0.4055037388328474 0.9056864196277082 0.9754405345459376" />
            </geometry>
        </collision>
    </link>
    <joint name="Link2-0_Link2-0-0" type="revolute">
       <parent link="Link2-0"/>
       <child  link="Link2-0-0"/>
       <origin rpy="0 0 0" xyz="0.0 -0.46480038154388426 -0.24224027908667445" />
     <axis xyz="[1 2 1]"/>
       <limit effort="0.0" lower="-3.14159" upper="3.14159" velocity="0.0"/>
    </joint>
    <link name="Link2-0-0">
        <inertial>
            <origin xyz="0.0 -0.4610081586899761 0.0" rpy="0 0 0"/>
            <mass value="1" />
            <inertia ixx="100" ixy="0" ixz="0" iyy="100" iyz="0" izz="100" />
        </inertial>
        <visual>
            <origin xyz="0.0 -0.4610081586899761 0.0" rpy="0 0 0"/>
            <geometry>
                <box size="0.5813586521856493 0.9220163173799522 0.7006236105879717" />
            </geometry>
            <material name="Blue">
                <color rgba="0 0 1.0 1.0"/>
            </material>
        </visual>
        <collision>
            <origin xyz="0.0 -0.4610081586899761 0.0" rpy="0 0 0"/>
            <geometry>
                <box size="0.5813586521856493 0.9220163173799522 0.7006236105879717" />
            </geometry>
        </collision>
    </link>
    <joint name="Link2-0-0_Link2-0-1" type="revolute">
       <parent link="Link2-0-0"/>
       <child  link="Link2-0-1"/>
       <origin rpy="0 0 0" xyz="0.0 -0.9220163173799522 0.0" />
     <axis xyz="[1 2 1]"/>
       <limit effort="0.0" lower="-3.14159" upper="3.14159" velocity="0.0"/>
    </joint>
    <link name="Link2-0-1">
        <inertial>
            <origin xyz="0.0 -0.3251852834244858 0.0" rpy="0 0 0"/>
            <mass value="1" />
            <inertia ixx="100" ixy="0" ixz="0" iyy="100" iyz="0" izz="100" />
        </inertial>
        <visual>
            <origin xyz="0.0 -0.3251852834244858 0.0" rpy="0 0 0"/>
            <geometry>
                <box size="0.6132769500745642 0.6503705668489717 0.7541353699906984" />
            </geometry>
            <material name="Blue">
                <color rgba="0 0 1.0 1.0"/>
            </material>
        </visual>
        <collision>
            <origin xyz="0.0 -0.3251852834244858 0.0" rpy="0 0 0"/>
            <geometry>
                <box size="0.6132769500745642 0.6503705668489717 0.7541353699906984" />
            </geometry>
        </collision>
    </link>
    <joint name="Link2-0-1_Link2-0-2" type="revolute">
       <parent link="Link2-0-1"/>
       <child  link="Link2-0-2"/>
       <origin rpy="0 0 0" xyz="0.0 -0.6503705668489717 0.0" />
     <axis xyz="[1 2 1]"/>
       <limit effort="0.0" lower="-3.14159" upper="3.14159" velocity="0.0"/>
    </joint>
    <link name="Link2-0-2">
        <inertial>
            <origin xyz="0.0 -0.23090825386577207 0.0" rpy="0 0 0"/>
            <mass value="1" />
            <inertia ixx="100" ixy="0" ixz="0" iyy="100" iyz="0" izz="100" />
        </inertial>
        <visual>
            <origin xyz="0.0 -0.23090825386577207 0.0" rpy="0 0 0"/>
            <geometry>
                <box size="0.526563720516948 0.46181650773154415 0.45874594882729136" />
            </geometry>
            <material name="Green">
                <color rgba="0 1.0 0 1.0"/>
            </material>
        </visual>
        <collision>
            <origin xyz="0.0 -0.23090825386577207 0.0" rpy="0 0 0"/>
            <geometry>
                <box size="0.526563720516948 0.46181650773154415 0.45874594882729136" />
            </geometry>
        </collision>
    </link>
    <joint name="Link2-0-1_Link2-0-1-0" type="revolute">
       <parent link="Link2-0-1"/>
       <child  link="Link2-0-1-0"/>
       <origin rpy="0 0 0" xyz="-0.4123257492191684 -0.3251852834244858 0.0" />
     <axis xyz="[2 1 1]"/>
       <limit effort="0.0" lower="-3.14159" upper="3.14159" velocity="0.0"/>
    </joint>
    <link name="Link2-0-1-0">
        <inertial>
            <origin xyz="-0.33964582338473104 0.0 0.0" rpy="0 0 0"/>
            <mass value="1" />
            <inertia ixx="100" ixy="0" ixz="0" iyy="100" iyz="0" izz="100" />
        </inertial>
        <visual>
            <origin xyz="-0.33964582338473104 0.0 0.0" rpy="0 0 0"/>
            <geometry>
                <box size="0.6792916467694621 0.7622535905749916 0.37846675873455377" />
            </geometry>
            <material name="Green">
                <color rgba="0 1.0 0 1.0"/>
            </material>
        </visual>
        <collision>
            <origin xyz="-0.33964582338473104 0.0 0.0" rpy="0 0 0"/>
            <geometry>
                <box size="0.6792916467694621 0.7622535905749916 0.37846675873455377" />
            </geometry>
        </collision>
    </link>
    <joint name="Link2-0-1-0_Link2-0-1-0-0" type="revolute">
       <parent link="Link2-0-1-0"/>
       <child  link="Link2-0-1-0-0"/>
       <origin rpy="0 0 0" xyz="-0.33964582338473104 -0.3811267952874958 0.0" />
     <axis xyz="[1 2 1]"/>
       <limit effort="0.0" lower="-3.14159" upper="3.14159" velocity="0.0"/>
    </joint>
    <link name="Link2-0-1-0-0">
        <inertial>
            <origin xyz="0.0 -0.3887059075664574 0.0" rpy="0 0 0"/>
            <mass value="1" />
            <inertia ixx="100" ixy="0" ixz="0" iyy="100" iyz="0" izz="100" />
        </inertial>
        <visual>
            <origin xyz="0.0 -0.3887059075664574 0.0" rpy="0 0 0"/>
            <geometry>
                <box size="0.322405930600286 0.7774118151329148 0.7796699964371443" />
            </geometry>
            <material name="Green">
                <color rgba="0 1.0 0 1.0"/>
            </material>
        </visual>
        <collision>
            <origin xyz="0.0 -0.3887059075664574 0.0" rpy="0 0 0"/>
            <geometry>
                <box size="0.322405930600286 0.7774118151329148 0.7796699964371443" />
            </geometry>
        </collision>
    </link>
    <joint name="Link2-0-1-0-0_Link2-0-1-0-0-0" type="revolute">
       <parent link="Link2-0-1-0-0"/>
       <child  link="Link2-0-1-0-0-0"/>
       <origin rpy="0 0 0" xyz="0.0 -0.3887059075664574 0.35230734960654164" />
     <axis xyz="[1 1 0]"/>
       <limit effort="0.0" lower="-3.14159" upper="3.14159" velocity="0.0"/>
    </joint>
    <link name="Link2-0-1-0-0-0">
        <inertial>
            <origin xyz="0.0 0.0 0.12932016051748935" rpy="0 0 0"/>
            <mass value="1" />
            <inertia ixx="100" ixy="0" ixz="0" iyy="100" iyz="0" izz="100" />
        </inertial>
        <visual>
            <origin xyz="0.0 0.0 0.12932016051748935" rpy="0 0 0"/>
            <geometry>
                <box size="0.5669650712903519 0.48322626831665627 0.2586403210349787" />
            </geometry>
            <material name="Blue">
                <color rgba="0 0 1.0 1.0"/>
            </material>
        </visual>
        <collision>
            <origin xyz="0.0 0.0 0.12932016051748935" rpy="0 0 0"/>
            <geometry>
                <box size="0.5669650712903519 0.48322626831665627 0.2586403210349787" />
            </geometry>
        </collision>
    </link>
    <joint name="Link2-0-1-0-0-0_Link2-0-1-0-0-0-0" type="revolute">
       <parent link="Link2-0-1-0-0-0"/>
       <child  link="Link2-0-1-0-0-0-0"/>
       <origin rpy="0 0 0" xyz="-0.24458306385490436 0.0 0.12932016051748935" />
     <axis xyz="[2 1 1]"/>
       <limit effort="0.0" lower="-3.14159" upper="3.14159" velocity="0.0"/>
    </joint>
    <link name="Link2-0-1-0-0-0-0">
        <inertial>
            <origin xyz="-0.19437603437596002 0.0 0.0" rpy="0 0 0"/>
            <mass value="1" />
            <inertia ixx="100" ixy="0" ixz="0" iyy="100" iyz="0" izz="100" />
        </inertial>
        <visual>
            <origin xyz="-0.19437603437596002 0.0 0.0" rpy="0 0 0"/>
            <geometry>
                <box size="0.38875206875192003 0.8592800550292592 0.4918748145658767" />
            </geometry>
            <material name="Green">
                <color rgba="0 1.0 0 1.0"/>
            </material>
        </visual>
        <collision>
            <origin xyz="-0.19437603437596002 0.0 0.0" rpy="0 0 0"/>
            <geometry>
                <box size="0.38875206875192003 0.8592800550292592 0.4918748145658767" />
            </geometry>
        </collision>
    </link>
    <joint name="Link2-0-1-0-0-0-0_Link2-0-1-0-0-0-0-0" type="revolute">
       <parent link="Link2-0-1-0-0-0-0"/>
       <child  link="Link2-0-1-0-0-0-0-0"/>
       <origin rpy="0 0 0" xyz="-0.19437603437596002 0.0 0.15453870589977325" />
     <axis xyz="[1 1 0]"/>
       <limit effort="0.0" lower="-3.14159" upper="3.14159" velocity="0.0"/>
    </joint>
    <link name="Link2-0-1-0-0-0-0-0">
        <inertial>
            <origin xyz="0.0 0.0 0.081328903240126" rpy="0 0 0"/>
            <mass value="1" />
            <inertia ixx="100" ixy="0" ixz="0" iyy="100" iyz="0" izz="100" />
        </inertial>
        <visual>
            <origin xyz="0.0 0.0 0.081328903240126" rpy="0 0 0"/>
            <geometry>
                <box size="0.28440154764461045 0.5860233463396569 0.162657806480252" />
            </geometry>
            <material name="Green">
                <color rgba="0 1.0 0 1.0"/>
            </material>
        </visual>
        <collision>
            <origin xyz="0.0 0.0 0.081328903240126" rpy="0 0 0"/>
            <geometry>
                <box size="0.28440154764461045 0.5860233463396569 0.162657806480252" />
            </geometry>
        </collision>
    </link>
    <joint name="Link2-0-0_Link2-0-0-0" type="revolute">
       <parent link="Link2-0-0"/>
       <child  link="Link2-0-0-0"/>
       <origin rpy="0 0 0" xyz="0.0 -0.4610081586899761 -0.35031180529398587" />
     <axis xyz="[1 1 2]"/>
       <limit effort="0.0" lower="-3.14159" upper="3.14159" velocity="0.0"/>
    </joint>
    <link name="Link2-0-0-0">
        <inertial>
            <origin xyz="0.0 0.0 -0.2419540002572129" rpy="0 0 0"/>
            <mass value="1" />
            <inertia ixx="100" ixy="0" ixz="0" iyy="100" iyz="0" izz="100" />
        </inertial>
        <visual>
            <origin xyz="0.0 0.0 -0.2419540002572129" rpy="0 0 0"/>
            <geometry>
                <box size="0.9269885176753426 0.4386285629107557 0.4839080005144258" />
            </geometry>
            <material name="Blue">
                <color rgba="0 0 1.0 1.0"/>
            </material>
        </visual>
        <collision>
            <origin xyz="0.0 0.0 -0.2419540002572129" rpy="0 0 0"/>
            <geometry>
                <box size="0.9269885176753426 0.4386285629107557 0.4839080005144258" />
            </geometry>
        </collision>
    </link>
</robot>