<robot name = "robot">
    <link name="Link0">
        <inertial>
            <origin xyz="0.0 0.0 2.239229892334542" rpy="0 0 0"/>
            <mass value="1" />
            <inertia ixx="100" ixy="0" ixz="0" iyy="100" iyz="0" izz="100" />
        </inertial>
        <visual>
            <origin xyz="0.0 0.0 2.239229892334542" rpy="0 0 0"/>
            <geometry>
                <box size="0.5430544724995393 0.6967060974392003 0.4784597846690842" />
            </geometry>
            <material name="Green">
                <color rgba="0 1.0 0 1.0"/>
            </material>
        </visual>
        <collision>
            <origin xyz="0.0 0.0 2.239229892334542" rpy="0 0 0"/>
            <geometry>
                <box size="0.5430544724995393 0.6967060974392003 0.4784597846690842" />
            </geometry>
        </collision>
    </link>
    <joint name="Link0_Link1" type="revolute">
       <parent link="Link0"/>
       <child  link="Link1"/>
       <origin rpy="0 0 0" xyz="0.0 0.34835304871960016 2.239229892334542" />
     <axis xyz="1 0 1"/>
       <limit effort="0.0" lower="-3.14159" upper="3.14159" velocity="0.0"/>
    </joint>
    <link name="Link1">
        <inertial>
            <origin xyz="0.0 0.47804089269389505 0.0" rpy="0 0 0"/>
            <mass value="1" />
            <inertia ixx="100" ixy="0" ixz="0" iyy="100" iyz="0" izz="100" />
        </inertial>
        <visual>
            <origin xyz="0.0 0.47804089269389505 0.0" rpy="0 0 0"/>
            <geometry>
                <box size="0.38344664209815227 0.9560817853877901 0.4179731063349359" />
            </geometry>
            <material name="Blue">
                <color rgba="0 0 1.0 1.0"/>
            </material>
        </visual>
        <collision>
            <origin xyz="0.0 0.47804089269389505 0.0" rpy="0 0 0"/>
            <geometry>
                <box size="0.38344664209815227 0.9560817853877901 0.4179731063349359" />
            </geometry>
        </collision>
    </link>
    <joint name="Link1_Link2" type="revolute">
       <parent link="Link1"/>
       <child  link="Link2"/>
       <origin rpy="0 0 0" xyz="0.0 0.9560817853877901 0.0" />
     <axis xyz="[1 0 1]"/>
       <limit effort="0.0" lower="-3.14159" upper="3.14159" velocity="0.0"/>
    </joint>
    <link name="Link2">
        <inertial>
            <origin xyz="0.0 0.31937267957390025 0.0" rpy="0 0 0"/>
            <mass value="1" />
            <inertia ixx="100" ixy="0" ixz="0" iyy="100" iyz="0" izz="100" />
        </inertial>
        <visual>
            <origin xyz="0.0 0.31937267957390025 0.0" rpy="0 0 0"/>
            <geometry>
                <box size="0.6649067054950479 0.6387453591478005 0.3601967684674324" />
            </geometry>
            <material name="Green">
                <color rgba="0 1.0 0 1.0"/>
            </material>
        </visual>
        <collision>
            <origin xyz="0.0 0.31937267957390025 0.0" rpy="0 0 0"/>
            <geometry>
                <box size="0.6649067054950479 0.6387453591478005 0.3601967684674324" />
            </geometry>
        </collision>
    </link>
    <joint name="Link2_Link2-0" type="revolute">
       <parent link="Link2"/>
       <child  link="Link2-0"/>
       <origin rpy="0 0 0" xyz="0.0 0.31937267957390025 0.1800983842337162" />
     <axis xyz="[1 1 0]"/>
       <limit effort="0.0" lower="-3.14159" upper="3.14159" velocity="0.0"/>
    </joint>
    <link name="Link2-0">
        <inertial>
            <origin xyz="0.0 0.0 0.1624608578086647" rpy="0 0 0"/>
            <mass value="1" />
            <inertia ixx="100" ixy="0" ixz="0" iyy="100" iyz="0" izz="100" />
        </inertial>
        <visual>
            <origin xyz="0.0 0.0 0.1624608578086647" rpy="0 0 0"/>
            <geometry>
                <box size="0.4587575254180105 0.8336260613192289 0.3249217156173294" />
            </geometry>
            <material name="Blue">
                <color rgba="0 0 1.0 1.0"/>
            </material>
        </visual>
        <collision>
            <origin xyz="0.0 0.0 0.1624608578086647" rpy="0 0 0"/>
            <geometry>
                <box size="0.4587575254180105 0.8336260613192289 0.3249217156173294" />
            </geometry>
        </collision>
    </link>
    <joint name="Link2_Link3" type="revolute">
       <parent link="Link2"/>
       <child  link="Link3"/>
       <origin rpy="0 0 0" xyz="0.0 0.6387453591478005 0.0" />
     <axis xyz="[1 0 1]"/>
       <limit effort="0.0" lower="-3.14159" upper="3.14159" velocity="0.0"/>
    </joint>
    <link name="Link3">
        <inertial>
            <origin xyz="0.0 0.29814610186977397 0.0" rpy="0 0 0"/>
            <mass value="1" />
            <inertia ixx="100" ixy="0" ixz="0" iyy="100" iyz="0" izz="100" />
        </inertial>
        <visual>
            <origin xyz="0.0 0.29814610186977397 0.0" rpy="0 0 0"/>
            <geometry>
                <box size="0.38823588258180997 0.5962922037395479 0.4972189423558234" />
            </geometry>
            <material name="Green">
                <color rgba="0 1.0 0 1.0"/>
            </material>
        </visual>
        <collision>
            <origin xyz="0.0 0.29814610186977397 0.0" rpy="0 0 0"/>
            <geometry>
                <box size="0.38823588258180997 0.5962922037395479 0.4972189423558234" />
            </geometry>
        </collision>
    </link>
    <joint name="Link3_Link3-0" type="revolute">
       <parent link="Link3"/>
       <child  link="Link3-0"/>
       <origin rpy="0 0 0" xyz="0.0 0.29814610186977397 -0.2486094711779117" />
     <axis xyz="[1 1 2]"/>
       <limit effort="0.0" lower="-3.14159" upper="3.14159" velocity="0.0"/>
    </joint>
    <link name="Link3-0">
        <inertial>
            <origin xyz="0.0 0.0 -0.2410400781624547" rpy="0 0 0"/>
            <mass value="1" />
            <inertia ixx="100" ixy="0" ixz="0" iyy="100" iyz="0" izz="100" />
        </inertial>
        <visual>
            <origin xyz="0.0 0.0 -0.2410400781624547" rpy="0 0 0"/>
            <geometry>
                <box size="0.7512872610477349 0.3147388831426505 0.4820801563249094" />
            </geometry>
            <material name="Green">
                <color rgba="0 1.0 0 1.0"/>
            </material>
        </visual>
        <collision>
            <origin xyz="0.0 0.0 -0.2410400781624547" rpy="0 0 0"/>
            <geometry>
                <box size="0.7512872610477349 0.3147388831426505 0.4820801563249094" />
            </geometry>
        </collision>
    </link>
</robot>