<robot name = "robot">
    <link name="Link0">
        <inertial>
            <origin xyz="0.0 0.0 2.220694991182313" rpy="0 0 0"/>
            <mass value="1" />
            <inertia ixx="100" ixy="0" ixz="0" iyy="100" iyz="0" izz="100" />
        </inertial>
        <visual>
            <origin xyz="0.0 0.0 2.220694991182313" rpy="0 0 0"/>
            <geometry>
                <box size="0.2487614034073126 0.6466133447171732 0.4413899823646262" />
            </geometry>
            <material name="Green">
                <color rgba="0 1.0 0 1.0"/>
            </material>
        </visual>
        <collision>
            <origin xyz="0.0 0.0 2.220694991182313" rpy="0 0 0"/>
            <geometry>
                <box size="0.2487614034073126 0.6466133447171732 0.4413899823646262" />
            </geometry>
        </collision>
    </link>
    <joint name="Link0_Link1" type="revolute">
       <parent link="Link0"/>
       <child  link="Link1"/>
       <origin rpy="0 0 0" xyz="0.0 0.3233066723585866 2.220694991182313" />
     <axis xyz="1 0 1"/>
       <limit effort="0.0" lower="-3.14159" upper="3.14159" velocity="0.0"/>
    </joint>
    <link name="Link1">
        <inertial>
            <origin xyz="0.0 0.21656330807324126 0.0" rpy="0 0 0"/>
            <mass value="1" />
            <inertia ixx="100" ixy="0" ixz="0" iyy="100" iyz="0" izz="100" />
        </inertial>
        <visual>
            <origin xyz="0.0 0.21656330807324126 0.0" rpy="0 0 0"/>
            <geometry>
                <box size="0.21693964741942146 0.4331266161464825 0.48084956645531074" />
            </geometry>
            <material name="Blue">
                <color rgba="0 0 1.0 1.0"/>
            </material>
        </visual>
        <collision>
            <origin xyz="0.0 0.21656330807324126 0.0" rpy="0 0 0"/>
            <geometry>
                <box size="0.21693964741942146 0.4331266161464825 0.48084956645531074" />
            </geometry>
        </collision>
    </link>
    <joint name="Link1_Link2" type="revolute">
       <parent link="Link1"/>
       <child  link="Link2"/>
       <origin rpy="0 0 0" xyz="0.0 0.4331266161464825 0.0" />
     <axis xyz="[1 0 1]"/>
       <limit effort="0.0" lower="-3.14159" upper="3.14159" velocity="0.0"/>
    </joint>
    <link name="Link2">
        <inertial>
            <origin xyz="0.0 0.20228605954464146 0.0" rpy="0 0 0"/>
            <mass value="1" />
            <inertia ixx="100" ixy="0" ixz="0" iyy="100" iyz="0" izz="100" />
        </inertial>
        <visual>
            <origin xyz="0.0 0.20228605954464146 0.0" rpy="0 0 0"/>
            <geometry>
                <box size="0.7981890499705879 0.4045721190892829 0.20663786088680297" />
            </geometry>
            <material name="Blue">
                <color rgba="0 0 1.0 1.0"/>
            </material>
        </visual>
        <collision>
            <origin xyz="0.0 0.20228605954464146 0.0" rpy="0 0 0"/>
            <geometry>
                <box size="0.7981890499705879 0.4045721190892829 0.20663786088680297" />
            </geometry>
        </collision>
    </link>
    <joint name="Link2_Link2-0" type="revolute">
       <parent link="Link2"/>
       <child  link="Link2-0"/>
       <origin rpy="0 0 0" xyz="0.0 0.20228605954464146 0.10331893044340149" />
     <axis xyz="[1 1 0]"/>
       <limit effort="0.0" lower="-3.14159" upper="3.14159" velocity="0.0"/>
    </joint>
    <link name="Link2-0">
        <inertial>
            <origin xyz="0.0 0.0 0.21986402243872588" rpy="0 0 0"/>
            <mass value="1" />
            <inertia ixx="100" ixy="0" ixz="0" iyy="100" iyz="0" izz="100" />
        </inertial>
        <visual>
            <origin xyz="0.0 0.0 0.21986402243872588" rpy="0 0 0"/>
            <geometry>
                <box size="0.7622122488798931 0.5478605656267317 0.43972804487745176" />
            </geometry>
            <material name="Green">
                <color rgba="0 1.0 0 1.0"/>
            </material>
        </visual>
        <collision>
            <origin xyz="0.0 0.0 0.21986402243872588" rpy="0 0 0"/>
            <geometry>
                <box size="0.7622122488798931 0.5478605656267317 0.43972804487745176" />
            </geometry>
        </collision>
    </link>
    <joint name="Link2-0_Link2-0-0" type="revolute">
       <parent link="Link2-0"/>
       <child  link="Link2-0-0"/>
       <origin rpy="0 0 0" xyz="-0.38110612443994657 0.0 0.21986402243872588" />
     <axis xyz="[2 1 1]"/>
       <limit effort="0.0" lower="-3.14159" upper="3.14159" velocity="0.0"/>
    </joint>
    <link name="Link2-0-0">
        <inertial>
            <origin xyz="-0.14109483127922415 0.0 0.0" rpy="0 0 0"/>
            <mass value="1" />
            <inertia ixx="100" ixy="0" ixz="0" iyy="100" iyz="0" izz="100" />
        </inertial>
        <visual>
            <origin xyz="-0.14109483127922415 0.0 0.0" rpy="0 0 0"/>
            <geometry>
                <box size="0.2821896625584483 0.5389136811378985 0.4474947235702899" />
            </geometry>
            <material name="Green">
                <color rgba="0 1.0 0 1.0"/>
            </material>
        </visual>
        <collision>
            <origin xyz="-0.14109483127922415 0.0 0.0" rpy="0 0 0"/>
            <geometry>
                <box size="0.2821896625584483 0.5389136811378985 0.4474947235702899" />
            </geometry>
        </collision>
    </link>
    <joint name="Link2-0-0_Link2-0-1" type="revolute">
       <parent link="Link2-0-0"/>
       <child  link="Link2-0-1"/>
       <origin rpy="0 0 0" xyz="-0.2821896625584483 0.0 0.0" />
     <axis xyz="[2 1 1]"/>
       <limit effort="0.0" lower="-3.14159" upper="3.14159" velocity="0.0"/>
    </joint>
    <link name="Link2-0-1">
        <inertial>
            <origin xyz="-0.28355259688304635 0.0 0.0" rpy="0 0 0"/>
            <mass value="1" />
            <inertia ixx="100" ixy="0" ixz="0" iyy="100" iyz="0" izz="100" />
        </inertial>
        <visual>
            <origin xyz="-0.28355259688304635 0.0 0.0" rpy="0 0 0"/>
            <geometry>
                <box size="0.5671051937660927 0.9279878208891603 0.2704613000789376" />
            </geometry>
            <material name="Blue">
                <color rgba="0 0 1.0 1.0"/>
            </material>
        </visual>
        <collision>
            <origin xyz="-0.28355259688304635 0.0 0.0" rpy="0 0 0"/>
            <geometry>
                <box size="0.5671051937660927 0.9279878208891603 0.2704613000789376" />
            </geometry>
        </collision>
    </link>
    <joint name="Link2-0-1_Link2-0-1-0" type="revolute">
       <parent link="Link2-0-1"/>
       <child  link="Link2-0-1-0"/>
       <origin rpy="0 0 0" xyz="-0.28355259688304635 -0.46399391044458016 0.0" />
     <axis xyz="[1 2 1]"/>
       <limit effort="0.0" lower="-3.14159" upper="3.14159" velocity="0.0"/>
    </joint>
    <link name="Link2-0-1-0">
        <inertial>
            <origin xyz="0.0 -0.4648232598425044 0.0" rpy="0 0 0"/>
            <mass value="1" />
            <inertia ixx="100" ixy="0" ixz="0" iyy="100" iyz="0" izz="100" />
        </inertial>
        <visual>
            <origin xyz="0.0 -0.4648232598425044 0.0" rpy="0 0 0"/>
            <geometry>
                <box size="0.6164556382179739 0.9296465196850088 0.24125681496453877" />
            </geometry>
            <material name="Green">
                <color rgba="0 1.0 0 1.0"/>
            </material>
        </visual>
        <collision>
            <origin xyz="0.0 -0.4648232598425044 0.0" rpy="0 0 0"/>
            <geometry>
                <box size="0.6164556382179739 0.9296465196850088 0.24125681496453877" />
            </geometry>
        </collision>
    </link>
    <joint name="Link2-0-1-0_Link2-0-1-1" type="revolute">
       <parent link="Link2-0-1-0"/>
       <child  link="Link2-0-1-1"/>
       <origin rpy="0 0 0" xyz="0.0 -0.9296465196850088 0.0" />
     <axis xyz="[1 2 1]"/>
       <limit effort="0.0" lower="-3.14159" upper="3.14159" velocity="0.0"/>
    </joint>
    <link name="Link2-0-1-1">
        <inertial>
            <origin xyz="0.0 -0.255887571109474 0.0" rpy="0 0 0"/>
            <mass value="1" />
            <inertia ixx="100" ixy="0" ixz="0" iyy="100" iyz="0" izz="100" />
        </inertial>
        <visual>
            <origin xyz="0.0 -0.255887571109474 0.0" rpy="0 0 0"/>
            <geometry>
                <box size="0.32687335023898406 0.511775142218948 0.47700939444302776" />
            </geometry>
            <material name="Blue">
                <color rgba="0 0 1.0 1.0"/>
            </material>
        </visual>
        <collision>
            <origin xyz="0.0 -0.255887571109474 0.0" rpy="0 0 0"/>
            <geometry>
                <box size="0.32687335023898406 0.511775142218948 0.47700939444302776" />
            </geometry>
        </collision>
    </link>
    <joint name="Link2-0-1-1_Link2-0-1-2" type="revolute">
       <parent link="Link2-0-1-1"/>
       <child  link="Link2-0-1-2"/>
       <origin rpy="0 0 0" xyz="0.0 -0.511775142218948 0.0" />
     <axis xyz="[1 2 1]"/>
       <limit effort="0.0" lower="-3.14159" upper="3.14159" velocity="0.0"/>
    </joint>
    <link name="Link2-0-1-2">
        <inertial>
            <origin xyz="0.0 -0.4059609388882178 0.0" rpy="0 0 0"/>
            <mass value="1" />
            <inertia ixx="100" ixy="0" ixz="0" iyy="100" iyz="0" izz="100" />
        </inertial>
        <visual>
            <origin xyz="0.0 -0.4059609388882178 0.0" rpy="0 0 0"/>
            <geometry>
                <box size="0.25825045818750625 0.8119218777764357 0.4045303715805368" />
            </geometry>
            <material name="Blue">
                <color rgba="0 0 1.0 1.0"/>
            </material>
        </visual>
        <collision>
            <origin xyz="0.0 -0.4059609388882178 0.0" rpy="0 0 0"/>
            <geometry>
                <box size="0.25825045818750625 0.8119218777764357 0.4045303715805368" />
            </geometry>
        </collision>
    </link>
    <joint name="Link2-0-1-2_Link2-0-1-3" type="revolute">
       <parent link="Link2-0-1-2"/>
       <child  link="Link2-0-1-3"/>
       <origin rpy="0 0 0" xyz="0.0 -0.8119218777764357 0.0" />
     <axis xyz="[1 2 1]"/>
       <limit effort="0.0" lower="-3.14159" upper="3.14159" velocity="0.0"/>
    </joint>
    <link name="Link2-0-1-3">
        <inertial>
            <origin xyz="0.0 -0.27354782695853297 0.0" rpy="0 0 0"/>
            <mass value="1" />
            <inertia ixx="100" ixy="0" ixz="0" iyy="100" iyz="0" izz="100" />
        </inertial>
        <visual>
            <origin xyz="0.0 -0.27354782695853297 0.0" rpy="0 0 0"/>
            <geometry>
                <box size="0.7631230751752571 0.5470956539170659 0.13398790366544372" />
            </geometry>
            <material name="Green">
                <color rgba="0 1.0 0 1.0"/>
            </material>
        </visual>
        <collision>
            <origin xyz="0.0 -0.27354782695853297 0.0" rpy="0 0 0"/>
            <geometry>
                <box size="0.7631230751752571 0.5470956539170659 0.13398790366544372" />
            </geometry>
        </collision>
    </link>
    <joint name="Link2-0-1-3_Link2-0-1-4" type="revolute">
       <parent link="Link2-0-1-3"/>
       <child  link="Link2-0-1-4"/>
       <origin rpy="0 0 0" xyz="0.0 -0.5470956539170659 0.0" />
     <axis xyz="[1 2 1]"/>
       <limit effort="0.0" lower="-3.14159" upper="3.14159" velocity="0.0"/>
    </joint>
    <link name="Link2-0-1-4">
        <inertial>
            <origin xyz="0.0 -0.49025365707169494 0.0" rpy="0 0 0"/>
            <mass value="1" />
            <inertia ixx="100" ixy="0" ixz="0" iyy="100" iyz="0" izz="100" />
        </inertial>
        <visual>
            <origin xyz="0.0 -0.49025365707169494 0.0" rpy="0 0 0"/>
            <geometry>
                <box size="0.5876931626976637 0.9805073141433899 0.3615138526077796" />
            </geometry>
            <material name="Green">
                <color rgba="0 1.0 0 1.0"/>
            </material>
        </visual>
        <collision>
            <origin xyz="0.0 -0.49025365707169494 0.0" rpy="0 0 0"/>
            <geometry>
                <box size="0.5876931626976637 0.9805073141433899 0.3615138526077796" />
            </geometry>
        </collision>
    </link>
    <joint name="Link2-0-1_Link2-0-2" type="revolute">
       <parent link="Link2-0-1"/>
       <child  link="Link2-0-2"/>
       <origin rpy="0 0 0" xyz="-0.5671051937660927 0.0 0.0" />
     <axis xyz="[2 1 1]"/>
       <limit effort="0.0" lower="-3.14159" upper="3.14159" velocity="0.0"/>
    </joint>
    <link name="Link2-0-2">
        <inertial>
            <origin xyz="-0.15691895825317626 0.0 0.0" rpy="0 0 0"/>
            <mass value="1" />
            <inertia ixx="100" ixy="0" ixz="0" iyy="100" iyz="0" izz="100" />
        </inertial>
        <visual>
            <origin xyz="-0.15691895825317626 0.0 0.0" rpy="0 0 0"/>
            <geometry>
                <box size="0.3138379165063525 0.575571013112042 0.38013915789252317" />
            </geometry>
            <material name="Green">
                <color rgba="0 1.0 0 1.0"/>
            </material>
        </visual>
        <collision>
            <origin xyz="-0.15691895825317626 0.0 0.0" rpy="0 0 0"/>
            <geometry>
                <box size="0.3138379165063525 0.575571013112042 0.38013915789252317" />
            </geometry>
        </collision>
    </link>
</robot>