<robot name = "robot">
    <link name="Link0">
        <inertial>
            <origin xyz="0.0 0.0 2.154319868248705" rpy="0 0 0"/>
            <mass value="1" />
            <inertia ixx="100" ixy="0" ixz="0" iyy="100" iyz="0" izz="100" />
        </inertial>
        <visual>
            <origin xyz="0.0 0.0 2.154319868248705" rpy="0 0 0"/>
            <geometry>
                <box size="0.23265739367748797 0.8122049488243268 0.30863973649740983" />
            </geometry>
            <material name="Green">
                <color rgba="0 1.0 0 1.0"/>
            </material>
        </visual>
        <collision>
            <origin xyz="0.0 0.0 2.154319868248705" rpy="0 0 0"/>
            <geometry>
                <box size="0.23265739367748797 0.8122049488243268 0.30863973649740983" />
            </geometry>
        </collision>
    </link>
    <joint name="Link0_Link1" type="revolute">
       <parent link="Link0"/>
       <child  link="Link1"/>
       <origin rpy="0 0 0" xyz="0.0 0.4061024744121634 2.154319868248705" />
     <axis xyz="1 0 1"/>
       <limit effort="0.0" lower="-3.14159" upper="3.14159" velocity="0.0"/>
    </joint>
    <link name="Link1">
        <inertial>
            <origin xyz="0.0 0.3340614439672956 0.0" rpy="0 0 0"/>
            <mass value="1" />
            <inertia ixx="100" ixy="0" ixz="0" iyy="100" iyz="0" izz="100" />
        </inertial>
        <visual>
            <origin xyz="0.0 0.3340614439672956 0.0" rpy="0 0 0"/>
            <geometry>
                <box size="0.43384837469306614 0.6681228879345912 0.21537678390253562" />
            </geometry>
            <material name="Blue">
                <color rgba="0 0 1.0 1.0"/>
            </material>
        </visual>
        <collision>
            <origin xyz="0.0 0.3340614439672956 0.0" rpy="0 0 0"/>
            <geometry>
                <box size="0.43384837469306614 0.6681228879345912 0.21537678390253562" />
            </geometry>
        </collision>
    </link>
    <joint name="Link1_Link2" type="revolute">
       <parent link="Link1"/>
       <child  link="Link2"/>
       <origin rpy="0 0 0" xyz="0.0 0.6681228879345912 0.0" />
     <axis xyz="[1 0 1]"/>
       <limit effort="0.0" lower="-3.14159" upper="3.14159" velocity="0.0"/>
    </joint>
    <link name="Link2">
        <inertial>
            <origin xyz="0.0 0.3449682987922401 0.0" rpy="0 0 0"/>
            <mass value="1" />
            <inertia ixx="100" ixy="0" ixz="0" iyy="100" iyz="0" izz="100" />
        </inertial>
        <visual>
            <origin xyz="0.0 0.3449682987922401 0.0" rpy="0 0 0"/>
            <geometry>
                <box size="0.5523328708835286 0.6899365975844802 0.8917190393895335" />
            </geometry>
            <material name="Green">
                <color rgba="0 1.0 0 1.0"/>
            </material>
        </visual>
        <collision>
            <origin xyz="0.0 0.3449682987922401 0.0" rpy="0 0 0"/>
            <geometry>
                <box size="0.5523328708835286 0.6899365975844802 0.8917190393895335" />
            </geometry>
        </collision>
    </link>
    <joint name="Link2_Link3" type="revolute">
       <parent link="Link2"/>
       <child  link="Link3"/>
       <origin rpy="0 0 0" xyz="0.0 0.6899365975844802 0.0" />
     <axis xyz="[1 0 1]"/>
       <limit effort="0.0" lower="-3.14159" upper="3.14159" velocity="0.0"/>
    </joint>
    <link name="Link3">
        <inertial>
            <origin xyz="0.0 0.35996260817139486 0.0" rpy="0 0 0"/>
            <mass value="1" />
            <inertia ixx="100" ixy="0" ixz="0" iyy="100" iyz="0" izz="100" />
        </inertial>
        <visual>
            <origin xyz="0.0 0.35996260817139486 0.0" rpy="0 0 0"/>
            <geometry>
                <box size="0.7641849828762567 0.7199252163427897 0.4903016517614102" />
            </geometry>
            <material name="Blue">
                <color rgba="0 0 1.0 1.0"/>
            </material>
        </visual>
        <collision>
            <origin xyz="0.0 0.35996260817139486 0.0" rpy="0 0 0"/>
            <geometry>
                <box size="0.7641849828762567 0.7199252163427897 0.4903016517614102" />
            </geometry>
        </collision>
    </link>
    <joint name="Link3_Link3-0" type="revolute">
       <parent link="Link3"/>
       <child  link="Link3-0"/>
       <origin rpy="0 0 0" xyz="0.38209249143812835 0.35996260817139486 0.0" />
     <axis xyz="[0 1 1]"/>
       <limit effort="0.0" lower="-3.14159" upper="3.14159" velocity="0.0"/>
    </joint>
    <link name="Link3-0">
        <inertial>
            <origin xyz="0.19395634223621264 0.0 0.0" rpy="0 0 0"/>
            <mass value="1" />
            <inertia ixx="100" ixy="0" ixz="0" iyy="100" iyz="0" izz="100" />
        </inertial>
        <visual>
            <origin xyz="0.19395634223621264 0.0 0.0" rpy="0 0 0"/>
            <geometry>
                <box size="0.3879126844724253 0.3123532202399951 0.21761812763576366" />
            </geometry>
            <material name="Blue">
                <color rgba="0 0 1.0 1.0"/>
            </material>
        </visual>
        <collision>
            <origin xyz="0.19395634223621264 0.0 0.0" rpy="0 0 0"/>
            <geometry>
                <box size="0.3879126844724253 0.3123532202399951 0.21761812763576366" />
            </geometry>
        </collision>
    </link>
    <joint name="Link3-0_Link3-1" type="revolute">
       <parent link="Link3-0"/>
       <child  link="Link3-1"/>
       <origin rpy="0 0 0" xyz="0.3879126844724253 0.0 0.0" />
     <axis xyz="[0 1 1]"/>
       <limit effort="0.0" lower="-3.14159" upper="3.14159" velocity="0.0"/>
    </joint>
    <link name="Link3-1">
        <inertial>
            <origin xyz="0.2865201086026977 0.0 0.0" rpy="0 0 0"/>
            <mass value="1" />
            <inertia ixx="100" ixy="0" ixz="0" iyy="100" iyz="0" izz="100" />
        </inertial>
        <visual>
            <origin xyz="0.2865201086026977 0.0 0.0" rpy="0 0 0"/>
            <geometry>
                <box size="0.5730402172053954 0.5963698879757302 0.4009462880825581" />
            </geometry>
            <material name="Green">
                <color rgba="0 1.0 0 1.0"/>
            </material>
        </visual>
        <collision>
            <origin xyz="0.2865201086026977 0.0 0.0" rpy="0 0 0"/>
            <geometry>
                <box size="0.5730402172053954 0.5963698879757302 0.4009462880825581" />
            </geometry>
        </collision>
    </link>
    <joint name="Link3-1_Link3-1-0" type="revolute">
       <parent link="Link3-1"/>
       <child  link="Link3-1-0"/>
       <origin rpy="0 0 0" xyz="0.2865201086026977 0.2981849439878651 0.0" />
     <axis xyz="[1 0 1]"/>
       <limit effort="0.0" lower="-3.14159" upper="3.14159" velocity="0.0"/>
    </joint>
    <link name="Link3-1-0">
        <inertial>
            <origin xyz="0.0 0.41776948916882883 0.0" rpy="0 0 0"/>
            <mass value="1" />
            <inertia ixx="100" ixy="0" ixz="0" iyy="100" iyz="0" izz="100" />
        </inertial>
        <visual>
            <origin xyz="0.0 0.41776948916882883 0.0" rpy="0 0 0"/>
            <geometry>
                <box size="0.6912102360148901 0.8355389783376577 0.3671627604595279" />
            </geometry>
            <material name="Blue">
                <color rgba="0 0 1.0 1.0"/>
            </material>
        </visual>
        <collision>
            <origin xyz="0.0 0.41776948916882883 0.0" rpy="0 0 0"/>
            <geometry>
                <box size="0.6912102360148901 0.8355389783376577 0.3671627604595279" />
            </geometry>
        </collision>
    </link>
    <joint name="Link3-1-0_Link3-1-1" type="revolute">
       <parent link="Link3-1-0"/>
       <child  link="Link3-1-1"/>
       <origin rpy="0 0 0" xyz="0.0 0.8355389783376577 0.0" />
     <axis xyz="[1 0 1]"/>
       <limit effort="0.0" lower="-3.14159" upper="3.14159" velocity="0.0"/>
    </joint>
    <link name="Link3-1-1">
        <inertial>
            <origin xyz="0.0 0.49119707167471227 0.0" rpy="0 0 0"/>
            <mass value="1" />
            <inertia ixx="100" ixy="0" ixz="0" iyy="100" iyz="0" izz="100" />
        </inertial>
        <visual>
            <origin xyz="0.0 0.49119707167471227 0.0" rpy="0 0 0"/>
            <geometry>
                <box size="0.6142026205703648 0.9823941433494245 0.3036346795714161" />
            </geometry>
            <material name="Blue">
                <color rgba="0 0 1.0 1.0"/>
            </material>
        </visual>
        <collision>
            <origin xyz="0.0 0.49119707167471227 0.0" rpy="0 0 0"/>
            <geometry>
                <box size="0.6142026205703648 0.9823941433494245 0.3036346795714161" />
            </geometry>
        </collision>
    </link>
    <joint name="Link3-1_Link3-2" type="revolute">
       <parent link="Link3-1"/>
       <child  link="Link3-2"/>
       <origin rpy="0 0 0" xyz="0.5730402172053954 0.0 0.0" />
     <axis xyz="[0 1 1]"/>
       <limit effort="0.0" lower="-3.14159" upper="3.14159" velocity="0.0"/>
    </joint>
    <link name="Link3-2">
        <inertial>
            <origin xyz="0.2201117789750406 0.0 0.0" rpy="0 0 0"/>
            <mass value="1" />
            <inertia ixx="100" ixy="0" ixz="0" iyy="100" iyz="0" izz="100" />
        </inertial>
        <visual>
            <origin xyz="0.2201117789750406 0.0 0.0" rpy="0 0 0"/>
            <geometry>
                <box size="0.4402235579500812 0.2697086011441166 0.2775479581092296" />
            </geometry>
            <material name="Blue">
                <color rgba="0 0 1.0 1.0"/>
            </material>
        </visual>
        <collision>
            <origin xyz="0.2201117789750406 0.0 0.0" rpy="0 0 0"/>
            <geometry>
                <box size="0.4402235579500812 0.2697086011441166 0.2775479581092296" />
            </geometry>
        </collision>
    </link>
</robot>