<robot name = "robot">
    <link name="Link0">
        <inertial>
            <origin xyz="0.0 0.0 2.227555466229151" rpy="0 0 0"/>
            <mass value="1" />
            <inertia ixx="100" ixy="0" ixz="0" iyy="100" iyz="0" izz="100" />
        </inertial>
        <visual>
            <origin xyz="0.0 0.0 2.227555466229151" rpy="0 0 0"/>
            <geometry>
                <box size="0.6450698981556487 0.7898485863065403 0.45511093245830225" />
            </geometry>
            <material name="Green">
                <color rgba="0 1.0 0 1.0"/>
            </material>
        </visual>
        <collision>
            <origin xyz="0.0 0.0 2.227555466229151" rpy="0 0 0"/>
            <geometry>
                <box size="0.6450698981556487 0.7898485863065403 0.45511093245830225" />
            </geometry>
        </collision>
    </link>
    <joint name="Link0_Link1" type="revolute">
       <parent link="Link0"/>
       <child  link="Link1"/>
       <origin rpy="0 0 0" xyz="0.0 0.39492429315327016 2.227555466229151" />
     <axis xyz="1 0 1"/>
       <limit effort="0.0" lower="-3.14159" upper="3.14159" velocity="0.0"/>
    </joint>
    <link name="Link1">
        <inertial>
            <origin xyz="0.0 0.31926926644224496 0.0" rpy="0 0 0"/>
            <mass value="1" />
            <inertia ixx="100" ixy="0" ixz="0" iyy="100" iyz="0" izz="100" />
        </inertial>
        <visual>
            <origin xyz="0.0 0.31926926644224496 0.0" rpy="0 0 0"/>
            <geometry>
                <box size="0.6162768329627526 0.6385385328844899 0.24266880108232464" />
            </geometry>
            <material name="Blue">
                <color rgba="0 0 1.0 1.0"/>
            </material>
        </visual>
        <collision>
            <origin xyz="0.0 0.31926926644224496 0.0" rpy="0 0 0"/>
            <geometry>
                <box size="0.6162768329627526 0.6385385328844899 0.24266880108232464" />
            </geometry>
        </collision>
    </link>
    <joint name="Link1_Link2" type="revolute">
       <parent link="Link1"/>
       <child  link="Link2"/>
       <origin rpy="0 0 0" xyz="0.0 0.6385385328844899 0.0" />
     <axis xyz="[1 0 1]"/>
       <limit effort="0.0" lower="-3.14159" upper="3.14159" velocity="0.0"/>
    </joint>
    <link name="Link2">
        <inertial>
            <origin xyz="0.0 0.26920848103083544 0.0" rpy="0 0 0"/>
            <mass value="1" />
            <inertia ixx="100" ixy="0" ixz="0" iyy="100" iyz="0" izz="100" />
        </inertial>
        <visual>
            <origin xyz="0.0 0.26920848103083544 0.0" rpy="0 0 0"/>
            <geometry>
                <box size="0.8143941035829085 0.5384169620616709 0.4243319969683682" />
            </geometry>
            <material name="Blue">
                <color rgba="0 0 1.0 1.0"/>
            </material>
        </visual>
        <collision>
            <origin xyz="0.0 0.26920848103083544 0.0" rpy="0 0 0"/>
            <geometry>
                <box size="0.8143941035829085 0.5384169620616709 0.4243319969683682" />
            </geometry>
        </collision>
    </link>
    <joint name="Link2_Link3" type="revolute">
       <parent link="Link2"/>
       <child  link="Link3"/>
       <origin rpy="0 0 0" xyz="0.0 0.5384169620616709 0.0" />
     <axis xyz="[1 0 1]"/>
       <limit effort="0.0" lower="-3.14159" upper="3.14159" velocity="0.0"/>
    </joint>
    <link name="Link3">
        <inertial>
            <origin xyz="0.0 0.4758146038977622 0.0" rpy="0 0 0"/>
            <mass value="1" />
            <inertia ixx="100" ixy="0" ixz="0" iyy="100" iyz="0" izz="100" />
        </inertial>
        <visual>
            <origin xyz="0.0 0.4758146038977622 0.0" rpy="0 0 0"/>
            <geometry>
                <box size="0.6274652367807313 0.9516292077955244 0.48216903593138055" />
            </geometry>
            <material name="Green">
                <color rgba="0 1.0 0 1.0"/>
            </material>
        </visual>
        <collision>
            <origin xyz="0.0 0.4758146038977622 0.0" rpy="0 0 0"/>
            <geometry>
                <box size="0.6274652367807313 0.9516292077955244 0.48216903593138055" />
            </geometry>
        </collision>
    </link>
    <joint name="Link3_Link3-0" type="revolute">
       <parent link="Link3"/>
       <child  link="Link3-0"/>
       <origin rpy="0 0 0" xyz="-0.31373261839036565 0.4758146038977622 0.0" />
     <axis xyz="[2 1 1]"/>
       <limit effort="0.0" lower="-3.14159" upper="3.14159" velocity="0.0"/>
    </joint>
    <link name="Link3-0">
        <inertial>
            <origin xyz="-0.24185759016525843 0.0 0.0" rpy="0 0 0"/>
            <mass value="1" />
            <inertia ixx="100" ixy="0" ixz="0" iyy="100" iyz="0" izz="100" />
        </inertial>
        <visual>
            <origin xyz="-0.24185759016525843 0.0 0.0" rpy="0 0 0"/>
            <geometry>
                <box size="0.48371518033051686 0.9631127651059236 0.25001532632055823" />
            </geometry>
            <material name="Green">
                <color rgba="0 1.0 0 1.0"/>
            </material>
        </visual>
        <collision>
            <origin xyz="-0.24185759016525843 0.0 0.0" rpy="0 0 0"/>
            <geometry>
                <box size="0.48371518033051686 0.9631127651059236 0.25001532632055823" />
            </geometry>
        </collision>
    </link>
    <joint name="Link3-0_Link3-0-0" type="revolute">
       <parent link="Link3-0"/>
       <child  link="Link3-0-0"/>
       <origin rpy="0 0 0" xyz="-0.24185759016525843 0.0 -0.12500766316027911" />
     <axis xyz="[1 1 2]"/>
       <limit effort="0.0" lower="-3.14159" upper="3.14159" velocity="0.0"/>
    </joint>
    <link name="Link3-0-0">
        <inertial>
            <origin xyz="0.0 0.0 -0.06659797755594499" rpy="0 0 0"/>
            <mass value="1" />
            <inertia ixx="100" ixy="0" ixz="0" iyy="100" iyz="0" izz="100" />
        </inertial>
        <visual>
            <origin xyz="0.0 0.0 -0.06659797755594499" rpy="0 0 0"/>
            <geometry>
                <box size="0.8737849970937188 0.4094327456470862 0.13319595511188997" />
            </geometry>
            <material name="Green">
                <color rgba="0 1.0 0 1.0"/>
            </material>
        </visual>
        <collision>
            <origin xyz="0.0 0.0 -0.06659797755594499" rpy="0 0 0"/>
            <geometry>
                <box size="0.8737849970937188 0.4094327456470862 0.13319595511188997" />
            </geometry>
        </collision>
    </link>
    <joint name="Link3-0-0_Link3-0-1" type="revolute">
       <parent link="Link3-0-0"/>
       <child  link="Link3-0-1"/>
       <origin rpy="0 0 0" xyz="0.0 0.0 -0.13319595511188997" />
     <axis xyz="[1 1 2]"/>
       <limit effort="0.0" lower="-3.14159" upper="3.14159" velocity="0.0"/>
    </joint>
    <link name="Link3-0-1">
        <inertial>
            <origin xyz="0.0 0.0 -0.15435339567305068" rpy="0 0 0"/>
            <mass value="1" />
            <inertia ixx="100" ixy="0" ixz="0" iyy="100" iyz="0" izz="100" />
        </inertial>
        <visual>
            <origin xyz="0.0 0.0 -0.15435339567305068" rpy="0 0 0"/>
            <geometry>
                <box size="0.5632485326470658 0.8233479290858874 0.30870679134610135" />
            </geometry>
            <material name="Blue">
                <color rgba="0 0 1.0 1.0"/>
            </material>
        </visual>
        <collision>
            <origin xyz="0.0 0.0 -0.15435339567305068" rpy="0 0 0"/>
            <geometry>
                <box size="0.5632485326470658 0.8233479290858874 0.30870679134610135" />
            </geometry>
        </collision>
    </link>
    <joint name="Link3-0-1_Link3-0-2" type="revolute">
       <parent link="Link3-0-1"/>
       <child  link="Link3-0-2"/>
       <origin rpy="0 0 0" xyz="0.0 0.0 -0.30870679134610135" />
     <axis xyz="[1 1 2]"/>
       <limit effort="0.0" lower="-3.14159" upper="3.14159" velocity="0.0"/>
    </joint>
    <link name="Link3-0-2">
        <inertial>
            <origin xyz="0.0 0.0 -0.08556543430116387" rpy="0 0 0"/>
            <mass value="1" />
            <inertia ixx="100" ixy="0" ixz="0" iyy="100" iyz="0" izz="100" />
        </inertial>
        <visual>
            <origin xyz="0.0 0.0 -0.08556543430116387" rpy="0 0 0"/>
            <geometry>
                <box size="0.21258527433489238 0.30175733973825525 0.17113086860232773" />
            </geometry>
            <material name="Green">
                <color rgba="0 1.0 0 1.0"/>
            </material>
        </visual>
        <collision>
            <origin xyz="0.0 0.0 -0.08556543430116387" rpy="0 0 0"/>
            <geometry>
                <box size="0.21258527433489238 0.30175733973825525 0.17113086860232773" />
            </geometry>
        </collision>
    </link>
    <joint name="Link3-0-2_Link3-0-3" type="revolute">
       <parent link="Link3-0-2"/>
       <child  link="Link3-0-3"/>
       <origin rpy="0 0 0" xyz="0.0 0.0 -0.17113086860232773" />
     <axis xyz="[1 1 2]"/>
       <limit effort="0.0" lower="-3.14159" upper="3.14159" velocity="0.0"/>
    </joint>
    <link name="Link3-0-3">
        <inertial>
            <origin xyz="0.0 0.0 -0.12667109041417846" rpy="0 0 0"/>
            <mass value="1" />
            <inertia ixx="100" ixy="0" ixz="0" iyy="100" iyz="0" izz="100" />
        </inertial>
        <visual>
            <origin xyz="0.0 0.0 -0.12667109041417846" rpy="0 0 0"/>
            <geometry>
                <box size="0.6624910618875793 0.6128289588315607 0.2533421808283569" />
            </geometry>
            <material name="Green">
                <color rgba="0 1.0 0 1.0"/>
            </material>
        </visual>
        <collision>
            <origin xyz="0.0 0.0 -0.12667109041417846" rpy="0 0 0"/>
            <geometry>
                <box size="0.6624910618875793 0.6128289588315607 0.2533421808283569" />
            </geometry>
        </collision>
    </link>
    <joint name="Link3-0-3_Link3-0-4" type="revolute">
       <parent link="Link3-0-3"/>
       <child  link="Link3-0-4"/>
       <origin rpy="0 0 0" xyz="0.0 0.0 -0.2533421808283569" />
     <axis xyz="[1 1 2]"/>
       <limit effort="0.0" lower="-3.14159" upper="3.14159" velocity="0.0"/>
    </joint>
    <link name="Link3-0-4">
        <inertial>
            <origin xyz="0.0 0.0 -0.1863240888195512" rpy="0 0 0"/>
            <mass value="1" />
            <inertia ixx="100" ixy="0" ixz="0" iyy="100" iyz="0" izz="100" />
        </inertial>
        <visual>
            <origin xyz="0.0 0.0 -0.1863240888195512" rpy="0 0 0"/>
            <geometry>
                <box size="0.7477543623307357 0.5750695295501063 0.3726481776391024" />
            </geometry>
            <material name="Green">
                <color rgba="0 1.0 0 1.0"/>
            </material>
        </visual>
        <collision>
            <origin xyz="0.0 0.0 -0.1863240888195512" rpy="0 0 0"/>
            <geometry>
                <box size="0.7477543623307357 0.5750695295501063 0.3726481776391024" />
            </geometry>
        </collision>
    </link>
    <joint name="Link3-0_Link3-1" type="revolute">
       <parent link="Link3-0"/>
       <child  link="Link3-1"/>
       <origin rpy="0 0 0" xyz="-0.48371518033051686 0.0 0.0" />
     <axis xyz="[2 1 1]"/>
       <limit effort="0.0" lower="-3.14159" upper="3.14159" velocity="0.0"/>
    </joint>
    <link name="Link3-1">
        <inertial>
            <origin xyz="-0.35651895050016486 0.0 0.0" rpy="0 0 0"/>
            <mass value="1" />
            <inertia ixx="100" ixy="0" ixz="0" iyy="100" iyz="0" izz="100" />
        </inertial>
        <visual>
            <origin xyz="-0.35651895050016486 0.0 0.0" rpy="0 0 0"/>
            <geometry>
                <box size="0.7130379010003297 0.8255053241066821 0.2548397599293327" />
            </geometry>
            <material name="Green">
                <color rgba="0 1.0 0 1.0"/>
            </material>
        </visual>
        <collision>
            <origin xyz="-0.35651895050016486 0.0 0.0" rpy="0 0 0"/>
            <geometry>
                <box size="0.7130379010003297 0.8255053241066821 0.2548397599293327" />
            </geometry>
        </collision>
    </link>
    <joint name="Link3-1_Link3-1-0" type="revolute">
       <parent link="Link3-1"/>
       <child  link="Link3-1-0"/>
       <origin rpy="0 0 0" xyz="-0.35651895050016486 0.0 0.12741987996466636" />
     <axis xyz="[1 1 0]"/>
       <limit effort="0.0" lower="-3.14159" upper="3.14159" velocity="0.0"/>
    </joint>
    <link name="Link3-1-0">
        <inertial>
            <origin xyz="0.0 0.0 0.11047937794408418" rpy="0 0 0"/>
            <mass value="1" />
            <inertia ixx="100" ixy="0" ixz="0" iyy="100" iyz="0" izz="100" />
        </inertial>
        <visual>
            <origin xyz="0.0 0.0 0.11047937794408418" rpy="0 0 0"/>
            <geometry>
                <box size="0.8524518835977621 0.3129458628815554 0.22095875588816835" />
            </geometry>
            <material name="Blue">
                <color rgba="0 0 1.0 1.0"/>
            </material>
        </visual>
        <collision>
            <origin xyz="0.0 0.0 0.11047937794408418" rpy="0 0 0"/>
            <geometry>
                <box size="0.8524518835977621 0.3129458628815554 0.22095875588816835" />
            </geometry>
        </collision>
    </link>
    <joint name="Link3-1-0_Link3-1-1" type="revolute">
       <parent link="Link3-1-0"/>
       <child  link="Link3-1-1"/>
       <origin rpy="0 0 0" xyz="0.0 0.0 0.22095875588816835" />
     <axis xyz="[1 1 0]"/>
       <limit effort="0.0" lower="-3.14159" upper="3.14159" velocity="0.0"/>
    </joint>
    <link name="Link3-1-1">
        <inertial>
            <origin xyz="0.0 0.0 0.17627043020192243" rpy="0 0 0"/>
            <mass value="1" />
            <inertia ixx="100" ixy="0" ixz="0" iyy="100" iyz="0" izz="100" />
        </inertial>
        <visual>
            <origin xyz="0.0 0.0 0.17627043020192243" rpy="0 0 0"/>
            <geometry>
                <box size="0.7901350797505073 0.8473089720748427 0.35254086040384486" />
            </geometry>
            <material name="Green">
                <color rgba="0 1.0 0 1.0"/>
            </material>
        </visual>
        <collision>
            <origin xyz="0.0 0.0 0.17627043020192243" rpy="0 0 0"/>
            <geometry>
                <box size="0.7901350797505073 0.8473089720748427 0.35254086040384486" />
            </geometry>
        </collision>
    </link>
    <joint name="Link3-0-3_Link3-0-3-0" type="revolute">
       <parent link="Link3-0-3"/>
       <child  link="Link3-0-3-0"/>
       <origin rpy="0 0 0" xyz="0.18109559101110106 0.0 -0.12667109041417846" />
     <axis xyz="[0 1 1]"/>
       <limit effort="0.0" lower="-3.14159" upper="3.14159" velocity="0.0"/>
    </joint>
    <link name="Link3-0-3-0">
        <inertial>
            <origin xyz="0.3368975661587281 0.0 0.0" rpy="0 0 0"/>
            <mass value="1" />
            <inertia ixx="100" ixy="0" ixz="0" iyy="100" iyz="0" izz="100" />
        </inertial>
        <visual>
            <origin xyz="0.3368975661587281 0.0 0.0" rpy="0 0 0"/>
            <geometry>
                <box size="0.6737951323174562 0.42590374239517087 0.16331531609403577" />
            </geometry>
            <material name="Blue">
                <color rgba="0 0 1.0 1.0"/>
            </material>
        </visual>
        <collision>
            <origin xyz="0.3368975661587281 0.0 0.0" rpy="0 0 0"/>
            <geometry>
                <box size="0.6737951323174562 0.42590374239517087 0.16331531609403577" />
            </geometry>
        </collision>
    </link>
    <joint name="Link3-0-2_Link3-0-2-0" type="revolute">
       <parent link="Link3-0-2"/>
       <child  link="Link3-0-2-0"/>
       <origin rpy="0 0 0" xyz="0.10629263716744619 0.0 -0.08556543430116387" />
     <axis xyz="[0 1 1]"/>
       <limit effort="0.0" lower="-3.14159" upper="3.14159" velocity="0.0"/>
    </joint>
    <link name="Link3-0-2-0">
        <inertial>
            <origin xyz="0.12215837553705966 0.0 0.0" rpy="0 0 0"/>
            <mass value="1" />
            <inertia ixx="100" ixy="0" ixz="0" iyy="100" iyz="0" izz="100" />
        </inertial>
        <visual>
            <origin xyz="0.12215837553705966 0.0 0.0" rpy="0 0 0"/>
            <geometry>
                <box size="0.24431675107411932 0.8773438199209468 0.7093972256756588" />
            </geometry>
            <material name="Green">
                <color rgba="0 1.0 0 1.0"/>
            </material>
        </visual>
        <collision>
            <origin xyz="0.12215837553705966 0.0 0.0" rpy="0 0 0"/>
            <geometry>
                <box size="0.24431675107411932 0.8773438199209468 0.7093972256756588" />
            </geometry>
        </collision>
    </link>
</robot>