<robot name = "robot">
    <link name="Link0">
        <inertial>
            <origin xyz="0.0 0.0 2.347380925439458" rpy="0 0 0"/>
            <mass value="1" />
            <inertia ixx="100" ixy="0" ixz="0" iyy="100" iyz="0" izz="100" />
        </inertial>
        <visual>
            <origin xyz="0.0 0.0 2.347380925439458" rpy="0 0 0"/>
            <geometry>
                <box size="0.6556113182557813 0.7988963059505801 0.6947618508789163" />
            </geometry>
            <material name="Green">
                <color rgba="0 1.0 0 1.0"/>
            </material>
        </visual>
        <collision>
            <origin xyz="0.0 0.0 2.347380925439458" rpy="0 0 0"/>
            <geometry>
                <box size="0.6556113182557813 0.7988963059505801 0.6947618508789163" />
            </geometry>
        </collision>
    </link>
    <joint name="Link0_Link1" type="revolute">
       <parent link="Link0"/>
       <child  link="Link1"/>
       <origin rpy="0 0 0" xyz="0.0 0.39944815297529007 2.347380925439458" />
     <axis xyz="1 0 1"/>
       <limit effort="0.0" lower="-3.14159" upper="3.14159" velocity="0.0"/>
    </joint>
    <link name="Link1">
        <inertial>
            <origin xyz="0.0 0.4330039159281214 0.0" rpy="0 0 0"/>
            <mass value="1" />
            <inertia ixx="100" ixy="0" ixz="0" iyy="100" iyz="0" izz="100" />
        </inertial>
        <visual>
            <origin xyz="0.0 0.4330039159281214 0.0" rpy="0 0 0"/>
            <geometry>
                <box size="0.43864994951046576 0.8660078318562427 0.2292700854433876" />
            </geometry>
            <material name="Blue">
                <color rgba="0 0 1.0 1.0"/>
            </material>
        </visual>
        <collision>
            <origin xyz="0.0 0.4330039159281214 0.0" rpy="0 0 0"/>
            <geometry>
                <box size="0.43864994951046576 0.8660078318562427 0.2292700854433876" />
            </geometry>
        </collision>
    </link>
    <joint name="Link1_Link2" type="revolute">
       <parent link="Link1"/>
       <child  link="Link2"/>
       <origin rpy="0 0 0" xyz="0.0 0.8660078318562427 0.0" />
     <axis xyz="[1 0 1]"/>
       <limit effort="0.0" lower="-3.14159" upper="3.14159" velocity="0.0"/>
    </joint>
    <link name="Link2">
        <inertial>
            <origin xyz="0.0 0.41452776315244444 0.0" rpy="0 0 0"/>
            <mass value="1" />
            <inertia ixx="100" ixy="0" ixz="0" iyy="100" iyz="0" izz="100" />
        </inertial>
        <visual>
            <origin xyz="0.0 0.41452776315244444 0.0" rpy="0 0 0"/>
            <geometry>
                <box size="0.2381827439397659 0.8290555263048889 0.4390122789822055" />
            </geometry>
            <material name="Blue">
                <color rgba="0 0 1.0 1.0"/>
            </material>
        </visual>
        <collision>
            <origin xyz="0.0 0.41452776315244444 0.0" rpy="0 0 0"/>
            <geometry>
                <box size="0.2381827439397659 0.8290555263048889 0.4390122789822055" />
            </geometry>
        </collision>
    </link>
    <joint name="Link2_Link2-0" type="revolute">
       <parent link="Link2"/>
       <child  link="Link2-0"/>
       <origin rpy="0 0 0" xyz="0.11909137196988295 0.41452776315244444 0.0" />
     <axis xyz="[0 1 1]"/>
       <limit effort="0.0" lower="-3.14159" upper="3.14159" velocity="0.0"/>
    </joint>
    <link name="Link2-0">
        <inertial>
            <origin xyz="0.22051143671661644 0.0 0.0" rpy="0 0 0"/>
            <mass value="1" />
            <inertia ixx="100" ixy="0" ixz="0" iyy="100" iyz="0" izz="100" />
        </inertial>
        <visual>
            <origin xyz="0.22051143671661644 0.0 0.0" rpy="0 0 0"/>
            <geometry>
                <box size="0.4410228734332329 0.8095362097043954 0.30989572202897314" />
            </geometry>
            <material name="Green">
                <color rgba="0 1.0 0 1.0"/>
            </material>
        </visual>
        <collision>
            <origin xyz="0.22051143671661644 0.0 0.0" rpy="0 0 0"/>
            <geometry>
                <box size="0.4410228734332329 0.8095362097043954 0.30989572202897314" />
            </geometry>
        </collision>
    </link>
    <joint name="Link2-0_Link2-0-0" type="revolute">
       <parent link="Link2-0"/>
       <child  link="Link2-0-0"/>
       <origin rpy="0 0 0" xyz="0.22051143671661644 0.4047681048521977 0.0" />
     <axis xyz="[1 0 1]"/>
       <limit effort="0.0" lower="-3.14159" upper="3.14159" velocity="0.0"/>
    </joint>
    <link name="Link2-0-0">
        <inertial>
            <origin xyz="0.0 0.1791327018397962 0.0" rpy="0 0 0"/>
            <mass value="1" />
            <inertia ixx="100" ixy="0" ixz="0" iyy="100" iyz="0" izz="100" />
        </inertial>
        <visual>
            <origin xyz="0.0 0.1791327018397962 0.0" rpy="0 0 0"/>
            <geometry>
                <box size="0.5968319292369414 0.3582654036795924 0.2644204760633514" />
            </geometry>
            <material name="Blue">
                <color rgba="0 0 1.0 1.0"/>
            </material>
        </visual>
        <collision>
            <origin xyz="0.0 0.1791327018397962 0.0" rpy="0 0 0"/>
            <geometry>
                <box size="0.5968319292369414 0.3582654036795924 0.2644204760633514" />
            </geometry>
        </collision>
    </link>
    <joint name="Link2-0-0_Link2-0-1" type="revolute">
       <parent link="Link2-0-0"/>
       <child  link="Link2-0-1"/>
       <origin rpy="0 0 0" xyz="0.0 0.3582654036795924 0.0" />
     <axis xyz="[1 0 1]"/>
       <limit effort="0.0" lower="-3.14159" upper="3.14159" velocity="0.0"/>
    </joint>
    <link name="Link2-0-1">
        <inertial>
            <origin xyz="0.0 0.4551450825428802 0.0" rpy="0 0 0"/>
            <mass value="1" />
            <inertia ixx="100" ixy="0" ixz="0" iyy="100" iyz="0" izz="100" />
        </inertial>
        <visual>
            <origin xyz="0.0 0.4551450825428802 0.0" rpy="0 0 0"/>
            <geometry>
                <box size="0.5225260870734044 0.9102901650857604 0.16781185778720376" />
            </geometry>
            <material name="Green">
                <color rgba="0 1.0 0 1.0"/>
            </material>
        </visual>
        <collision>
            <origin xyz="0.0 0.4551450825428802 0.0" rpy="0 0 0"/>
            <geometry>
                <box size="0.5225260870734044 0.9102901650857604 0.16781185778720376" />
            </geometry>
        </collision>
    </link>
    <joint name="Link2-0-1_Link2-0-2" type="revolute">
       <parent link="Link2-0-1"/>
       <child  link="Link2-0-2"/>
       <origin rpy="0 0 0" xyz="0.0 0.9102901650857604 0.0" />
     <axis xyz="[1 0 1]"/>
       <limit effort="0.0" lower="-3.14159" upper="3.14159" velocity="0.0"/>
    </joint>
    <link name="Link2-0-2">
        <inertial>
            <origin xyz="0.0 0.3858903282903403 0.0" rpy="0 0 0"/>
            <mass value="1" />
            <inertia ixx="100" ixy="0" ixz="0" iyy="100" iyz="0" izz="100" />
        </inertial>
        <visual>
            <origin xyz="0.0 0.3858903282903403 0.0" rpy="0 0 0"/>
            <geometry>
                <box size="0.5157508784519319 0.7717806565806806 0.27311105518638257" />
            </geometry>
            <material name="Green">
                <color rgba="0 1.0 0 1.0"/>
            </material>
        </visual>
        <collision>
            <origin xyz="0.0 0.3858903282903403 0.0" rpy="0 0 0"/>
            <geometry>
                <box size="0.5157508784519319 0.7717806565806806 0.27311105518638257" />
            </geometry>
        </collision>
    </link>
    <joint name="Link2-0-2_Link2-0-3" type="revolute">
       <parent link="Link2-0-2"/>
       <child  link="Link2-0-3"/>
       <origin rpy="0 0 0" xyz="0.0 0.7717806565806806 0.0" />
     <axis xyz="[1 0 1]"/>
       <limit effort="0.0" lower="-3.14159" upper="3.14159" velocity="0.0"/>
    </joint>
    <link name="Link2-0-3">
        <inertial>
            <origin xyz="0.0 0.3927069300047277 0.0" rpy="0 0 0"/>
            <mass value="1" />
            <inertia ixx="100" ixy="0" ixz="0" iyy="100" iyz="0" izz="100" />
        </inertial>
        <visual>
            <origin xyz="0.0 0.3927069300047277 0.0" rpy="0 0 0"/>
            <geometry>
                <box size="0.224219422037877 0.7854138600094553 0.31047588066466314" />
            </geometry>
            <material name="Green">
                <color rgba="0 1.0 0 1.0"/>
            </material>
        </visual>
        <collision>
            <origin xyz="0.0 0.3927069300047277 0.0" rpy="0 0 0"/>
            <geometry>
                <box size="0.224219422037877 0.7854138600094553 0.31047588066466314" />
            </geometry>
        </collision>
    </link>
    <joint name="Link2-0-2_Link2-0-2-0" type="revolute">
       <parent link="Link2-0-2"/>
       <child  link="Link2-0-2-0"/>
       <origin rpy="0 0 0" xyz="-0.25787543922596595 0.3858903282903403 0.0" />
     <axis xyz="[2 1 1]"/>
       <limit effort="0.0" lower="-3.14159" upper="3.14159" velocity="0.0"/>
    </joint>
    <link name="Link2-0-2-0">
        <inertial>
            <origin xyz="-0.21598655281884432 0.0 0.0" rpy="0 0 0"/>
            <mass value="1" />
            <inertia ixx="100" ixy="0" ixz="0" iyy="100" iyz="0" izz="100" />
        </inertial>
        <visual>
            <origin xyz="-0.21598655281884432 0.0 0.0" rpy="0 0 0"/>
            <geometry>
                <box size="0.43197310563768865 0.515493573385988 0.26020244545372184" />
            </geometry>
            <material name="Green">
                <color rgba="0 1.0 0 1.0"/>
            </material>
        </visual>
        <collision>
            <origin xyz="-0.21598655281884432 0.0 0.0" rpy="0 0 0"/>
            <geometry>
                <box size="0.43197310563768865 0.515493573385988 0.26020244545372184" />
            </geometry>
        </collision>
    </link>
    <joint name="Link2-0-2-0_Link2-0-2-0-0" type="revolute">
       <parent link="Link2-0-2-0"/>
       <child  link="Link2-0-2-0-0"/>
       <origin rpy="0 0 0" xyz="-0.21598655281884432 0.257746786692994 0.0" />
     <axis xyz="[1 0 1]"/>
       <limit effort="0.0" lower="-3.14159" upper="3.14159" velocity="0.0"/>
    </joint>
    <link name="Link2-0-2-0-0">
        <inertial>
            <origin xyz="0.0 0.274239990714558 0.0" rpy="0 0 0"/>
            <mass value="1" />
            <inertia ixx="100" ixy="0" ixz="0" iyy="100" iyz="0" izz="100" />
        </inertial>
        <visual>
            <origin xyz="0.0 0.274239990714558 0.0" rpy="0 0 0"/>
            <geometry>
                <box size="0.7417715232969814 0.548479981429116 0.1929373362876486" />
            </geometry>
            <material name="Blue">
                <color rgba="0 0 1.0 1.0"/>
            </material>
        </visual>
        <collision>
            <origin xyz="0.0 0.274239990714558 0.0" rpy="0 0 0"/>
            <geometry>
                <box size="0.7417715232969814 0.548479981429116 0.1929373362876486" />
            </geometry>
        </collision>
    </link>
</robot>