<robot name = "robot">
    <link name="Link0">
        <inertial>
            <origin xyz="0.0 0.0 2.167524504062173" rpy="0 0 0"/>
            <mass value="1" />
            <inertia ixx="100" ixy="0" ixz="0" iyy="100" iyz="0" izz="100" />
        </inertial>
        <visual>
            <origin xyz="0.0 0.0 2.167524504062173" rpy="0 0 0"/>
            <geometry>
                <box size="0.5613742833766574 0.6874231174560351 0.3350490081243459" />
            </geometry>
            <material name="Green">
                <color rgba="0 1.0 0 1.0"/>
            </material>
        </visual>
        <collision>
            <origin xyz="0.0 0.0 2.167524504062173" rpy="0 0 0"/>
            <geometry>
                <box size="0.5613742833766574 0.6874231174560351 0.3350490081243459" />
            </geometry>
        </collision>
    </link>
    <joint name="Link0_Link1" type="revolute">
       <parent link="Link0"/>
       <child  link="Link1"/>
       <origin rpy="0 0 0" xyz="0.0 0.34371155872801756 2.167524504062173" />
     <axis xyz="1 0 1"/>
       <limit effort="0.0" lower="-3.14159" upper="3.14159" velocity="0.0"/>
    </joint>
    <link name="Link1">
        <inertial>
            <origin xyz="0.0 0.41119245476884436 0.0" rpy="0 0 0"/>
            <mass value="1" />
            <inertia ixx="100" ixy="0" ixz="0" iyy="100" iyz="0" izz="100" />
        </inertial>
        <visual>
            <origin xyz="0.0 0.41119245476884436 0.0" rpy="0 0 0"/>
            <geometry>
                <box size="0.5867850357567116 0.8223849095376887 0.3810762931927206" />
            </geometry>
            <material name="Blue">
                <color rgba="0 0 1.0 1.0"/>
            </material>
        </visual>
        <collision>
            <origin xyz="0.0 0.41119245476884436 0.0" rpy="0 0 0"/>
            <geometry>
                <box size="0.5867850357567116 0.8223849095376887 0.3810762931927206" />
            </geometry>
        </collision>
    </link>
    <joint name="Link1_Link2" type="revolute">
       <parent link="Link1"/>
       <child  link="Link2"/>
       <origin rpy="0 0 0" xyz="0.0 0.8223849095376887 0.0" />
     <axis xyz="[1 0 1]"/>
       <limit effort="0.0" lower="-3.14159" upper="3.14159" velocity="0.0"/>
    </joint>
    <link name="Link2">
        <inertial>
            <origin xyz="0.0 0.22353898299101596 0.0" rpy="0 0 0"/>
            <mass value="1" />
            <inertia ixx="100" ixy="0" ixz="0" iyy="100" iyz="0" izz="100" />
        </inertial>
        <visual>
            <origin xyz="0.0 0.22353898299101596 0.0" rpy="0 0 0"/>
            <geometry>
                <box size="0.6165525835534267 0.4470779659820319 0.2677476928226777" />
            </geometry>
            <material name="Green">
                <color rgba="0 1.0 0 1.0"/>
            </material>
        </visual>
        <collision>
            <origin xyz="0.0 0.22353898299101596 0.0" rpy="0 0 0"/>
            <geometry>
                <box size="0.6165525835534267 0.4470779659820319 0.2677476928226777" />
            </geometry>
        </collision>
    </link>
</robot>