<robot name = "robot">
    <link name="Link0">
        <inertial>
            <origin xyz="0.0 0.0 2.08077004657739" rpy="0 0 0"/>
            <mass value="1" />
            <inertia ixx="100" ixy="0" ixz="0" iyy="100" iyz="0" izz="100" />
        </inertial>
        <visual>
            <origin xyz="0.0 0.0 2.08077004657739" rpy="0 0 0"/>
            <geometry>
                <box size="0.5622059359268251 0.9697205657714922 0.16154009315478013" />
            </geometry>
            <material name="Green">
                <color rgba="0 1.0 0 1.0"/>
            </material>
        </visual>
        <collision>
            <origin xyz="0.0 0.0 2.08077004657739" rpy="0 0 0"/>
            <geometry>
                <box size="0.5622059359268251 0.9697205657714922 0.16154009315478013" />
            </geometry>
        </collision>
    </link>
    <joint name="Link0_Link1" type="revolute">
       <parent link="Link0"/>
       <child  link="Link1"/>
       <origin rpy="0 0 0" xyz="0.0 0.4848602828857461 2.08077004657739" />
     <axis xyz="1 0 1"/>
       <limit effort="0.0" lower="-3.14159" upper="3.14159" velocity="0.0"/>
    </joint>
    <link name="Link1">
        <inertial>
            <origin xyz="0.0 0.3916074420127125 0.0" rpy="0 0 0"/>
            <mass value="1" />
            <inertia ixx="100" ixy="0" ixz="0" iyy="100" iyz="0" izz="100" />
        </inertial>
        <visual>
            <origin xyz="0.0 0.3916074420127125 0.0" rpy="0 0 0"/>
            <geometry>
                <box size="0.6866810504739906 0.783214884025425 0.3420579317552028" />
            </geometry>
            <material name="Blue">
                <color rgba="0 0 1.0 1.0"/>
            </material>
        </visual>
        <collision>
            <origin xyz="0.0 0.3916074420127125 0.0" rpy="0 0 0"/>
            <geometry>
                <box size="0.6866810504739906 0.783214884025425 0.3420579317552028" />
            </geometry>
        </collision>
    </link>
    <joint name="Link1_Link2" type="revolute">
       <parent link="Link1"/>
       <child  link="Link2"/>
       <origin rpy="0 0 0" xyz="0.0 0.783214884025425 0.0" />
     <axis xyz="[1 0 1]"/>
       <limit effort="0.0" lower="-3.14159" upper="3.14159" velocity="0.0"/>
    </joint>
    <link name="Link2">
        <inertial>
            <origin xyz="0.0 0.1708915940969892 0.0" rpy="0 0 0"/>
            <mass value="1" />
            <inertia ixx="100" ixy="0" ixz="0" iyy="100" iyz="0" izz="100" />
        </inertial>
        <visual>
            <origin xyz="0.0 0.1708915940969892 0.0" rpy="0 0 0"/>
            <geometry>
                <box size="0.7683872372629127 0.3417831881939784 0.2333166103879922" />
            </geometry>
            <material name="Blue">
                <color rgba="0 0 1.0 1.0"/>
            </material>
        </visual>
        <collision>
            <origin xyz="0.0 0.1708915940969892 0.0" rpy="0 0 0"/>
            <geometry>
                <box size="0.7683872372629127 0.3417831881939784 0.2333166103879922" />
            </geometry>
        </collision>
    </link>
</robot>