<robot name = "robot">
    <link name="Link0">
        <inertial>
            <origin xyz="0.0 0.0 2.19436337034665" rpy="0 0 0"/>
            <mass value="1" />
            <inertia ixx="100" ixy="0" ixz="0" iyy="100" iyz="0" izz="100" />
        </inertial>
        <visual>
            <origin xyz="0.0 0.0 2.19436337034665" rpy="0 0 0"/>
            <geometry>
                <box size="0.38628232644048444 0.284903973643779 0.3887267406932999" />
            </geometry>
            <material name="Green">
                <color rgba="0 1.0 0 1.0"/>
            </material>
        </visual>
        <collision>
            <origin xyz="0.0 0.0 2.19436337034665" rpy="0 0 0"/>
            <geometry>
                <box size="0.38628232644048444 0.284903973643779 0.3887267406932999" />
            </geometry>
        </collision>
    </link>
    <joint name="Link0_Link1" type="revolute">
       <parent link="Link0"/>
       <child  link="Link1"/>
       <origin rpy="0 0 0" xyz="0.0 0.1424519868218895 2.19436337034665" />
     <axis xyz="1 0 1"/>
       <limit effort="0.0" lower="-3.14159" upper="3.14159" velocity="0.0"/>
    </joint>
    <link name="Link1">
        <inertial>
            <origin xyz="0.0 0.1703847636912714 0.0" rpy="0 0 0"/>
            <mass value="1" />
            <inertia ixx="100" ixy="0" ixz="0" iyy="100" iyz="0" izz="100" />
        </inertial>
        <visual>
            <origin xyz="0.0 0.1703847636912714 0.0" rpy="0 0 0"/>
            <geometry>
                <box size="0.7325462306935725 0.3407695273825428 0.2597360046694297" />
            </geometry>
            <material name="Blue">
                <color rgba="0 0 1.0 1.0"/>
            </material>
        </visual>
        <collision>
            <origin xyz="0.0 0.1703847636912714 0.0" rpy="0 0 0"/>
            <geometry>
                <box size="0.7325462306935725 0.3407695273825428 0.2597360046694297" />
            </geometry>
        </collision>
    </link>
    <joint name="Link1_Link2" type="revolute">
       <parent link="Link1"/>
       <child  link="Link2"/>
       <origin rpy="0 0 0" xyz="0.0 0.3407695273825428 0.0" />
     <axis xyz="[1 0 1]"/>
       <limit effort="0.0" lower="-3.14159" upper="3.14159" velocity="0.0"/>
    </joint>
    <link name="Link2">
        <inertial>
            <origin xyz="0.0 0.137441620712918 0.0" rpy="0 0 0"/>
            <mass value="1" />
            <inertia ixx="100" ixy="0" ixz="0" iyy="100" iyz="0" izz="100" />
        </inertial>
        <visual>
            <origin xyz="0.0 0.137441620712918 0.0" rpy="0 0 0"/>
            <geometry>
                <box size="0.3049819791346169 0.274883241425836 0.4233848029077832" />
            </geometry>
            <material name="Blue">
                <color rgba="0 0 1.0 1.0"/>
            </material>
        </visual>
        <collision>
            <origin xyz="0.0 0.137441620712918 0.0" rpy="0 0 0"/>
            <geometry>
                <box size="0.3049819791346169 0.274883241425836 0.4233848029077832" />
            </geometry>
        </collision>
    </link>
</robot>