<robot name = "robot">
    <link name="Link0">
        <inertial>
            <origin xyz="0.0 0.0 2.1172372291066703" rpy="0 0 0"/>
            <mass value="1" />
            <inertia ixx="100" ixy="0" ixz="0" iyy="100" iyz="0" izz="100" />
        </inertial>
        <visual>
            <origin xyz="0.0 0.0 2.1172372291066703" rpy="0 0 0"/>
            <geometry>
                <box size="0.7205718764288973 0.6773235128572984 0.23447445821334068" />
            </geometry>
            <material name="Green">
                <color rgba="0 1.0 0 1.0"/>
            </material>
        </visual>
        <collision>
            <origin xyz="0.0 0.0 2.1172372291066703" rpy="0 0 0"/>
            <geometry>
                <box size="0.7205718764288973 0.6773235128572984 0.23447445821334068" />
            </geometry>
        </collision>
    </link>
    <joint name="Link0_Link1" type="revolute">
       <parent link="Link0"/>
       <child  link="Link1"/>
       <origin rpy="0 0 0" xyz="0.0 0.3386617564286492 2.1172372291066703" />
     <axis xyz="1 0 1"/>
       <limit effort="0.0" lower="-3.14159" upper="3.14159" velocity="0.0"/>
    </joint>
    <link name="Link1">
        <inertial>
            <origin xyz="0.0 0.42421849852066007 0.0" rpy="0 0 0"/>
            <mass value="1" />
            <inertia ixx="100" ixy="0" ixz="0" iyy="100" iyz="0" izz="100" />
        </inertial>
        <visual>
            <origin xyz="0.0 0.42421849852066007 0.0" rpy="0 0 0"/>
            <geometry>
                <box size="0.7078971287742606 0.8484369970413201 0.42887510553616387" />
            </geometry>
            <material name="Green">
                <color rgba="0 1.0 0 1.0"/>
            </material>
        </visual>
        <collision>
            <origin xyz="0.0 0.42421849852066007 0.0" rpy="0 0 0"/>
            <geometry>
                <box size="0.7078971287742606 0.8484369970413201 0.42887510553616387" />
            </geometry>
        </collision>
    </link>
    <joint name="Link1_Link2" type="revolute">
       <parent link="Link1"/>
       <child  link="Link2"/>
       <origin rpy="0 0 0" xyz="0.0 0.8484369970413201 0.0" />
     <axis xyz="[1 0 1]"/>
       <limit effort="0.0" lower="-3.14159" upper="3.14159" velocity="0.0"/>
    </joint>
    <link name="Link2">
        <inertial>
            <origin xyz="0.0 0.23708846459165833 0.0" rpy="0 0 0"/>
            <mass value="1" />
            <inertia ixx="100" ixy="0" ixz="0" iyy="100" iyz="0" izz="100" />
        </inertial>
        <visual>
            <origin xyz="0.0 0.23708846459165833 0.0" rpy="0 0 0"/>
            <geometry>
                <box size="0.6149942019557882 0.47417692918331666 0.41499118026782467" />
            </geometry>
            <material name="Green">
                <color rgba="0 1.0 0 1.0"/>
            </material>
        </visual>
        <collision>
            <origin xyz="0.0 0.23708846459165833 0.0" rpy="0 0 0"/>
            <geometry>
                <box size="0.6149942019557882 0.47417692918331666 0.41499118026782467" />
            </geometry>
        </collision>
    </link>
    <joint name="Link1_Link1-0" type="revolute">
       <parent link="Link1"/>
       <child  link="Link1-0"/>
       <origin rpy="0 0 0" xyz="0.0 0.42421849852066007 0.21443755276808193" />
     <axis xyz="[1 1 0]"/>
       <limit effort="0.0" lower="-3.14159" upper="3.14159" velocity="0.0"/>
    </joint>
    <link name="Link1-0">
        <inertial>
            <origin xyz="0.0 0.0 0.23210821943137688" rpy="0 0 0"/>
            <mass value="1" />
            <inertia ixx="100" ixy="0" ixz="0" iyy="100" iyz="0" izz="100" />
        </inertial>
        <visual>
            <origin xyz="0.0 0.0 0.23210821943137688" rpy="0 0 0"/>
            <geometry>
                <box size="0.261454453569423 0.9288655327875287 0.46421643886275377" />
            </geometry>
            <material name="Blue">
                <color rgba="0 0 1.0 1.0"/>
            </material>
        </visual>
        <collision>
            <origin xyz="0.0 0.0 0.23210821943137688" rpy="0 0 0"/>
            <geometry>
                <box size="0.261454453569423 0.9288655327875287 0.46421643886275377" />
            </geometry>
        </collision>
    </link>
    <joint name="Link1-0_Link1-0-0" type="revolute">
       <parent link="Link1-0"/>
       <child  link="Link1-0-0"/>
       <origin rpy="0 0 0" xyz="0.0 0.46443276639376435 0.23210821943137688" />
     <axis xyz="[1 0 1]"/>
       <limit effort="0.0" lower="-3.14159" upper="3.14159" velocity="0.0"/>
    </joint>
    <link name="Link1-0-0">
        <inertial>
            <origin xyz="0.0 0.4155173079178327 0.0" rpy="0 0 0"/>
            <mass value="1" />
            <inertia ixx="100" ixy="0" ixz="0" iyy="100" iyz="0" izz="100" />
        </inertial>
        <visual>
            <origin xyz="0.0 0.4155173079178327 0.0" rpy="0 0 0"/>
            <geometry>
                <box size="0.44124871112798075 0.8310346158356654 0.19849995286864375" />
            </geometry>
            <material name="Blue">
                <color rgba="0 0 1.0 1.0"/>
            </material>
        </visual>
        <collision>
            <origin xyz="0.0 0.4155173079178327 0.0" rpy="0 0 0"/>
            <geometry>
                <box size="0.44124871112798075 0.8310346158356654 0.19849995286864375" />
            </geometry>
        </collision>
    </link>
</robot>