<robot name = "robot">
    <link name="Link0">
        <inertial>
            <origin xyz="0.0 0.0 2.1325248571208544" rpy="0 0 0"/>
            <mass value="1" />
            <inertia ixx="100" ixy="0" ixz="0" iyy="100" iyz="0" izz="100" />
        </inertial>
        <visual>
            <origin xyz="0.0 0.0 2.1325248571208544" rpy="0 0 0"/>
            <geometry>
                <box size="0.47499495622334553 0.4494806956991593 0.2650497142417084" />
            </geometry>
            <material name="Green">
                <color rgba="0 1.0 0 1.0"/>
            </material>
        </visual>
        <collision>
            <origin xyz="0.0 0.0 2.1325248571208544" rpy="0 0 0"/>
            <geometry>
                <box size="0.47499495622334553 0.4494806956991593 0.2650497142417084" />
            </geometry>
        </collision>
    </link>
    <joint name="Link0_Link1" type="revolute">
       <parent link="Link0"/>
       <child  link="Link1"/>
       <origin rpy="0 0 0" xyz="0.0 0.22474034784957966 2.1325248571208544" />
     <axis xyz="1 0 1"/>
       <limit effort="0.0" lower="-3.14159" upper="3.14159" velocity="0.0"/>
    </joint>
    <link name="Link1">
        <inertial>
            <origin xyz="0.0 0.16801539563502466 0.0" rpy="0 0 0"/>
            <mass value="1" />
            <inertia ixx="100" ixy="0" ixz="0" iyy="100" iyz="0" izz="100" />
        </inertial>
        <visual>
            <origin xyz="0.0 0.16801539563502466 0.0" rpy="0 0 0"/>
            <geometry>
                <box size="0.46839375668549615 0.3360307912700493 0.18817033119153553" />
            </geometry>
            <material name="Green">
                <color rgba="0 1.0 0 1.0"/>
            </material>
        </visual>
        <collision>
            <origin xyz="0.0 0.16801539563502466 0.0" rpy="0 0 0"/>
            <geometry>
                <box size="0.46839375668549615 0.3360307912700493 0.18817033119153553" />
            </geometry>
        </collision>
    </link>
    <joint name="Link1_Link2" type="revolute">
       <parent link="Link1"/>
       <child  link="Link2"/>
       <origin rpy="0 0 0" xyz="0.0 0.3360307912700493 0.0" />
     <axis xyz="[1 0 1]"/>
       <limit effort="0.0" lower="-3.14159" upper="3.14159" velocity="0.0"/>
    </joint>
    <link name="Link2">
        <inertial>
            <origin xyz="0.0 0.34289494019630673 0.0" rpy="0 0 0"/>
            <mass value="1" />
            <inertia ixx="100" ixy="0" ixz="0" iyy="100" iyz="0" izz="100" />
        </inertial>
        <visual>
            <origin xyz="0.0 0.34289494019630673 0.0" rpy="0 0 0"/>
            <geometry>
                <box size="0.7896028702139255 0.6857898803926135 0.31661215682023225" />
            </geometry>
            <material name="Blue">
                <color rgba="0 0 1.0 1.0"/>
            </material>
        </visual>
        <collision>
            <origin xyz="0.0 0.34289494019630673 0.0" rpy="0 0 0"/>
            <geometry>
                <box size="0.7896028702139255 0.6857898803926135 0.31661215682023225" />
            </geometry>
        </collision>
    </link>
    <joint name="Link2_Link3" type="revolute">
       <parent link="Link2"/>
       <child  link="Link3"/>
       <origin rpy="0 0 0" xyz="0.0 0.6857898803926135 0.0" />
     <axis xyz="[1 0 1]"/>
       <limit effort="0.0" lower="-3.14159" upper="3.14159" velocity="0.0"/>
    </joint>
    <link name="Link3">
        <inertial>
            <origin xyz="0.0 0.321197104256682 0.0" rpy="0 0 0"/>
            <mass value="1" />
            <inertia ixx="100" ixy="0" ixz="0" iyy="100" iyz="0" izz="100" />
        </inertial>
        <visual>
            <origin xyz="0.0 0.321197104256682 0.0" rpy="0 0 0"/>
            <geometry>
                <box size="0.2761455086228212 0.642394208513364 0.44864281967777475" />
            </geometry>
            <material name="Blue">
                <color rgba="0 0 1.0 1.0"/>
            </material>
        </visual>
        <collision>
            <origin xyz="0.0 0.321197104256682 0.0" rpy="0 0 0"/>
            <geometry>
                <box size="0.2761455086228212 0.642394208513364 0.44864281967777475" />
            </geometry>
        </collision>
    </link>
    <joint name="Link1_Link1-0" type="revolute">
       <parent link="Link1"/>
       <child  link="Link1-0"/>
       <origin rpy="0 0 0" xyz="0.23419687834274808 0.16801539563502466 0.0" />
     <axis xyz="[0 1 1]"/>
       <limit effort="0.0" lower="-3.14159" upper="3.14159" velocity="0.0"/>
    </joint>
    <link name="Link1-0">
        <inertial>
            <origin xyz="0.19284423840482362 0.0 0.0" rpy="0 0 0"/>
            <mass value="1" />
            <inertia ixx="100" ixy="0" ixz="0" iyy="100" iyz="0" izz="100" />
        </inertial>
        <visual>
            <origin xyz="0.19284423840482362 0.0 0.0" rpy="0 0 0"/>
            <geometry>
                <box size="0.38568847680964724 0.4876553884138527 0.27275143749275493" />
            </geometry>
            <material name="Green">
                <color rgba="0 1.0 0 1.0"/>
            </material>
        </visual>
        <collision>
            <origin xyz="0.19284423840482362 0.0 0.0" rpy="0 0 0"/>
            <geometry>
                <box size="0.38568847680964724 0.4876553884138527 0.27275143749275493" />
            </geometry>
        </collision>
    </link>
    <joint name="Link1-0_Link1-0-0" type="revolute">
       <parent link="Link1-0"/>
       <child  link="Link1-0-0"/>
       <origin rpy="0 0 0" xyz="0.19284423840482362 0.24382769420692635 0.0" />
     <axis xyz="[1 0 1]"/>
       <limit effort="0.0" lower="-3.14159" upper="3.14159" velocity="0.0"/>
    </joint>
    <link name="Link1-0-0">
        <inertial>
            <origin xyz="0.0 0.20761973652263338 0.0" rpy="0 0 0"/>
            <mass value="1" />
            <inertia ixx="100" ixy="0" ixz="0" iyy="100" iyz="0" izz="100" />
        </inertial>
        <visual>
            <origin xyz="0.0 0.20761973652263338 0.0" rpy="0 0 0"/>
            <geometry>
                <box size="0.38509191156093864 0.41523947304526676 0.13721530726036596" />
            </geometry>
            <material name="Green">
                <color rgba="0 1.0 0 1.0"/>
            </material>
        </visual>
        <collision>
            <origin xyz="0.0 0.20761973652263338 0.0" rpy="0 0 0"/>
            <geometry>
                <box size="0.38509191156093864 0.41523947304526676 0.13721530726036596" />
            </geometry>
        </collision>
    </link>
</robot>