<robot name = "robot">
    <link name="Link0">
        <inertial>
            <origin xyz="0.0 0.0 2.1552657945330225" rpy="0 0 0"/>
            <mass value="1" />
            <inertia ixx="100" ixy="0" ixz="0" iyy="100" iyz="0" izz="100" />
        </inertial>
        <visual>
            <origin xyz="0.0 0.0 2.1552657945330225" rpy="0 0 0"/>
            <geometry>
                <box size="0.30475782797603884 0.5149189936898513 0.31053158906604533" />
            </geometry>
            <material name="Green">
                <color rgba="0 1.0 0 1.0"/>
            </material>
        </visual>
        <collision>
            <origin xyz="0.0 0.0 2.1552657945330225" rpy="0 0 0"/>
            <geometry>
                <box size="0.30475782797603884 0.5149189936898513 0.31053158906604533" />
            </geometry>
        </collision>
    </link>
    <joint name="Link0_Link1" type="revolute">
       <parent link="Link0"/>
       <child  link="Link1"/>
       <origin rpy="0 0 0" xyz="0.0 0.25745949684492564 2.1552657945330225" />
     <axis xyz="1 0 1"/>
       <limit effort="0.0" lower="-3.14159" upper="3.14159" velocity="0.0"/>
    </joint>
    <link name="Link1">
        <inertial>
            <origin xyz="0.0 0.4312379121799787 0.0" rpy="0 0 0"/>
            <mass value="1" />
            <inertia ixx="100" ixy="0" ixz="0" iyy="100" iyz="0" izz="100" />
        </inertial>
        <visual>
            <origin xyz="0.0 0.4312379121799787 0.0" rpy="0 0 0"/>
            <geometry>
                <box size="0.25241634760844534 0.8624758243599574 0.48852457590723875" />
            </geometry>
            <material name="Green">
                <color rgba="0 1.0 0 1.0"/>
            </material>
        </visual>
        <collision>
            <origin xyz="0.0 0.4312379121799787 0.0" rpy="0 0 0"/>
            <geometry>
                <box size="0.25241634760844534 0.8624758243599574 0.48852457590723875" />
            </geometry>
        </collision>
    </link>
    <joint name="Link1_Link2" type="revolute">
       <parent link="Link1"/>
       <child  link="Link2"/>
       <origin rpy="0 0 0" xyz="0.0 0.8624758243599574 0.0" />
     <axis xyz="[1 0 1]"/>
       <limit effort="0.0" lower="-3.14159" upper="3.14159" velocity="0.0"/>
    </joint>
    <link name="Link2">
        <inertial>
            <origin xyz="0.0 0.20890500632586687 0.0" rpy="0 0 0"/>
            <mass value="1" />
            <inertia ixx="100" ixy="0" ixz="0" iyy="100" iyz="0" izz="100" />
        </inertial>
        <visual>
            <origin xyz="0.0 0.20890500632586687 0.0" rpy="0 0 0"/>
            <geometry>
                <box size="0.8455254391010102 0.41781001265173373 0.3505376905310223" />
            </geometry>
            <material name="Blue">
                <color rgba="0 0 1.0 1.0"/>
            </material>
        </visual>
        <collision>
            <origin xyz="0.0 0.20890500632586687 0.0" rpy="0 0 0"/>
            <geometry>
                <box size="0.8455254391010102 0.41781001265173373 0.3505376905310223" />
            </geometry>
        </collision>
    </link>
    <joint name="Link2_Link2-0" type="revolute">
       <parent link="Link2"/>
       <child  link="Link2-0"/>
       <origin rpy="0 0 0" xyz="-0.19277385045478224 0.20890500632586687 0.0" />
     <axis xyz="[2 1 1]"/>
       <limit effort="0.0" lower="-3.14159" upper="3.14159" velocity="0.0"/>
    </joint>
    <link name="Link2-0">
        <inertial>
            <origin xyz="-0.2368177548333911 0.0 0.0" rpy="0 0 0"/>
            <mass value="1" />
            <inertia ixx="100" ixy="0" ixz="0" iyy="100" iyz="0" izz="100" />
        </inertial>
        <visual>
            <origin xyz="-0.2368177548333911 0.0 0.0" rpy="0 0 0"/>
            <geometry>
                <box size="0.4736355096667822 0.4949622100841188 0.4283928593541867" />
            </geometry>
            <material name="Blue">
                <color rgba="0 0 1.0 1.0"/>
            </material>
        </visual>
        <collision>
            <origin xyz="-0.2368177548333911 0.0 0.0" rpy="0 0 0"/>
            <geometry>
                <box size="0.4736355096667822 0.4949622100841188 0.4283928593541867" />
            </geometry>
        </collision>
    </link>
</robot>