<robot name = "robot">
    <link name="Link0">
        <inertial>
            <origin xyz="0.0 0.0 2.0986740956850563" rpy="0 0 0"/>
            <mass value="1" />
            <inertia ixx="100" ixy="0" ixz="0" iyy="100" iyz="0" izz="100" />
        </inertial>
        <visual>
            <origin xyz="0.0 0.0 2.0986740956850563" rpy="0 0 0"/>
            <geometry>
                <box size="0.644133215932493 0.740562461050733 0.19734819137011275" />
            </geometry>
            <material name="Green">
                <color rgba="0 1.0 0 1.0"/>
            </material>
        </visual>
        <collision>
            <origin xyz="0.0 0.0 2.0986740956850563" rpy="0 0 0"/>
            <geometry>
                <box size="0.644133215932493 0.740562461050733 0.19734819137011275" />
            </geometry>
        </collision>
    </link>
    <joint name="Link0_Link1" type="revolute">
       <parent link="Link0"/>
       <child  link="Link1"/>
       <origin rpy="0 0 0" xyz="0.0 0.3702812305253665 2.0986740956850563" />
     <axis xyz="1 0 1"/>
       <limit effort="0.0" lower="-3.14159" upper="3.14159" velocity="0.0"/>
    </joint>
    <link name="Link1">
        <inertial>
            <origin xyz="0.0 0.20813465453035296 0.0" rpy="0 0 0"/>
            <mass value="1" />
            <inertia ixx="100" ixy="0" ixz="0" iyy="100" iyz="0" izz="100" />
        </inertial>
        <visual>
            <origin xyz="0.0 0.20813465453035296 0.0" rpy="0 0 0"/>
            <geometry>
                <box size="0.6982536283390897 0.4162693090607059 0.37509764406692114" />
            </geometry>
            <material name="Blue">
                <color rgba="0 0 1.0 1.0"/>
            </material>
        </visual>
        <collision>
            <origin xyz="0.0 0.20813465453035296 0.0" rpy="0 0 0"/>
            <geometry>
                <box size="0.6982536283390897 0.4162693090607059 0.37509764406692114" />
            </geometry>
        </collision>
    </link>
    <joint name="Link1_Link2" type="revolute">
       <parent link="Link1"/>
       <child  link="Link2"/>
       <origin rpy="0 0 0" xyz="0.0 0.4162693090607059 0.0" />
     <axis xyz="[1 0 1]"/>
       <limit effort="0.0" lower="-3.14159" upper="3.14159" velocity="0.0"/>
    </joint>
    <link name="Link2">
        <inertial>
            <origin xyz="0.0 0.44232088127801844 0.0" rpy="0 0 0"/>
            <mass value="1" />
            <inertia ixx="100" ixy="0" ixz="0" iyy="100" iyz="0" izz="100" />
        </inertial>
        <visual>
            <origin xyz="0.0 0.44232088127801844 0.0" rpy="0 0 0"/>
            <geometry>
                <box size="0.7380466034128393 0.8846417625560369 0.3883987266616526" />
            </geometry>
            <material name="Green">
                <color rgba="0 1.0 0 1.0"/>
            </material>
        </visual>
        <collision>
            <origin xyz="0.0 0.44232088127801844 0.0" rpy="0 0 0"/>
            <geometry>
                <box size="0.7380466034128393 0.8846417625560369 0.3883987266616526" />
            </geometry>
        </collision>
    </link>
</robot>