<robot name = "robot">
    <link name="Link0">
        <inertial>
            <origin xyz="0.0 0.0 2.191957806102434" rpy="0 0 0"/>
            <mass value="1" />
            <inertia ixx="100" ixy="0" ixz="0" iyy="100" iyz="0" izz="100" />
        </inertial>
        <visual>
            <origin xyz="0.0 0.0 2.191957806102434" rpy="0 0 0"/>
            <geometry>
                <box size="0.6393128346082411 0.9030557748254717 0.383915612204868" />
            </geometry>
            <material name="Green">
                <color rgba="0 1.0 0 1.0"/>
            </material>
        </visual>
        <collision>
            <origin xyz="0.0 0.0 2.191957806102434" rpy="0 0 0"/>
            <geometry>
                <box size="0.6393128346082411 0.9030557748254717 0.383915612204868" />
            </geometry>
        </collision>
    </link>
    <joint name="Link0_Link1" type="revolute">
       <parent link="Link0"/>
       <child  link="Link1"/>
       <origin rpy="0 0 0" xyz="0.0 0.45152788741273586 2.191957806102434" />
     <axis xyz="1 0 1"/>
       <limit effort="0.0" lower="-3.14159" upper="3.14159" velocity="0.0"/>
    </joint>
    <link name="Link1">
        <inertial>
            <origin xyz="0.0 0.3496319137422935 0.0" rpy="0 0 0"/>
            <mass value="1" />
            <inertia ixx="100" ixy="0" ixz="0" iyy="100" iyz="0" izz="100" />
        </inertial>
        <visual>
            <origin xyz="0.0 0.3496319137422935 0.0" rpy="0 0 0"/>
            <geometry>
                <box size="0.68419920658057 0.699263827484587 0.3998751195042449" />
            </geometry>
            <material name="Green">
                <color rgba="0 1.0 0 1.0"/>
            </material>
        </visual>
        <collision>
            <origin xyz="0.0 0.3496319137422935 0.0" rpy="0 0 0"/>
            <geometry>
                <box size="0.68419920658057 0.699263827484587 0.3998751195042449" />
            </geometry>
        </collision>
    </link>
    <joint name="Link1_Link2" type="revolute">
       <parent link="Link1"/>
       <child  link="Link2"/>
       <origin rpy="0 0 0" xyz="0.0 0.699263827484587 0.0" />
     <axis xyz="[1 0 1]"/>
       <limit effort="0.0" lower="-3.14159" upper="3.14159" velocity="0.0"/>
    </joint>
    <link name="Link2">
        <inertial>
            <origin xyz="0.0 0.3242037072277456 0.0" rpy="0 0 0"/>
            <mass value="1" />
            <inertia ixx="100" ixy="0" ixz="0" iyy="100" iyz="0" izz="100" />
        </inertial>
        <visual>
            <origin xyz="0.0 0.3242037072277456 0.0" rpy="0 0 0"/>
            <geometry>
                <box size="0.660334397052682 0.6484074144554912 0.2999730753992754" />
            </geometry>
            <material name="Green">
                <color rgba="0 1.0 0 1.0"/>
            </material>
        </visual>
        <collision>
            <origin xyz="0.0 0.3242037072277456 0.0" rpy="0 0 0"/>
            <geometry>
                <box size="0.660334397052682 0.6484074144554912 0.2999730753992754" />
            </geometry>
        </collision>
    </link>
    <joint name="Link2_Link2-0" type="revolute">
       <parent link="Link2"/>
       <child  link="Link2-0"/>
       <origin rpy="0 0 0" xyz="-0.330167198526341 0.3242037072277456 0.0" />
     <axis xyz="[2 1 1]"/>
       <limit effort="0.0" lower="-3.14159" upper="3.14159" velocity="0.0"/>
    </joint>
    <link name="Link2-0">
        <inertial>
            <origin xyz="-0.2584869096522861 0.0 0.0" rpy="0 0 0"/>
            <mass value="1" />
            <inertia ixx="100" ixy="0" ixz="0" iyy="100" iyz="0" izz="100" />
        </inertial>
        <visual>
            <origin xyz="-0.2584869096522861 0.0 0.0" rpy="0 0 0"/>
            <geometry>
                <box size="0.5169738193045722 0.5434723594199853 0.37285036986193965" />
            </geometry>
            <material name="Blue">
                <color rgba="0 0 1.0 1.0"/>
            </material>
        </visual>
        <collision>
            <origin xyz="-0.2584869096522861 0.0 0.0" rpy="0 0 0"/>
            <geometry>
                <box size="0.5169738193045722 0.5434723594199853 0.37285036986193965" />
            </geometry>
        </collision>
    </link>
</robot>