<robot name = "robot">
    <link name="Link0">
        <inertial>
            <origin xyz="0.0 0.0 2.097383060021071" rpy="0 0 0"/>
            <mass value="1" />
            <inertia ixx="100" ixy="0" ixz="0" iyy="100" iyz="0" izz="100" />
        </inertial>
        <visual>
            <origin xyz="0.0 0.0 2.097383060021071" rpy="0 0 0"/>
            <geometry>
                <box size="0.40362501248020133 0.828816364945967 0.19476612004214233" />
            </geometry>
            <material name="Green">
                <color rgba="0 1.0 0 1.0"/>
            </material>
        </visual>
        <collision>
            <origin xyz="0.0 0.0 2.097383060021071" rpy="0 0 0"/>
            <geometry>
                <box size="0.40362501248020133 0.828816364945967 0.19476612004214233" />
            </geometry>
        </collision>
    </link>
    <joint name="Link0_Link1" type="revolute">
       <parent link="Link0"/>
       <child  link="Link1"/>
       <origin rpy="0 0 0" xyz="0.0 0.4144081824729835 2.097383060021071" />
     <axis xyz="1 0 1"/>
       <limit effort="0.0" lower="-3.14159" upper="3.14159" velocity="0.0"/>
    </joint>
    <link name="Link1">
        <inertial>
            <origin xyz="0.0 0.45524174639123605 0.0" rpy="0 0 0"/>
            <mass value="1" />
            <inertia ixx="100" ixy="0" ixz="0" iyy="100" iyz="0" izz="100" />
        </inertial>
        <visual>
            <origin xyz="0.0 0.45524174639123605 0.0" rpy="0 0 0"/>
            <geometry>
                <box size="0.37603867756811227 0.9104834927824721 0.4833011841853987" />
            </geometry>
            <material name="Blue">
                <color rgba="0 0 1.0 1.0"/>
            </material>
        </visual>
        <collision>
            <origin xyz="0.0 0.45524174639123605 0.0" rpy="0 0 0"/>
            <geometry>
                <box size="0.37603867756811227 0.9104834927824721 0.4833011841853987" />
            </geometry>
        </collision>
    </link>
    <joint name="Link1_Link2" type="revolute">
       <parent link="Link1"/>
       <child  link="Link2"/>
       <origin rpy="0 0 0" xyz="0.0 0.9104834927824721 0.0" />
     <axis xyz="[1 0 1]"/>
       <limit effort="0.0" lower="-3.14159" upper="3.14159" velocity="0.0"/>
    </joint>
    <link name="Link2">
        <inertial>
            <origin xyz="0.0 0.4150600371952188 0.0" rpy="0 0 0"/>
            <mass value="1" />
            <inertia ixx="100" ixy="0" ixz="0" iyy="100" iyz="0" izz="100" />
        </inertial>
        <visual>
            <origin xyz="0.0 0.4150600371952188 0.0" rpy="0 0 0"/>
            <geometry>
                <box size="0.7644187740844893 0.8301200743904376 0.49828172160439416" />
            </geometry>
            <material name="Blue">
                <color rgba="0 0 1.0 1.0"/>
            </material>
        </visual>
        <collision>
            <origin xyz="0.0 0.4150600371952188 0.0" rpy="0 0 0"/>
            <geometry>
                <box size="0.7644187740844893 0.8301200743904376 0.49828172160439416" />
            </geometry>
        </collision>
    </link>
</robot>