<robot name = "robot">
    <link name="Link0">
        <inertial>
            <origin xyz="0.0 0.0 2.1278997255358987" rpy="0 0 0"/>
            <mass value="1" />
            <inertia ixx="100" ixy="0" ixz="0" iyy="100" iyz="0" izz="100" />
        </inertial>
        <visual>
            <origin xyz="0.0 0.0 2.1278997255358987" rpy="0 0 0"/>
            <geometry>
                <box size="0.408280818261337 0.9343137534575509 0.255799451071797" />
            </geometry>
            <material name="Green">
                <color rgba="0 1.0 0 1.0"/>
            </material>
        </visual>
        <collision>
            <origin xyz="0.0 0.0 2.1278997255358987" rpy="0 0 0"/>
            <geometry>
                <box size="0.408280818261337 0.9343137534575509 0.255799451071797" />
            </geometry>
        </collision>
    </link>
    <joint name="Link0_Link1" type="revolute">
       <parent link="Link0"/>
       <child  link="Link1"/>
       <origin rpy="0 0 0" xyz="0.0 0.4671568767287754 2.1278997255358987" />
     <axis xyz="1 0 1"/>
       <limit effort="0.0" lower="-3.14159" upper="3.14159" velocity="0.0"/>
    </joint>
    <link name="Link1">
        <inertial>
            <origin xyz="0.0 0.47092595292204553 0.0" rpy="0 0 0"/>
            <mass value="1" />
            <inertia ixx="100" ixy="0" ixz="0" iyy="100" iyz="0" izz="100" />
        </inertial>
        <visual>
            <origin xyz="0.0 0.47092595292204553 0.0" rpy="0 0 0"/>
            <geometry>
                <box size="0.6564285053100559 0.9418519058440911 0.4413512033424225" />
            </geometry>
            <material name="Green">
                <color rgba="0 1.0 0 1.0"/>
            </material>
        </visual>
        <collision>
            <origin xyz="0.0 0.47092595292204553 0.0" rpy="0 0 0"/>
            <geometry>
                <box size="0.6564285053100559 0.9418519058440911 0.4413512033424225" />
            </geometry>
        </collision>
    </link>
    <joint name="Link1_Link2" type="revolute">
       <parent link="Link1"/>
       <child  link="Link2"/>
       <origin rpy="0 0 0" xyz="0.0 0.9418519058440911 0.0" />
     <axis xyz="[1 0 1]"/>
       <limit effort="0.0" lower="-3.14159" upper="3.14159" velocity="0.0"/>
    </joint>
    <link name="Link2">
        <inertial>
            <origin xyz="0.0 0.38005264699661756 0.0" rpy="0 0 0"/>
            <mass value="1" />
            <inertia ixx="100" ixy="0" ixz="0" iyy="100" iyz="0" izz="100" />
        </inertial>
        <visual>
            <origin xyz="0.0 0.38005264699661756 0.0" rpy="0 0 0"/>
            <geometry>
                <box size="0.9026148695194194 0.7601052939932351 0.3591813924649287" />
            </geometry>
            <material name="Green">
                <color rgba="0 1.0 0 1.0"/>
            </material>
        </visual>
        <collision>
            <origin xyz="0.0 0.38005264699661756 0.0" rpy="0 0 0"/>
            <geometry>
                <box size="0.9026148695194194 0.7601052939932351 0.3591813924649287" />
            </geometry>
        </collision>
    </link>
    <joint name="Link2_Link2-0" type="revolute">
       <parent link="Link2"/>
       <child  link="Link2-0"/>
       <origin rpy="0 0 0" xyz="0.19360496522944454 0.38005264699661756 0.0" />
     <axis xyz="[0 1 1]"/>
       <limit effort="0.0" lower="-3.14159" upper="3.14159" velocity="0.0"/>
    </joint>
    <link name="Link2-0">
        <inertial>
            <origin xyz="0.10919685502171127 0.0 0.0" rpy="0 0 0"/>
            <mass value="1" />
            <inertia ixx="100" ixy="0" ixz="0" iyy="100" iyz="0" izz="100" />
        </inertial>
        <visual>
            <origin xyz="0.10919685502171127 0.0 0.0" rpy="0 0 0"/>
            <geometry>
                <box size="0.21839371004342253 0.9717900220024376 0.20349749558768132" />
            </geometry>
            <material name="Green">
                <color rgba="0 1.0 0 1.0"/>
            </material>
        </visual>
        <collision>
            <origin xyz="0.10919685502171127 0.0 0.0" rpy="0 0 0"/>
            <geometry>
                <box size="0.21839371004342253 0.9717900220024376 0.20349749558768132" />
            </geometry>
        </collision>
    </link>
</robot>