<robot name = "robot">
    <link name="Link0">
        <inertial>
            <origin xyz="0.0 0.0 2.195892199379406" rpy="0 0 0"/>
            <mass value="1" />
            <inertia ixx="100" ixy="0" ixz="0" iyy="100" iyz="0" izz="100" />
        </inertial>
        <visual>
            <origin xyz="0.0 0.0 2.195892199379406" rpy="0 0 0"/>
            <geometry>
                <box size="0.4696747567244963 0.5803351628343968 0.39178439875881216" />
            </geometry>
            <material name="Green">
                <color rgba="0 1.0 0 1.0"/>
            </material>
        </visual>
        <collision>
            <origin xyz="0.0 0.0 2.195892199379406" rpy="0 0 0"/>
            <geometry>
                <box size="0.4696747567244963 0.5803351628343968 0.39178439875881216" />
            </geometry>
        </collision>
    </link>
    <joint name="Link0_Link1" type="revolute">
       <parent link="Link0"/>
       <child  link="Link1"/>
       <origin rpy="0 0 0" xyz="0.0 0.2901675814171984 2.195892199379406" />
     <axis xyz="1 0 1"/>
       <limit effort="0.0" lower="-3.14159" upper="3.14159" velocity="0.0"/>
    </joint>
    <link name="Link1">
        <inertial>
            <origin xyz="0.0 0.3010599916626857 0.0" rpy="0 0 0"/>
            <mass value="1" />
            <inertia ixx="100" ixy="0" ixz="0" iyy="100" iyz="0" izz="100" />
        </inertial>
        <visual>
            <origin xyz="0.0 0.3010599916626857 0.0" rpy="0 0 0"/>
            <geometry>
                <box size="0.7016808998519573 0.6021199833253714 0.12813663672232284" />
            </geometry>
            <material name="Green">
                <color rgba="0 1.0 0 1.0"/>
            </material>
        </visual>
        <collision>
            <origin xyz="0.0 0.3010599916626857 0.0" rpy="0 0 0"/>
            <geometry>
                <box size="0.7016808998519573 0.6021199833253714 0.12813663672232284" />
            </geometry>
        </collision>
    </link>
    <joint name="Link1_Link2" type="revolute">
       <parent link="Link1"/>
       <child  link="Link2"/>
       <origin rpy="0 0 0" xyz="0.0 0.6021199833253714 0.0" />
     <axis xyz="[1 0 1]"/>
       <limit effort="0.0" lower="-3.14159" upper="3.14159" velocity="0.0"/>
    </joint>
    <link name="Link2">
        <inertial>
            <origin xyz="0.0 0.3729377741936933 0.0" rpy="0 0 0"/>
            <mass value="1" />
            <inertia ixx="100" ixy="0" ixz="0" iyy="100" iyz="0" izz="100" />
        </inertial>
        <visual>
            <origin xyz="0.0 0.3729377741936933 0.0" rpy="0 0 0"/>
            <geometry>
                <box size="0.6760261594815088 0.7458755483873866 0.47090756032040015" />
            </geometry>
            <material name="Blue">
                <color rgba="0 0 1.0 1.0"/>
            </material>
        </visual>
        <collision>
            <origin xyz="0.0 0.3729377741936933 0.0" rpy="0 0 0"/>
            <geometry>
                <box size="0.6760261594815088 0.7458755483873866 0.47090756032040015" />
            </geometry>
        </collision>
    </link>
</robot>