<robot name = "robot">
    <link name="Link0">
        <inertial>
            <origin xyz="0.0 0.0 2.1870571894860085" rpy="0 0 0"/>
            <mass value="1" />
            <inertia ixx="100" ixy="0" ixz="0" iyy="100" iyz="0" izz="100" />
        </inertial>
        <visual>
            <origin xyz="0.0 0.0 2.1870571894860085" rpy="0 0 0"/>
            <geometry>
                <box size="0.5986267214865443 0.8327380895473213 0.3741143789720174" />
            </geometry>
            <material name="Green">
                <color rgba="0 1.0 0 1.0"/>
            </material>
        </visual>
        <collision>
            <origin xyz="0.0 0.0 2.1870571894860085" rpy="0 0 0"/>
            <geometry>
                <box size="0.5986267214865443 0.8327380895473213 0.3741143789720174" />
            </geometry>
        </collision>
    </link>
    <joint name="Link0_Link1" type="revolute">
       <parent link="Link0"/>
       <child  link="Link1"/>
       <origin rpy="0 0 0" xyz="0.0 0.41636904477366066 2.1870571894860085" />
     <axis xyz="1 0 1"/>
       <limit effort="0.0" lower="-3.14159" upper="3.14159" velocity="0.0"/>
    </joint>
    <link name="Link1">
        <inertial>
            <origin xyz="0.0 0.14459816335197212 0.0" rpy="0 0 0"/>
            <mass value="1" />
            <inertia ixx="100" ixy="0" ixz="0" iyy="100" iyz="0" izz="100" />
        </inertial>
        <visual>
            <origin xyz="0.0 0.14459816335197212 0.0" rpy="0 0 0"/>
            <geometry>
                <box size="0.526075097659351 0.28919632670394424 0.30412172088851774" />
            </geometry>
            <material name="Green">
                <color rgba="0 1.0 0 1.0"/>
            </material>
        </visual>
        <collision>
            <origin xyz="0.0 0.14459816335197212 0.0" rpy="0 0 0"/>
            <geometry>
                <box size="0.526075097659351 0.28919632670394424 0.30412172088851774" />
            </geometry>
        </collision>
    </link>
    <joint name="Link1_Link2" type="revolute">
       <parent link="Link1"/>
       <child  link="Link2"/>
       <origin rpy="0 0 0" xyz="0.0 0.28919632670394424 0.0" />
     <axis xyz="[1 0 1]"/>
       <limit effort="0.0" lower="-3.14159" upper="3.14159" velocity="0.0"/>
    </joint>
    <link name="Link2">
        <inertial>
            <origin xyz="0.0 0.45508677482986576 0.0" rpy="0 0 0"/>
            <mass value="1" />
            <inertia ixx="100" ixy="0" ixz="0" iyy="100" iyz="0" izz="100" />
        </inertial>
        <visual>
            <origin xyz="0.0 0.45508677482986576 0.0" rpy="0 0 0"/>
            <geometry>
                <box size="0.5219609598719475 0.9101735496597315 0.3890030915659998" />
            </geometry>
            <material name="Green">
                <color rgba="0 1.0 0 1.0"/>
            </material>
        </visual>
        <collision>
            <origin xyz="0.0 0.45508677482986576 0.0" rpy="0 0 0"/>
            <geometry>
                <box size="0.5219609598719475 0.9101735496597315 0.3890030915659998" />
            </geometry>
        </collision>
    </link>
    <joint name="Link2_Link2-0" type="revolute">
       <parent link="Link2"/>
       <child  link="Link2-0"/>
       <origin rpy="0 0 0" xyz="0.0 0.45508677482986576 0.1945015457829999" />
     <axis xyz="[1 1 0]"/>
       <limit effort="0.0" lower="-3.14159" upper="3.14159" velocity="0.0"/>
    </joint>
    <link name="Link2-0">
        <inertial>
            <origin xyz="0.0 0.0 0.0760138938554881" rpy="0 0 0"/>
            <mass value="1" />
            <inertia ixx="100" ixy="0" ixz="0" iyy="100" iyz="0" izz="100" />
        </inertial>
        <visual>
            <origin xyz="0.0 0.0 0.0760138938554881" rpy="0 0 0"/>
            <geometry>
                <box size="0.7412127437825118 0.6236207650888925 0.1520277877109762" />
            </geometry>
            <material name="Green">
                <color rgba="0 1.0 0 1.0"/>
            </material>
        </visual>
        <collision>
            <origin xyz="0.0 0.0 0.0760138938554881" rpy="0 0 0"/>
            <geometry>
                <box size="0.7412127437825118 0.6236207650888925 0.1520277877109762" />
            </geometry>
        </collision>
    </link>
    <joint name="Link2-0_Link2-0-0" type="revolute">
       <parent link="Link2-0"/>
       <child  link="Link2-0-0"/>
       <origin rpy="0 0 0" xyz="0.3706063718912559 0.0 0.0760138938554881" />
     <axis xyz="[0 1 1]"/>
       <limit effort="0.0" lower="-3.14159" upper="3.14159" velocity="0.0"/>
    </joint>
    <link name="Link2-0-0">
        <inertial>
            <origin xyz="0.1416116995594476 0.0 0.0" rpy="0 0 0"/>
            <mass value="1" />
            <inertia ixx="100" ixy="0" ixz="0" iyy="100" iyz="0" izz="100" />
        </inertial>
        <visual>
            <origin xyz="0.1416116995594476 0.0 0.0" rpy="0 0 0"/>
            <geometry>
                <box size="0.2832233991188952 0.3260680483948204 0.3963030631239747" />
            </geometry>
            <material name="Green">
                <color rgba="0 1.0 0 1.0"/>
            </material>
        </visual>
        <collision>
            <origin xyz="0.1416116995594476 0.0 0.0" rpy="0 0 0"/>
            <geometry>
                <box size="0.2832233991188952 0.3260680483948204 0.3963030631239747" />
            </geometry>
        </collision>
    </link>
</robot>