<robot name = "robot">
    <link name="Link0">
        <inertial>
            <origin xyz="0.0 0.0 2.1538560476236506" rpy="0 0 0"/>
            <mass value="1" />
            <inertia ixx="100" ixy="0" ixz="0" iyy="100" iyz="0" izz="100" />
        </inertial>
        <visual>
            <origin xyz="0.0 0.0 2.1538560476236506" rpy="0 0 0"/>
            <geometry>
                <box size="0.20253652339391587 0.9876788396651648 0.30771209524730114" />
            </geometry>
            <material name="Green">
                <color rgba="0 1.0 0 1.0"/>
            </material>
        </visual>
        <collision>
            <origin xyz="0.0 0.0 2.1538560476236506" rpy="0 0 0"/>
            <geometry>
                <box size="0.20253652339391587 0.9876788396651648 0.30771209524730114" />
            </geometry>
        </collision>
    </link>
    <joint name="Link0_Link1" type="revolute">
       <parent link="Link0"/>
       <child  link="Link1"/>
       <origin rpy="0 0 0" xyz="0.0 0.4938394198325824 2.1538560476236506" />
     <axis xyz="1 0 1"/>
       <limit effort="0.0" lower="-3.14159" upper="3.14159" velocity="0.0"/>
    </joint>
    <link name="Link1">
        <inertial>
            <origin xyz="0.0 0.39512045405321145 0.0" rpy="0 0 0"/>
            <mass value="1" />
            <inertia ixx="100" ixy="0" ixz="0" iyy="100" iyz="0" izz="100" />
        </inertial>
        <visual>
            <origin xyz="0.0 0.39512045405321145 0.0" rpy="0 0 0"/>
            <geometry>
                <box size="0.7489840719692697 0.7902409081064229 0.3058720954397077" />
            </geometry>
            <material name="Green">
                <color rgba="0 1.0 0 1.0"/>
            </material>
        </visual>
        <collision>
            <origin xyz="0.0 0.39512045405321145 0.0" rpy="0 0 0"/>
            <geometry>
                <box size="0.7489840719692697 0.7902409081064229 0.3058720954397077" />
            </geometry>
        </collision>
    </link>
    <joint name="Link1_Link2" type="revolute">
       <parent link="Link1"/>
       <child  link="Link2"/>
       <origin rpy="0 0 0" xyz="0.0 0.7902409081064229 0.0" />
     <axis xyz="[1 0 1]"/>
       <limit effort="0.0" lower="-3.14159" upper="3.14159" velocity="0.0"/>
    </joint>
    <link name="Link2">
        <inertial>
            <origin xyz="0.0 0.24576168842305612 0.0" rpy="0 0 0"/>
            <mass value="1" />
            <inertia ixx="100" ixy="0" ixz="0" iyy="100" iyz="0" izz="100" />
        </inertial>
        <visual>
            <origin xyz="0.0 0.24576168842305612 0.0" rpy="0 0 0"/>
            <geometry>
                <box size="0.6079981241553045 0.49152337684611225 0.2642421761027821" />
            </geometry>
            <material name="Blue">
                <color rgba="0 0 1.0 1.0"/>
            </material>
        </visual>
        <collision>
            <origin xyz="0.0 0.24576168842305612 0.0" rpy="0 0 0"/>
            <geometry>
                <box size="0.6079981241553045 0.49152337684611225 0.2642421761027821" />
            </geometry>
        </collision>
    </link>
    <joint name="Link2_Link3" type="revolute">
       <parent link="Link2"/>
       <child  link="Link3"/>
       <origin rpy="0 0 0" xyz="0.0 0.49152337684611225 0.0" />
     <axis xyz="[1 0 1]"/>
       <limit effort="0.0" lower="-3.14159" upper="3.14159" velocity="0.0"/>
    </joint>
    <link name="Link3">
        <inertial>
            <origin xyz="0.0 0.47291810031623266 0.0" rpy="0 0 0"/>
            <mass value="1" />
            <inertia ixx="100" ixy="0" ixz="0" iyy="100" iyz="0" izz="100" />
        </inertial>
        <visual>
            <origin xyz="0.0 0.47291810031623266 0.0" rpy="0 0 0"/>
            <geometry>
                <box size="0.5014887542019077 0.9458362006324653 0.49185359879850854" />
            </geometry>
            <material name="Blue">
                <color rgba="0 0 1.0 1.0"/>
            </material>
        </visual>
        <collision>
            <origin xyz="0.0 0.47291810031623266 0.0" rpy="0 0 0"/>
            <geometry>
                <box size="0.5014887542019077 0.9458362006324653 0.49185359879850854" />
            </geometry>
        </collision>
    </link>
</robot>