<robot name = "robot">
    <link name="Link0">
        <inertial>
            <origin xyz="0.0 0.0 2.1384314319412008" rpy="0 0 0"/>
            <mass value="1" />
            <inertia ixx="100" ixy="0" ixz="0" iyy="100" iyz="0" izz="100" />
        </inertial>
        <visual>
            <origin xyz="0.0 0.0 2.1384314319412008" rpy="0 0 0"/>
            <geometry>
                <box size="0.34358337637602754 0.6779147913991733 0.2768628638824016" />
            </geometry>
            <material name="Green">
                <color rgba="0 1.0 0 1.0"/>
            </material>
        </visual>
        <collision>
            <origin xyz="0.0 0.0 2.1384314319412008" rpy="0 0 0"/>
            <geometry>
                <box size="0.34358337637602754 0.6779147913991733 0.2768628638824016" />
            </geometry>
        </collision>
    </link>
    <joint name="Link0_Link1" type="revolute">
       <parent link="Link0"/>
       <child  link="Link1"/>
       <origin rpy="0 0 0" xyz="0.0 0.33895739569958666 2.1384314319412008" />
     <axis xyz="1 0 1"/>
       <limit effort="0.0" lower="-3.14159" upper="3.14159" velocity="0.0"/>
    </joint>
    <link name="Link1">
        <inertial>
            <origin xyz="0.0 0.40432606760097867 0.0" rpy="0 0 0"/>
            <mass value="1" />
            <inertia ixx="100" ixy="0" ixz="0" iyy="100" iyz="0" izz="100" />
        </inertial>
        <visual>
            <origin xyz="0.0 0.40432606760097867 0.0" rpy="0 0 0"/>
            <geometry>
                <box size="0.6709435216319981 0.8086521352019573 0.13605612960577002" />
            </geometry>
            <material name="Blue">
                <color rgba="0 0 1.0 1.0"/>
            </material>
        </visual>
        <collision>
            <origin xyz="0.0 0.40432606760097867 0.0" rpy="0 0 0"/>
            <geometry>
                <box size="0.6709435216319981 0.8086521352019573 0.13605612960577002" />
            </geometry>
        </collision>
    </link>
    <joint name="Link1_Link2" type="revolute">
       <parent link="Link1"/>
       <child  link="Link2"/>
       <origin rpy="0 0 0" xyz="0.0 0.8086521352019573 0.0" />
     <axis xyz="[1 0 1]"/>
       <limit effort="0.0" lower="-3.14159" upper="3.14159" velocity="0.0"/>
    </joint>
    <link name="Link2">
        <inertial>
            <origin xyz="0.0 0.3496359250789727 0.0" rpy="0 0 0"/>
            <mass value="1" />
            <inertia ixx="100" ixy="0" ixz="0" iyy="100" iyz="0" izz="100" />
        </inertial>
        <visual>
            <origin xyz="0.0 0.3496359250789727 0.0" rpy="0 0 0"/>
            <geometry>
                <box size="0.3721552874904732 0.6992718501579454 0.38762500674647454" />
            </geometry>
            <material name="Blue">
                <color rgba="0 0 1.0 1.0"/>
            </material>
        </visual>
        <collision>
            <origin xyz="0.0 0.3496359250789727 0.0" rpy="0 0 0"/>
            <geometry>
                <box size="0.3721552874904732 0.6992718501579454 0.38762500674647454" />
            </geometry>
        </collision>
    </link>
</robot>