<robot name = "robot">
    <link name="Link0">
        <inertial>
            <origin xyz="0.0 0.0 2.1280501085865016" rpy="0 0 0"/>
            <mass value="1" />
            <inertia ixx="100" ixy="0" ixz="0" iyy="100" iyz="0" izz="100" />
        </inertial>
        <visual>
            <origin xyz="0.0 0.0 2.1280501085865016" rpy="0 0 0"/>
            <geometry>
                <box size="0.2492006713359162 0.9098103207539706 0.25610021717300346" />
            </geometry>
            <material name="Green">
                <color rgba="0 1.0 0 1.0"/>
            </material>
        </visual>
        <collision>
            <origin xyz="0.0 0.0 2.1280501085865016" rpy="0 0 0"/>
            <geometry>
                <box size="0.2492006713359162 0.9098103207539706 0.25610021717300346" />
            </geometry>
        </collision>
    </link>
    <joint name="Link0_Link1" type="revolute">
       <parent link="Link0"/>
       <child  link="Link1"/>
       <origin rpy="0 0 0" xyz="0.0 0.4549051603769853 2.1280501085865016" />
     <axis xyz="1 0 1"/>
       <limit effort="0.0" lower="-3.14159" upper="3.14159" velocity="0.0"/>
    </joint>
    <link name="Link1">
        <inertial>
            <origin xyz="0.0 0.40735910711704976 0.0" rpy="0 0 0"/>
            <mass value="1" />
            <inertia ixx="100" ixy="0" ixz="0" iyy="100" iyz="0" izz="100" />
        </inertial>
        <visual>
            <origin xyz="0.0 0.40735910711704976 0.0" rpy="0 0 0"/>
            <geometry>
                <box size="0.2788626471002851 0.8147182142340995 0.17974907317248268" />
            </geometry>
            <material name="Blue">
                <color rgba="0 0 1.0 1.0"/>
            </material>
        </visual>
        <collision>
            <origin xyz="0.0 0.40735910711704976 0.0" rpy="0 0 0"/>
            <geometry>
                <box size="0.2788626471002851 0.8147182142340995 0.17974907317248268" />
            </geometry>
        </collision>
    </link>
    <joint name="Link1_Link2" type="revolute">
       <parent link="Link1"/>
       <child  link="Link2"/>
       <origin rpy="0 0 0" xyz="0.0 0.8147182142340995 0.0" />
     <axis xyz="[1 0 1]"/>
       <limit effort="0.0" lower="-3.14159" upper="3.14159" velocity="0.0"/>
    </joint>
    <link name="Link2">
        <inertial>
            <origin xyz="0.0 0.4576654726361602 0.0" rpy="0 0 0"/>
            <mass value="1" />
            <inertia ixx="100" ixy="0" ixz="0" iyy="100" iyz="0" izz="100" />
        </inertial>
        <visual>
            <origin xyz="0.0 0.4576654726361602 0.0" rpy="0 0 0"/>
            <geometry>
                <box size="0.5574413646867787 0.9153309452723204 0.30468462677311714" />
            </geometry>
            <material name="Green">
                <color rgba="0 1.0 0 1.0"/>
            </material>
        </visual>
        <collision>
            <origin xyz="0.0 0.4576654726361602 0.0" rpy="0 0 0"/>
            <geometry>
                <box size="0.5574413646867787 0.9153309452723204 0.30468462677311714" />
            </geometry>
        </collision>
    </link>
</robot>