<robot name = "robot">
    <link name="Link0">
        <inertial>
            <origin xyz="0.0 0.0 2.167524504062173" rpy="0 0 0"/>
            <mass value="1" />
            <inertia ixx="100" ixy="0" ixz="0" iyy="100" iyz="0" izz="100" />
        </inertial>
        <visual>
            <origin xyz="0.0 0.0 2.167524504062173" rpy="0 0 0"/>
            <geometry>
                <box size="0.5613742833766574 0.6874231174560351 0.3350490081243459" />
            </geometry>
            <material name="Green">
                <color rgba="0 1.0 0 1.0"/>
            </material>
        </visual>
        <collision>
            <origin xyz="0.0 0.0 2.167524504062173" rpy="0 0 0"/>
            <geometry>
                <box size="0.5613742833766574 0.6874231174560351 0.3350490081243459" />
            </geometry>
        </collision>
    </link>
    <joint name="Link0_Link1" type="revolute">
       <parent link="Link0"/>
       <child  link="Link1"/>
       <origin rpy="0 0 0" xyz="0.0 0.34371155872801756 2.167524504062173" />
     <axis xyz="1 0 1"/>
       <limit effort="0.0" lower="-3.14159" upper="3.14159" velocity="0.0"/>
    </joint>
    <link name="Link1">
        <inertial>
            <origin xyz="0.0 0.41119245476884436 0.0" rpy="0 0 0"/>
            <mass value="1" />
            <inertia ixx="100" ixy="0" ixz="0" iyy="100" iyz="0" izz="100" />
        </inertial>
        <visual>
            <origin xyz="0.0 0.41119245476884436 0.0" rpy="0 0 0"/>
            <geometry>
                <box size="0.5867850357567116 0.8223849095376887 0.3810762931927206" />
            </geometry>
            <material name="Blue">
                <color rgba="0 0 1.0 1.0"/>
            </material>
        </visual>
        <collision>
            <origin xyz="0.0 0.41119245476884436 0.0" rpy="0 0 0"/>
            <geometry>
                <box size="0.5867850357567116 0.8223849095376887 0.3810762931927206" />
            </geometry>
        </collision>
    </link>
    <joint name="Link1_Link2" type="revolute">
       <parent link="Link1"/>
       <child  link="Link2"/>
       <origin rpy="0 0 0" xyz="0.0 0.8223849095376887 0.0" />
     <axis xyz="[1 0 1]"/>
       <limit effort="0.0" lower="-3.14159" upper="3.14159" velocity="0.0"/>
    </joint>
    <link name="Link2">
        <inertial>
            <origin xyz="0.0 0.22353898299101596 0.0" rpy="0 0 0"/>
            <mass value="1" />
            <inertia ixx="100" ixy="0" ixz="0" iyy="100" iyz="0" izz="100" />
        </inertial>
        <visual>
            <origin xyz="0.0 0.22353898299101596 0.0" rpy="0 0 0"/>
            <geometry>
                <box size="0.3697161406798783 0.4470779659820319 0.9212707159033432" />
            </geometry>
            <material name="Blue">
                <color rgba="0 0 1.0 1.0"/>
            </material>
        </visual>
        <collision>
            <origin xyz="0.0 0.22353898299101596 0.0" rpy="0 0 0"/>
            <geometry>
                <box size="0.3697161406798783 0.4470779659820319 0.9212707159033432" />
            </geometry>
        </collision>
    </link>
    <joint name="Link2_Link2-0" type="revolute">
       <parent link="Link2"/>
       <child  link="Link2-0"/>
       <origin rpy="0 0 0" xyz="-0.18485807033993915 0.22353898299101596 0.0" />
     <axis xyz="[2 1 1]"/>
       <limit effort="0.0" lower="-3.14159" upper="3.14159" velocity="0.0"/>
    </joint>
    <link name="Link2-0">
        <inertial>
            <origin xyz="-0.3275749379580333 0.0 0.0" rpy="0 0 0"/>
            <mass value="1" />
            <inertia ixx="100" ixy="0" ixz="0" iyy="100" iyz="0" izz="100" />
        </inertial>
        <visual>
            <origin xyz="-0.3275749379580333 0.0 0.0" rpy="0 0 0"/>
            <geometry>
                <box size="0.6551498759160665 0.5735349608574632 0.30399665737292414" />
            </geometry>
            <material name="Green">
                <color rgba="0 1.0 0 1.0"/>
            </material>
        </visual>
        <collision>
            <origin xyz="-0.3275749379580333 0.0 0.0" rpy="0 0 0"/>
            <geometry>
                <box size="0.6551498759160665 0.5735349608574632 0.30399665737292414" />
            </geometry>
        </collision>
    </link>
    <joint name="Link2-0_Link2-0-0" type="revolute">
       <parent link="Link2-0"/>
       <child  link="Link2-0-0"/>
       <origin rpy="0 0 0" xyz="-0.3275749379580333 0.3632389762645836 0.0" />
     <axis xyz="[1 0 1]"/>
       <limit effort="0.0" lower="-3.14159" upper="3.14159" velocity="0.0"/>
    </joint>
    <link name="Link2-0-0">
        <inertial>
            <origin xyz="0.0 0.15064604738508336 0.0" rpy="0 0 0"/>
            <mass value="1" />
            <inertia ixx="100" ixy="0" ixz="0" iyy="100" iyz="0" izz="100" />
        </inertial>
        <visual>
            <origin xyz="0.0 0.15064604738508336 0.0" rpy="0 0 0"/>
            <geometry>
                <box size="0.3894933327971139 0.3012920947701667 0.2346077826251978" />
            </geometry>
            <material name="Blue">
                <color rgba="0 0 1.0 1.0"/>
            </material>
        </visual>
        <collision>
            <origin xyz="0.0 0.15064604738508336 0.0" rpy="0 0 0"/>
            <geometry>
                <box size="0.3894933327971139 0.3012920947701667 0.2346077826251978" />
            </geometry>
        </collision>
    </link>
    <joint name="Link2-0-0_Link2-0-0-0" type="revolute">
       <parent link="Link2-0-0"/>
       <child  link="Link2-0-0-0"/>
       <origin rpy="0 0 0" xyz="0.0 0.15064604738508336 -0.1173038913125989" />
     <axis xyz="[1 1 2]"/>
       <limit effort="0.0" lower="-3.14159" upper="3.14159" velocity="0.0"/>
    </joint>
    <link name="Link2-0-0-0">
        <inertial>
            <origin xyz="0.0 0.0 -0.14632001093357" rpy="0 0 0"/>
            <mass value="1" />
            <inertia ixx="100" ixy="0" ixz="0" iyy="100" iyz="0" izz="100" />
        </inertial>
        <visual>
            <origin xyz="0.0 0.0 -0.14632001093357" rpy="0 0 0"/>
            <geometry>
                <box size="0.43874792586667355 0.5519764577779612 0.29264002186714" />
            </geometry>
            <material name="Green">
                <color rgba="0 1.0 0 1.0"/>
            </material>
        </visual>
        <collision>
            <origin xyz="0.0 0.0 -0.14632001093357" rpy="0 0 0"/>
            <geometry>
                <box size="0.43874792586667355 0.5519764577779612 0.29264002186714" />
            </geometry>
        </collision>
    </link>
</robot>