<robot name = "robot">
    <link name="Link0">
        <inertial>
            <origin xyz="0.0 0.0 2.2439555133819353" rpy="0 0 0"/>
            <mass value="1" />
            <inertia ixx="100" ixy="0" ixz="0" iyy="100" iyz="0" izz="100" />
        </inertial>
        <visual>
            <origin xyz="0.0 0.0 2.2439555133819353" rpy="0 0 0"/>
            <geometry>
                <box size="0.34511929309129163 0.7952821760843456 0.4879110267638707" />
            </geometry>
            <material name="Green">
                <color rgba="0 1.0 0 1.0"/>
            </material>
        </visual>
        <collision>
            <origin xyz="0.0 0.0 2.2439555133819353" rpy="0 0 0"/>
            <geometry>
                <box size="0.34511929309129163 0.7952821760843456 0.4879110267638707" />
            </geometry>
        </collision>
    </link>
    <joint name="Link0_Link1" type="revolute">
       <parent link="Link0"/>
       <child  link="Link1"/>
       <origin rpy="0 0 0" xyz="0.0 0.3976410880421728 2.2439555133819353" />
     <axis xyz="1 0 1"/>
       <limit effort="0.0" lower="-3.14159" upper="3.14159" velocity="0.0"/>
    </joint>
    <link name="Link1">
        <inertial>
            <origin xyz="0.0 0.18512323516539497 0.0" rpy="0 0 0"/>
            <mass value="1" />
            <inertia ixx="100" ixy="0" ixz="0" iyy="100" iyz="0" izz="100" />
        </inertial>
        <visual>
            <origin xyz="0.0 0.18512323516539497 0.0" rpy="0 0 0"/>
            <geometry>
                <box size="0.7341829689536588 0.37024647033078995 0.13609844878442268" />
            </geometry>
            <material name="Blue">
                <color rgba="0 0 1.0 1.0"/>
            </material>
        </visual>
        <collision>
            <origin xyz="0.0 0.18512323516539497 0.0" rpy="0 0 0"/>
            <geometry>
                <box size="0.7341829689536588 0.37024647033078995 0.13609844878442268" />
            </geometry>
        </collision>
    </link>
    <joint name="Link1_Link2" type="revolute">
       <parent link="Link1"/>
       <child  link="Link2"/>
       <origin rpy="0 0 0" xyz="0.0 0.37024647033078995 0.0" />
     <axis xyz="[1 0 1]"/>
       <limit effort="0.0" lower="-3.14159" upper="3.14159" velocity="0.0"/>
    </joint>
    <link name="Link2">
        <inertial>
            <origin xyz="0.0 0.4888065434073037 0.0" rpy="0 0 0"/>
            <mass value="1" />
            <inertia ixx="100" ixy="0" ixz="0" iyy="100" iyz="0" izz="100" />
        </inertial>
        <visual>
            <origin xyz="0.0 0.4888065434073037 0.0" rpy="0 0 0"/>
            <geometry>
                <box size="0.5576856032997787 0.9776130868146073 0.4041619599278945" />
            </geometry>
            <material name="Green">
                <color rgba="0 1.0 0 1.0"/>
            </material>
        </visual>
        <collision>
            <origin xyz="0.0 0.4888065434073037 0.0" rpy="0 0 0"/>
            <geometry>
                <box size="0.5576856032997787 0.9776130868146073 0.4041619599278945" />
            </geometry>
        </collision>
    </link>
    <joint name="Link1_Link1-0" type="revolute">
       <parent link="Link1"/>
       <child  link="Link1-0"/>
       <origin rpy="0 0 0" xyz="-0.3670914844768294 0.18512323516539497 0.0" />
     <axis xyz="[2 1 1]"/>
       <limit effort="0.0" lower="-3.14159" upper="3.14159" velocity="0.0"/>
    </joint>
    <link name="Link1-0">
        <inertial>
            <origin xyz="-0.21622696825148077 0.0 0.0" rpy="0 0 0"/>
            <mass value="1" />
            <inertia ixx="100" ixy="0" ixz="0" iyy="100" iyz="0" izz="100" />
        </inertial>
        <visual>
            <origin xyz="-0.21622696825148077 0.0 0.0" rpy="0 0 0"/>
            <geometry>
                <box size="0.43245393650296154 0.797656014034416 0.4590767745189279" />
            </geometry>
            <material name="Blue">
                <color rgba="0 0 1.0 1.0"/>
            </material>
        </visual>
        <collision>
            <origin xyz="-0.21622696825148077 0.0 0.0" rpy="0 0 0"/>
            <geometry>
                <box size="0.43245393650296154 0.797656014034416 0.4590767745189279" />
            </geometry>
        </collision>
    </link>
</robot>