<robot name = "robot">
    <link name="Link0">
        <inertial>
            <origin xyz="0.0 0.0 2.170729427154829" rpy="0 0 0"/>
            <mass value="1" />
            <inertia ixx="100" ixy="0" ixz="0" iyy="100" iyz="0" izz="100" />
        </inertial>
        <visual>
            <origin xyz="0.0 0.0 2.170729427154829" rpy="0 0 0"/>
            <geometry>
                <box size="0.30745488882510613 0.35698309440953757 0.3414588543096577" />
            </geometry>
            <material name="Green">
                <color rgba="0 1.0 0 1.0"/>
            </material>
        </visual>
        <collision>
            <origin xyz="0.0 0.0 2.170729427154829" rpy="0 0 0"/>
            <geometry>
                <box size="0.30745488882510613 0.35698309440953757 0.3414588543096577" />
            </geometry>
        </collision>
    </link>
    <joint name="Link0_Link1" type="revolute">
       <parent link="Link0"/>
       <child  link="Link1"/>
       <origin rpy="0 0 0" xyz="0.0 0.17849154720476879 2.170729427154829" />
     <axis xyz="1 0 1"/>
       <limit effort="0.0" lower="-3.14159" upper="3.14159" velocity="0.0"/>
    </joint>
    <link name="Link1">
        <inertial>
            <origin xyz="0.0 0.48991479616534156 0.0" rpy="0 0 0"/>
            <mass value="1" />
            <inertia ixx="100" ixy="0" ixz="0" iyy="100" iyz="0" izz="100" />
        </inertial>
        <visual>
            <origin xyz="0.0 0.48991479616534156 0.0" rpy="0 0 0"/>
            <geometry>
                <box size="0.3475560619273044 0.9798295923306831 0.19839335595632407" />
            </geometry>
            <material name="Green">
                <color rgba="0 1.0 0 1.0"/>
            </material>
        </visual>
        <collision>
            <origin xyz="0.0 0.48991479616534156 0.0" rpy="0 0 0"/>
            <geometry>
                <box size="0.3475560619273044 0.9798295923306831 0.19839335595632407" />
            </geometry>
        </collision>
    </link>
    <joint name="Link1_Link2" type="revolute">
       <parent link="Link1"/>
       <child  link="Link2"/>
       <origin rpy="0 0 0" xyz="0.0 0.9798295923306831 0.0" />
     <axis xyz="[1 0 1]"/>
       <limit effort="0.0" lower="-3.14159" upper="3.14159" velocity="0.0"/>
    </joint>
    <link name="Link2">
        <inertial>
            <origin xyz="0.0 0.15540459490494327 0.0" rpy="0 0 0"/>
            <mass value="1" />
            <inertia ixx="100" ixy="0" ixz="0" iyy="100" iyz="0" izz="100" />
        </inertial>
        <visual>
            <origin xyz="0.0 0.15540459490494327 0.0" rpy="0 0 0"/>
            <geometry>
                <box size="0.501847238324838 0.31080918980988653 0.5145056637810468" />
            </geometry>
            <material name="Blue">
                <color rgba="0 0 1.0 1.0"/>
            </material>
        </visual>
        <collision>
            <origin xyz="0.0 0.15540459490494327 0.0" rpy="0 0 0"/>
            <geometry>
                <box size="0.501847238324838 0.31080918980988653 0.5145056637810468" />
            </geometry>
        </collision>
    </link>
    <joint name="Link2_Link2-0" type="revolute">
       <parent link="Link2"/>
       <child  link="Link2-0"/>
       <origin rpy="0 0 0" xyz="0.22383384173296023 0.15540459490494327 0.0" />
     <axis xyz="[0 1 1]"/>
       <limit effort="0.0" lower="-3.14159" upper="3.14159" velocity="0.0"/>
    </joint>
    <link name="Link2-0">
        <inertial>
            <origin xyz="0.3276861847160466 0.0 0.0" rpy="0 0 0"/>
            <mass value="1" />
            <inertia ixx="100" ixy="0" ixz="0" iyy="100" iyz="0" izz="100" />
        </inertial>
        <visual>
            <origin xyz="0.3276861847160466 0.0 0.0" rpy="0 0 0"/>
            <geometry>
                <box size="0.6553723694320932 0.9040730549561151 0.802369177019866" />
            </geometry>
            <material name="Blue">
                <color rgba="0 0 1.0 1.0"/>
            </material>
        </visual>
        <collision>
            <origin xyz="0.3276861847160466 0.0 0.0" rpy="0 0 0"/>
            <geometry>
                <box size="0.6553723694320932 0.9040730549561151 0.802369177019866" />
            </geometry>
        </collision>
    </link>
</robot>