<robot name = "robot">
    <link name="Link0">
        <inertial>
            <origin xyz="0.0 0.0 2.0917422705145547" rpy="0 0 0"/>
            <mass value="1" />
            <inertia ixx="100" ixy="0" ixz="0" iyy="100" iyz="0" izz="100" />
        </inertial>
        <visual>
            <origin xyz="0.0 0.0 2.0917422705145547" rpy="0 0 0"/>
            <geometry>
                <box size="0.7947200266821253 0.37089285294201346 0.18348454102910938" />
            </geometry>
            <material name="Green">
                <color rgba="0 1.0 0 1.0"/>
            </material>
        </visual>
        <collision>
            <origin xyz="0.0 0.0 2.0917422705145547" rpy="0 0 0"/>
            <geometry>
                <box size="0.7947200266821253 0.37089285294201346 0.18348454102910938" />
            </geometry>
        </collision>
    </link>
    <joint name="Link0_Link1" type="revolute">
       <parent link="Link0"/>
       <child  link="Link1"/>
       <origin rpy="0 0 0" xyz="0.0 0.18544642647100673 2.0917422705145547" />
     <axis xyz="1 0 1"/>
       <limit effort="0.0" lower="-3.14159" upper="3.14159" velocity="0.0"/>
    </joint>
    <link name="Link1">
        <inertial>
            <origin xyz="0.0 0.20743818379280263 0.0" rpy="0 0 0"/>
            <mass value="1" />
            <inertia ixx="100" ixy="0" ixz="0" iyy="100" iyz="0" izz="100" />
        </inertial>
        <visual>
            <origin xyz="0.0 0.20743818379280263 0.0" rpy="0 0 0"/>
            <geometry>
                <box size="0.3241576114664158 0.41487636758560525 0.3845338951652007" />
            </geometry>
            <material name="Blue">
                <color rgba="0 0 1.0 1.0"/>
            </material>
        </visual>
        <collision>
            <origin xyz="0.0 0.20743818379280263 0.0" rpy="0 0 0"/>
            <geometry>
                <box size="0.3241576114664158 0.41487636758560525 0.3845338951652007" />
            </geometry>
        </collision>
    </link>
    <joint name="Link1_Link2" type="revolute">
       <parent link="Link1"/>
       <child  link="Link2"/>
       <origin rpy="0 0 0" xyz="0.0 0.41487636758560525 0.0" />
     <axis xyz="[1 0 1]"/>
       <limit effort="0.0" lower="-3.14159" upper="3.14159" velocity="0.0"/>
    </joint>
    <link name="Link2">
        <inertial>
            <origin xyz="0.0 0.1305571067240593 0.0" rpy="0 0 0"/>
            <mass value="1" />
            <inertia ixx="100" ixy="0" ixz="0" iyy="100" iyz="0" izz="100" />
        </inertial>
        <visual>
            <origin xyz="0.0 0.1305571067240593 0.0" rpy="0 0 0"/>
            <geometry>
                <box size="0.4597503577465798 0.2611142134481186 0.2600422763779154" />
            </geometry>
            <material name="Blue">
                <color rgba="0 0 1.0 1.0"/>
            </material>
        </visual>
        <collision>
            <origin xyz="0.0 0.1305571067240593 0.0" rpy="0 0 0"/>
            <geometry>
                <box size="0.4597503577465798 0.2611142134481186 0.2600422763779154" />
            </geometry>
        </collision>
    </link>
</robot>