<robot name = "robot">
    <link name="Link0">
        <inertial>
            <origin xyz="0.0 0.0 2.1683402860886667" rpy="0 0 0"/>
            <mass value="1" />
            <inertia ixx="100" ixy="0" ixz="0" iyy="100" iyz="0" izz="100" />
        </inertial>
        <visual>
            <origin xyz="0.0 0.0 2.1683402860886667" rpy="0 0 0"/>
            <geometry>
                <box size="0.7651022801649898 0.6535278623315175 0.33668057217733327" />
            </geometry>
            <material name="Green">
                <color rgba="0 1.0 0 1.0"/>
            </material>
        </visual>
        <collision>
            <origin xyz="0.0 0.0 2.1683402860886667" rpy="0 0 0"/>
            <geometry>
                <box size="0.7651022801649898 0.6535278623315175 0.33668057217733327" />
            </geometry>
        </collision>
    </link>
    <joint name="Link0_Link1" type="revolute">
       <parent link="Link0"/>
       <child  link="Link1"/>
       <origin rpy="0 0 0" xyz="0.0 0.32676393116575875 2.1683402860886667" />
     <axis xyz="1 0 1"/>
       <limit effort="0.0" lower="-3.14159" upper="3.14159" velocity="0.0"/>
    </joint>
    <link name="Link1">
        <inertial>
            <origin xyz="0.0 0.4656629990369191 0.0" rpy="0 0 0"/>
            <mass value="1" />
            <inertia ixx="100" ixy="0" ixz="0" iyy="100" iyz="0" izz="100" />
        </inertial>
        <visual>
            <origin xyz="0.0 0.4656629990369191 0.0" rpy="0 0 0"/>
            <geometry>
                <box size="0.400649912484122 0.9313259980738382 0.17390946690310716" />
            </geometry>
            <material name="Blue">
                <color rgba="0 0 1.0 1.0"/>
            </material>
        </visual>
        <collision>
            <origin xyz="0.0 0.4656629990369191 0.0" rpy="0 0 0"/>
            <geometry>
                <box size="0.400649912484122 0.9313259980738382 0.17390946690310716" />
            </geometry>
        </collision>
    </link>
    <joint name="Link1_Link2" type="revolute">
       <parent link="Link1"/>
       <child  link="Link2"/>
       <origin rpy="0 0 0" xyz="0.0 0.9313259980738382 0.0" />
     <axis xyz="[1 0 1]"/>
       <limit effort="0.0" lower="-3.14159" upper="3.14159" velocity="0.0"/>
    </joint>
    <link name="Link2">
        <inertial>
            <origin xyz="0.0 0.3873216853439417 0.0" rpy="0 0 0"/>
            <mass value="1" />
            <inertia ixx="100" ixy="0" ixz="0" iyy="100" iyz="0" izz="100" />
        </inertial>
        <visual>
            <origin xyz="0.0 0.3873216853439417 0.0" rpy="0 0 0"/>
            <geometry>
                <box size="0.7641707275276425 0.7746433706878834 0.9042840316290985" />
            </geometry>
            <material name="Green">
                <color rgba="0 1.0 0 1.0"/>
            </material>
        </visual>
        <collision>
            <origin xyz="0.0 0.3873216853439417 0.0" rpy="0 0 0"/>
            <geometry>
                <box size="0.7641707275276425 0.7746433706878834 0.9042840316290985" />
            </geometry>
        </collision>
    </link>
    <joint name="Link2_Link3" type="revolute">
       <parent link="Link2"/>
       <child  link="Link3"/>
       <origin rpy="0 0 0" xyz="0.0 0.7746433706878834 0.0" />
     <axis xyz="[1 0 1]"/>
       <limit effort="0.0" lower="-3.14159" upper="3.14159" velocity="0.0"/>
    </joint>
    <link name="Link3">
        <inertial>
            <origin xyz="0.0 0.4452161978712852 0.0" rpy="0 0 0"/>
            <mass value="1" />
            <inertia ixx="100" ixy="0" ixz="0" iyy="100" iyz="0" izz="100" />
        </inertial>
        <visual>
            <origin xyz="0.0 0.4452161978712852 0.0" rpy="0 0 0"/>
            <geometry>
                <box size="0.9860727465670287 0.8904323957425704 0.4521148623783987" />
            </geometry>
            <material name="Green">
                <color rgba="0 1.0 0 1.0"/>
            </material>
        </visual>
        <collision>
            <origin xyz="0.0 0.4452161978712852 0.0" rpy="0 0 0"/>
            <geometry>
                <box size="0.9860727465670287 0.8904323957425704 0.4521148623783987" />
            </geometry>
        </collision>
    </link>
    <joint name="Link3_Link3-0" type="revolute">
       <parent link="Link3"/>
       <child  link="Link3-0"/>
       <origin rpy="0 0 0" xyz="-0.49303637328351435 0.4452161978712852 0.0" />
     <axis xyz="[2 1 1]"/>
       <limit effort="0.0" lower="-3.14159" upper="3.14159" velocity="0.0"/>
    </joint>
    <link name="Link3-0">
        <inertial>
            <origin xyz="-0.14603818026429144 0.0 0.0" rpy="0 0 0"/>
            <mass value="1" />
            <inertia ixx="100" ixy="0" ixz="0" iyy="100" iyz="0" izz="100" />
        </inertial>
        <visual>
            <origin xyz="-0.14603818026429144 0.0 0.0" rpy="0 0 0"/>
            <geometry>
                <box size="0.2920763605285829 0.8701971915162356 0.8439963750695921" />
            </geometry>
            <material name="Green">
                <color rgba="0 1.0 0 1.0"/>
            </material>
        </visual>
        <collision>
            <origin xyz="-0.14603818026429144 0.0 0.0" rpy="0 0 0"/>
            <geometry>
                <box size="0.2920763605285829 0.8701971915162356 0.8439963750695921" />
            </geometry>
        </collision>
    </link>
    <joint name="Link3-0_Link3-0-0" type="revolute">
       <parent link="Link3-0"/>
       <child  link="Link3-0-0"/>
       <origin rpy="0 0 0" xyz="-0.14603818026429144 0.0 -0.42199818753479607" />
     <axis xyz="[1 1 2]"/>
       <limit effort="0.0" lower="-3.14159" upper="3.14159" velocity="0.0"/>
    </joint>
    <link name="Link3-0-0">
        <inertial>
            <origin xyz="0.0 0.0 -0.10957329260231233" rpy="0 0 0"/>
            <mass value="1" />
            <inertia ixx="100" ixy="0" ixz="0" iyy="100" iyz="0" izz="100" />
        </inertial>
        <visual>
            <origin xyz="0.0 0.0 -0.10957329260231233" rpy="0 0 0"/>
            <geometry>
                <box size="0.3243230882710888 0.8207917549892704 0.21914658520462466" />
            </geometry>
            <material name="Green">
                <color rgba="0 1.0 0 1.0"/>
            </material>
        </visual>
        <collision>
            <origin xyz="0.0 0.0 -0.10957329260231233" rpy="0 0 0"/>
            <geometry>
                <box size="0.3243230882710888 0.8207917549892704 0.21914658520462466" />
            </geometry>
        </collision>
    </link>
    <joint name="Link2_Link2-0" type="revolute">
       <parent link="Link2"/>
       <child  link="Link2-0"/>
       <origin rpy="0 0 0" xyz="0.0 0.3873216853439417 -0.45214201581454927" />
     <axis xyz="[1 1 2]"/>
       <limit effort="0.0" lower="-3.14159" upper="3.14159" velocity="0.0"/>
    </joint>
    <link name="Link2-0">
        <inertial>
            <origin xyz="0.0 0.0 -0.11592351646870051" rpy="0 0 0"/>
            <mass value="1" />
            <inertia ixx="100" ixy="0" ixz="0" iyy="100" iyz="0" izz="100" />
        </inertial>
        <visual>
            <origin xyz="0.0 0.0 -0.11592351646870051" rpy="0 0 0"/>
            <geometry>
                <box size="0.30214430234099476 0.6493252305452363 0.23184703293740103" />
            </geometry>
            <material name="Green">
                <color rgba="0 1.0 0 1.0"/>
            </material>
        </visual>
        <collision>
            <origin xyz="0.0 0.0 -0.11592351646870051" rpy="0 0 0"/>
            <geometry>
                <box size="0.30214430234099476 0.6493252305452363 0.23184703293740103" />
            </geometry>
        </collision>
    </link>
</robot>