<robot name = "robot">
    <link name="Link0">
        <inertial>
            <origin xyz="0.0 0.0 2.2258304961770894" rpy="0 0 0"/>
            <mass value="1" />
            <inertia ixx="100" ixy="0" ixz="0" iyy="100" iyz="0" izz="100" />
        </inertial>
        <visual>
            <origin xyz="0.0 0.0 2.2258304961770894" rpy="0 0 0"/>
            <geometry>
                <box size="0.21861838617449375 0.2553896211140766 0.451660992354179" />
            </geometry>
            <material name="Green">
                <color rgba="0 1.0 0 1.0"/>
            </material>
        </visual>
        <collision>
            <origin xyz="0.0 0.0 2.2258304961770894" rpy="0 0 0"/>
            <geometry>
                <box size="0.21861838617449375 0.2553896211140766 0.451660992354179" />
            </geometry>
        </collision>
    </link>
    <joint name="Link0_Link1" type="revolute">
       <parent link="Link0"/>
       <child  link="Link1"/>
       <origin rpy="0 0 0" xyz="0.0 0.1276948105570383 2.2258304961770894" />
     <axis xyz="1 0 1"/>
       <limit effort="0.0" lower="-3.14159" upper="3.14159" velocity="0.0"/>
    </joint>
    <link name="Link1">
        <inertial>
            <origin xyz="0.0 0.4337307456480676 0.0" rpy="0 0 0"/>
            <mass value="1" />
            <inertia ixx="100" ixy="0" ixz="0" iyy="100" iyz="0" izz="100" />
        </inertial>
        <visual>
            <origin xyz="0.0 0.4337307456480676 0.0" rpy="0 0 0"/>
            <geometry>
                <box size="0.468732223483624 0.8674614912961351 0.25730014992835687" />
            </geometry>
            <material name="Green">
                <color rgba="0 1.0 0 1.0"/>
            </material>
        </visual>
        <collision>
            <origin xyz="0.0 0.4337307456480676 0.0" rpy="0 0 0"/>
            <geometry>
                <box size="0.468732223483624 0.8674614912961351 0.25730014992835687" />
            </geometry>
        </collision>
    </link>
    <joint name="Link1_Link2" type="revolute">
       <parent link="Link1"/>
       <child  link="Link2"/>
       <origin rpy="0 0 0" xyz="0.0 0.8674614912961351 0.0" />
     <axis xyz="[1 0 1]"/>
       <limit effort="0.0" lower="-3.14159" upper="3.14159" velocity="0.0"/>
    </joint>
    <link name="Link2">
        <inertial>
            <origin xyz="0.0 0.1377675004722203 0.0" rpy="0 0 0"/>
            <mass value="1" />
            <inertia ixx="100" ixy="0" ixz="0" iyy="100" iyz="0" izz="100" />
        </inertial>
        <visual>
            <origin xyz="0.0 0.1377675004722203 0.0" rpy="0 0 0"/>
            <geometry>
                <box size="0.5921124419549841 0.2755350009444406 0.3989564182654126" />
            </geometry>
            <material name="Green">
                <color rgba="0 1.0 0 1.0"/>
            </material>
        </visual>
        <collision>
            <origin xyz="0.0 0.1377675004722203 0.0" rpy="0 0 0"/>
            <geometry>
                <box size="0.5921124419549841 0.2755350009444406 0.3989564182654126" />
            </geometry>
        </collision>
    </link>
</robot>