<robot name = "robot">
    <link name="Link0">
        <inertial>
            <origin xyz="0.0 0.0 2.1044144340923046" rpy="0 0 0"/>
            <mass value="1" />
            <inertia ixx="100" ixy="0" ixz="0" iyy="100" iyz="0" izz="100" />
        </inertial>
        <visual>
            <origin xyz="0.0 0.0 2.1044144340923046" rpy="0 0 0"/>
            <geometry>
                <box size="0.41384298033128575 0.4250745891863679 0.20882886818460933" />
            </geometry>
            <material name="Green">
                <color rgba="0 1.0 0 1.0"/>
            </material>
        </visual>
        <collision>
            <origin xyz="0.0 0.0 2.1044144340923046" rpy="0 0 0"/>
            <geometry>
                <box size="0.41384298033128575 0.4250745891863679 0.20882886818460933" />
            </geometry>
        </collision>
    </link>
    <joint name="Link0_Link1" type="revolute">
       <parent link="Link0"/>
       <child  link="Link1"/>
       <origin rpy="0 0 0" xyz="0.0 0.21253729459318396 2.1044144340923046" />
     <axis xyz="1 0 1"/>
       <limit effort="0.0" lower="-3.14159" upper="3.14159" velocity="0.0"/>
    </joint>
    <link name="Link1">
        <inertial>
            <origin xyz="0.0 0.20914266287645658 0.0" rpy="0 0 0"/>
            <mass value="1" />
            <inertia ixx="100" ixy="0" ixz="0" iyy="100" iyz="0" izz="100" />
        </inertial>
        <visual>
            <origin xyz="0.0 0.20914266287645658 0.0" rpy="0 0 0"/>
            <geometry>
                <box size="0.7637136493872744 0.41828532575291316 0.3401647974727828" />
            </geometry>
            <material name="Blue">
                <color rgba="0 0 1.0 1.0"/>
            </material>
        </visual>
        <collision>
            <origin xyz="0.0 0.20914266287645658 0.0" rpy="0 0 0"/>
            <geometry>
                <box size="0.7637136493872744 0.41828532575291316 0.3401647974727828" />
            </geometry>
        </collision>
    </link>
    <joint name="Link1_Link2" type="revolute">
       <parent link="Link1"/>
       <child  link="Link2"/>
       <origin rpy="0 0 0" xyz="0.0 0.41828532575291316 0.0" />
     <axis xyz="[1 0 1]"/>
       <limit effort="0.0" lower="-3.14159" upper="3.14159" velocity="0.0"/>
    </joint>
    <link name="Link2">
        <inertial>
            <origin xyz="0.0 0.26778932544974837 0.0" rpy="0 0 0"/>
            <mass value="1" />
            <inertia ixx="100" ixy="0" ixz="0" iyy="100" iyz="0" izz="100" />
        </inertial>
        <visual>
            <origin xyz="0.0 0.26778932544974837 0.0" rpy="0 0 0"/>
            <geometry>
                <box size="0.4782363357283196 0.5355786508994967 0.3333528148687647" />
            </geometry>
            <material name="Green">
                <color rgba="0 1.0 0 1.0"/>
            </material>
        </visual>
        <collision>
            <origin xyz="0.0 0.26778932544974837 0.0" rpy="0 0 0"/>
            <geometry>
                <box size="0.4782363357283196 0.5355786508994967 0.3333528148687647" />
            </geometry>
        </collision>
    </link>
</robot>