<robot name = "robot">
    <link name="Link0">
        <inertial>
            <origin xyz="0.0 0.0 2.2284366454897007" rpy="0 0 0"/>
            <mass value="1" />
            <inertia ixx="100" ixy="0" ixz="0" iyy="100" iyz="0" izz="100" />
        </inertial>
        <visual>
            <origin xyz="0.0 0.0 2.2284366454897007" rpy="0 0 0"/>
            <geometry>
                <box size="0.7864632790450573 0.4753933656179649 0.45687329097940144" />
            </geometry>
            <material name="Green">
                <color rgba="0 1.0 0 1.0"/>
            </material>
        </visual>
        <collision>
            <origin xyz="0.0 0.0 2.2284366454897007" rpy="0 0 0"/>
            <geometry>
                <box size="0.7864632790450573 0.4753933656179649 0.45687329097940144" />
            </geometry>
        </collision>
    </link>
    <joint name="Link0_Link1" type="revolute">
       <parent link="Link0"/>
       <child  link="Link1"/>
       <origin rpy="0 0 0" xyz="0.0 0.23769668280898246 2.2284366454897007" />
     <axis xyz="1 0 1"/>
       <limit effort="0.0" lower="-3.14159" upper="3.14159" velocity="0.0"/>
    </joint>
    <link name="Link1">
        <inertial>
            <origin xyz="0.0 0.4624553949291617 0.0" rpy="0 0 0"/>
            <mass value="1" />
            <inertia ixx="100" ixy="0" ixz="0" iyy="100" iyz="0" izz="100" />
        </inertial>
        <visual>
            <origin xyz="0.0 0.4624553949291617 0.0" rpy="0 0 0"/>
            <geometry>
                <box size="0.559250485784348 0.9249107898583234 0.2143649930740748" />
            </geometry>
            <material name="Green">
                <color rgba="0 1.0 0 1.0"/>
            </material>
        </visual>
        <collision>
            <origin xyz="0.0 0.4624553949291617 0.0" rpy="0 0 0"/>
            <geometry>
                <box size="0.559250485784348 0.9249107898583234 0.2143649930740748" />
            </geometry>
        </collision>
    </link>
    <joint name="Link1_Link2" type="revolute">
       <parent link="Link1"/>
       <child  link="Link2"/>
       <origin rpy="0 0 0" xyz="0.0 0.9249107898583234 0.0" />
     <axis xyz="[1 0 1]"/>
       <limit effort="0.0" lower="-3.14159" upper="3.14159" velocity="0.0"/>
    </joint>
    <link name="Link2">
        <inertial>
            <origin xyz="0.0 0.35592759614375036 0.0" rpy="0 0 0"/>
            <mass value="1" />
            <inertia ixx="100" ixy="0" ixz="0" iyy="100" iyz="0" izz="100" />
        </inertial>
        <visual>
            <origin xyz="0.0 0.35592759614375036 0.0" rpy="0 0 0"/>
            <geometry>
                <box size="0.7748136964189563 0.7118551922875007 0.49346368192009604" />
            </geometry>
            <material name="Blue">
                <color rgba="0 0 1.0 1.0"/>
            </material>
        </visual>
        <collision>
            <origin xyz="0.0 0.35592759614375036 0.0" rpy="0 0 0"/>
            <geometry>
                <box size="0.7748136964189563 0.7118551922875007 0.49346368192009604" />
            </geometry>
        </collision>
    </link>
    <joint name="Link2_Link3" type="revolute">
       <parent link="Link2"/>
       <child  link="Link3"/>
       <origin rpy="0 0 0" xyz="0.0 0.7118551922875007 0.0" />
     <axis xyz="[1 0 1]"/>
       <limit effort="0.0" lower="-3.14159" upper="3.14159" velocity="0.0"/>
    </joint>
    <link name="Link3">
        <inertial>
            <origin xyz="0.0 0.18365810224058673 0.0" rpy="0 0 0"/>
            <mass value="1" />
            <inertia ixx="100" ixy="0" ixz="0" iyy="100" iyz="0" izz="100" />
        </inertial>
        <visual>
            <origin xyz="0.0 0.18365810224058673 0.0" rpy="0 0 0"/>
            <geometry>
                <box size="0.6502633105904413 0.36731620448117347 0.1273934451697573" />
            </geometry>
            <material name="Green">
                <color rgba="0 1.0 0 1.0"/>
            </material>
        </visual>
        <collision>
            <origin xyz="0.0 0.18365810224058673 0.0" rpy="0 0 0"/>
            <geometry>
                <box size="0.6502633105904413 0.36731620448117347 0.1273934451697573" />
            </geometry>
        </collision>
    </link>
</robot>